Workbook

Sheet Annual Medicaid Cost
A1: 2019 Annual Medicaid Cost per Enrollee
A2: State | B2: Data quality assessment | C2: Total | D2: Children | E2: Adult: non-expansion, non-disabled, under age 65 | F2: Aged | G2: People with disabilities | H2: Adult: ACA Medicaid expansion
A3: Alabama | B3: Medium concern | C3: 5582 | D3: 1878 | E3: 1555 | F3: 13017 | G3: 13317 | H3: -
A4: Alaska | B4: Low concern | C4: 10104 | D4: 5862 | E4: 7231 | F4: 22714 | G4: 33899 | H4: 9298
A5: Arizona | B5: Low concern | C5: 7074 | D5: 3232 | E5: 4823 | F5: 9581 | G5: 23415 | H5: 7637
A6: Arkansas | B6: Medium concern | C6: 7928 | D6: 4822 | E6: 10443 | F6: 20633 | G6: 20937 | H6: 1647
A7: California | B7: Medium concern | C7: 7433 | D7: 3122 | E7: 3300 | F7: 16501 | G7: 29021 | H7: 5806
A8: Colorado | B8: Low concern | C8: 7665 | D8: 2947 | E8: 4789 | F8: 21408 | G8: 28651 | H8: 5650
A9: Connecticut | B9: Low concern | C9: 8405 | D9: 3502 | E9: 5619 | F9: 15527 | G9: 28234 | H9: 7263
A10: Delaware | B10: Low concern | C10: 9634 | D10: 4630 | E10: 8092 | F10: 20858 | G10: 24914 | H10: 8170
A11: District of Columbia | B11: Low concern | C11: 11405 | D11: 4577 | E11: 6511 | F11: 23339 | G11: 33567 | H11: 6707
A12: Florida | B12: Medium concern | C12: 5387 | D12: 2329 | E12: 2754 | F12: 10788 | G12: 14423 | H12: -
A13: Georgia | B13: Low concern | C13: 5373 | D13: 2588 | E13: 4411 | F13: 9880 | G13: 12149 | H13: -
A14: Hawaii | B14: Medium concern | C14: 6890 | D14: 3291 | E14: 4923 | F14: 14252 | G14: 23758 | H14: 5711
A15: Idaho | B15: Low concern | C15: 7966 | D15: 3101 | E15: 7525 | F15: 12600 | G15: 21460 | H15: -
A16: Illinois | B16: Medium concern | C16: 7033 | D16: 2853 | E16: 5100 | F16: 17453 | G16: 15123 | H16: 6237
A17: Indiana | B17: Medium concern | C17: 8999 | D17: 3227 | E17: 8833 | F17: 18875 | G17: 18245 | H17: 10072
A18: Iowa | B18: Medium concern | C18: 8897 | D18: 3276 | E18: 7667 | F18: 22588 | G18: 25242 | H18: 6666
A19: Kansas | B19: Medium concern | C19: 9944 | D19: 4096 | E19: 16109 | F19: 23097 | G19: 16019 | H19: -
A20: Kentucky | B20: High concern | C20: 6827 | D20: 3556 | E20: 6451 | F20: 9858 | G20: 14454 | H20: 6046
A21: Louisiana | B21: Low concern | C21: 7005 | D21: 3523 | E21: 6029 | F21: 10893 | G21: 14366 | H21: 6611
A22: Maine | B22: Medium concern | C22: 10692 | D22: 4504 | E22: 4878 | F22: 13718 | G22: 23186 | H22: 6719
A23: Maryland | B23: Low concern | C23: 9359 | D23: 3746 | E23: 7566 | F23: 19056 | G23: 25648 | H23: 8876
A24: Massachusetts | B24: Medium concern | C24: 10288 | D24: 3564 | E24: 3974 | F24: 24092 | G24: 20119 | H24: 6735
A25: Michigan | B25: High concern | C25: 7608 | D25: 3154 | E25: 5754 | F25: 20658 | G25: 18735 | H25: 5628
A26: Minnesota | B26: Low concern | C26: 11829 | D26: 3815 | E26: 6731 | F26: 32854 | G26: 43171 | H26: 9921
A27: Mississippi | B27: Medium concern | C27: 7954 | D27: 4030 | E27: 5192 | F27: 13198 | G27: 14475 | H27: -
A28: Missouri | B28: Medium concern | C28: 10607 | D28: 4642 | E28: 6696 | F28: 20325 | G28: 26652 | H28: -
A29: Montana | B29: Medium concern | C29: 7708 | D29: 4304 | E29: 5995 | F29: 17719 | G29: 18519 | H29: 7097
A30: Nebraska | B30: High concern | C30: 9759 | D30: 4615 | E30: 9170 | F30: 24342 | G30: 19295 | H30: -
A31: Nevada | B31: Medium concern | C31: 6374 | D31: 2834 | E31: 5748 | F31: 8877 | G31: 18325 | H31: 6918
A32: New Hampshire | B32: Low concern | C32: 9297 | D32: 4212 | E32: 14746 | F32: 24632 | G32: 18906 | H32: 6551
A33: New Jersey | B33: Low concern | C33: 10066 | D33: 3318 | E33: 9678 | F33: 25402 | G33: 31248 | H33: 6709
A34: New Mexico | B34: Low concern | C34: 6712 | D34: 3921 | E34: 4227 | F34: 11021 | G34: 23066 | H34: 5931
A35: New York | B35: High concern | C35: 9762 | D35: 3432 | E35: 6735 | F35: 21874 | G35: 27242 | H35: 6344
A36: North Carolina | B36: Medium concern | C36: 6820 | D36: 3155 | E36: 2653 | F36: 14393 | G36: 19097 | H36: -
A37: North Dakota | B37: Medium concern | C37: 13811 | D37: 4694 | E37: 5786 | F37: 35124 | G37: 33685 | H37: 13966
A38: Ohio | B38: Low concern | C38: 8534 | D38: 3470 | E38: 5854 | F38: 21039 | G38: 18874 | H38: 7456
A39: Oklahoma | B39: Medium concern | C39: 7671 | D39: 4187 | E39: 5197 | F39: 15865 | G39: 18494 | H39: -
A40: Oregon | B40: High concern | C40: 9787 | D40: 5326 | E40: 11872 | F40: 18610 | G40: 18674 | H40: 9492
...

Sheet Monthly Medicaid Cost
A1: 2019 Monthly Medicaid Cost per Enrollee
A2: State | B2: Data quality assessment | C2: Total | D2: Children | E2: Adult: non-expansion, non-disabled, under age 65 | F2: Aged | G2: People with disabilities | H2: Adult: ACA Medicaid expansion
A3: ='Annual Medicaid Cost'!A3 -> Alabama | B3: ='Annual Medicaid Cost'!B3 -> Medium concern | C3: =IFERROR('Annual Medicaid Cost'!C3/12,"") -> 465.16667 | D3: =IFERROR('Annual Medicaid Cost'!D3/12,"") -> 156.5 | E3: =IFERROR('Annual Medicaid Cost'!E3/12,"") -> 129.58333 | F3: =IFERROR('Annual Medicaid Cost'!F3/12,"") -> 1084.75 | G3: =IFERROR('Annual Medicaid Cost'!G3/12,"") -> 1109.75 | H3: =IFERROR('Annual Medicaid Cost'!H3/12,"") | L3: Children | M3: Adult: non-expansion, non-disabled, under age 65 | N3: Aged | O3: People with disabilities
A4: ='Annual Medicaid Cost'!A4 -> Alaska | B4: ='Annual Medicaid Cost'!B4 -> Low concern | C4: =IFERROR('Annual Medicaid Cost'!C4/12,"") -> 842 | D4: =IFERROR('Annual Medicaid Cost'!D4/12,"") -> 488.5 | E4: =IFERROR('Annual Medicaid Cost'!E4/12,"") -> 602.58333 | F4: =IFERROR('Annual Medicaid Cost'!F4/12,"") -> 1892.8333 | G4: =IFERROR('Annual Medicaid Cost'!G4/12,"") -> 2824.9167 | H4: =IFERROR('Annual Medicaid Cost'!H4/12,"") -> 774.83333 | L4: 401.83333 | M4: 870.25 | N4: 1719.4167 | O4: 1744.75
A5: ='Annual Medicaid Cost'!A5 -> Arizona | B5: ='Annual Medicaid Cost'!B5 -> Low concern | C5: =IFERROR('Annual Medicaid Cost'!C5/12,"") -> 589.5 | D5: =IFERROR('Annual Medicaid Cost'!D5/12,"") -> 269.33333 | E5: =IFERROR('Annual Medicaid Cost'!E5/12,"") -> 401.91667 | F5: =IFERROR('Annual Medicaid Cost'!F5/12,"") -> 798.41667 | G5: =IFERROR('Annual Medicaid Cost'!G5/12,"") -> 1951.25 | H5: =IFERROR('Annual Medicaid Cost'!H5/12,"") -> 636.41667
A6: ='Annual Medicaid Cost'!A6 -> Arkansas | B6: ='Annual Medicaid Cost'!B6 -> Medium concern | C6: =IFERROR('Annual Medicaid Cost'!C6/12,"") -> 660.66667 | D6: =IFERROR('Annual Medicaid Cost'!D6/12,"") -> 401.83333 | E6: =IFERROR('Annual Medicaid Cost'!E6/12,"") -> 870.25 | F6: =IFERROR('Annual Medicaid Cost'!F6/12,"") -> 1719.4167 | G6: =IFERROR('Annual Medicaid Cost'!G6/12,"") -> 1744.75 | H6: =IFERROR('Annual Medicaid Cost'!H6/12,"") -> 137.25 | L6: Children | M6: 401.83333
A7: ='Annual Medicaid Cost'!A7 -> California | B7: ='Annual Medicaid Cost'!B7 -> Medium concern | C7: =IFERROR('Annual Medicaid Cost'!C7/12,"") -> 619.41667 | D7: =IFERROR('Annual Medicaid Cost'!D7/12,"") -> 260.16667 | E7: =IFERROR('Annual Medicaid Cost'!E7/12,"") -> 275 | F7: =IFERROR('Annual Medicaid Cost'!F7/12,"") -> 1375.0833 | G7: =IFERROR('Annual Medicaid Cost'!G7/12,"") -> 2418.4167 | H7: =IFERROR('Annual Medicaid Cost'!H7/12,"") -> 483.83333 | L7: Adult: | M7: 870.25
A8: ='Annual Medicaid Cost'!A8 -> Colorado | B8: ='Annual Medicaid Cost'!B8 -> Low concern | C8: =IFERROR('Annual Medicaid Cost'!C8/12,"") -> 638.75 | D8: =IFERROR('Annual Medicaid Cost'!D8/12,"") -> 245.58333 | E8: =IFERROR('Annual Medicaid Cost'!E8/12,"") -> 399.08333 | F8: =IFERROR('Annual Medicaid Cost'!F8/12,"") -> 1784 | G8: =IFERROR('Annual Medicaid Cost'!G8/12,"") -> 2387.5833 | H8: =IFERROR('Annual Medicaid Cost'!H8/12,"") -> 470.83333 | L8: Aged | M8: 1719.4167
A9: ='Annual Medicaid Cost'!A9 -> Connecticut | B9: ='Annual Medicaid Cost'!B9 -> Low concern | C9: =IFERROR('Annual Medicaid Cost'!C9/12,"") -> 700.41667 | D9: =IFERROR('Annual Medicaid Cost'!D9/12,"") -> 291.83333 | E9: =IFERROR('Annual Medicaid Cost'!E9/12,"") -> 468.25 | F9: =IFERROR('Annual Medicaid Cost'!F9/12,"") -> 1293.9167 | G9: =IFERROR('Annual Medicaid Cost'!G9/12,"") -> 2352.8333 | H9: =IFERROR('Annual Medicaid Cost'!H9/12,"") -> 605.25 | L9: People with disabilities | M9: 1744.75
A10: ='Annual Medicaid Cost'!A10 -> Delaware | B10: ='Annual Medicaid Cost'!B10 -> Low concern | C10: =IFERROR('Annual Medicaid Cost'!C10/12,"") -> 802.83333 | D10: =IFERROR('Annual Medicaid Cost'!D10/12,"") -> 385.83333 | E10: =IFERROR('Annual Medicaid Cost'!E10/12,"") -> 674.33333 | F10: =IFERROR('Annual Medicaid Cost'!F10/12,"") -> 1738.1667 | G10: =IFERROR('Annual Medicaid Cost'!G10/12,"") -> 2076.1667 | H10: =IFERROR('Annual Medicaid Cost'!H10/12,"") -> 680.83333
A11: ='Annual Medicaid Cost'!A11 -> District of Columbia | B11: ='Annual Medicaid Cost'!B11 -> Low concern | C11: =IFERROR('Annual Medicaid Cost'!C11/12,"") -> 950.41667 | D11: =IFERROR('Annual Medicaid Cost'!D11/12,"") -> 381.41667 | E11: =IFERROR('Annual Medicaid Cost'!E11/12,"") -> 542.58333 | F11: =IFERROR('Annual Medicaid Cost'!F11/12,"") -> 1944.9167 | G11: =IFERROR('Annual Medicaid Cost'!G11/12,"") -> 2797.25 | H11: =IFERROR('Annual Medicaid Cost'!H11/12,"") -> 558.91667 | L11: Adult: | M11: 870.25
A12: ='Annual Medicaid Cost'!A12 -> Florida | B12: ='Annual Medicaid Cost'!B12 -> Medium concern | C12: =IFERROR('Annual Medicaid Cost'!C12/12,"") -> 448.91667 | D12: =IFERROR('Annual Medicaid Cost'!D12/12,"") -> 194.08333 | E12: =IFERROR('Annual Medicaid Cost'!E12/12,"") -> 229.5 | F12: =IFERROR('Annual Medicaid Cost'!F12/12,"") -> 899 | G12: =IFERROR('Annual Medicaid Cost'!G12/12,"") -> 1201.9167 | H12: =IFERROR('Annual Medicaid Cost'!H12/12,"") | L12: People with disabilities | M12: 1744.75
A13: ='Annual Medicaid Cost'!A13 -> Georgia | B13: ='Annual Medicaid Cost'!B13 -> Low concern | C13: =IFERROR('Annual Medicaid Cost'!C13/12,"") -> 447.75 | D13: =IFERROR('Annual Medicaid Cost'!D13/12,"") -> 215.66667 | E13: =IFERROR('Annual Medicaid Cost'!E13/12,"") -> 367.58333 | F13: =IFERROR('Annual Medicaid Cost'!F13/12,"") -> 823.33333 | G13: =IFERROR('Annual Medicaid Cost'!G13/12,"") -> 1012.4167 | H13: =IFERROR('Annual Medicaid Cost'!H13/12,"") | L13: Children | M13: 401.83333
A14: ='Annual Medicaid Cost'!A14 -> Hawaii | B14: ='Annual Medicaid Cost'!B14 -> Medium concern | C14: =IFERROR('Annual Medicaid Cost'!C14/12,"") -> 574.16667 | D14: =IFERROR('Annual Medicaid Cost'!D14/12,"") -> 274.25 | E14: =IFERROR('Annual Medicaid Cost'!E14/12,"") -> 410.25 | F14: =IFERROR('Annual Medicaid Cost'!F14/12,"") -> 1187.6667 | G14: =IFERROR('Annual Medicaid Cost'!G14/12,"") -> 1979.8333 | H14: =IFERROR('Annual Medicaid Cost'!H14/12,"") -> 475.91667 | L14: People with disabilities | M14: 1744.75
A15: ='Annual Medicaid Cost'!A15 -> Idaho | B15: ='Annual Medicaid Cost'!B15 -> Low concern | C15: =IFERROR('Annual Medicaid Cost'!C15/12,"") -> 663.83333 | D15: =IFERROR('Annual Medicaid Cost'!D15/12,"") -> 258.41667 | E15: =IFERROR('Annual Medicaid Cost'!E15/12,"") -> 627.08333 | F15: =IFERROR('Annual Medicaid Cost'!F15/12,"") -> 1050 | G15: =IFERROR('Annual Medicaid Cost'!G15/12,"") -> 1788.3333 | H15: =IFERROR('Annual Medicaid Cost'!H15/12,"")
A16: ='Annual Medicaid Cost'!A16 -> Illinois | B16: ='Annual Medicaid Cost'!B16 -> Medium concern | C16: =IFERROR('Annual Medicaid Cost'!C16/12,"") -> 586.08333 | D16: =IFERROR('Annual Medicaid Cost'!D16/12,"") -> 237.75 | E16: =IFERROR('Annual Medicaid Cost'!E16/12,"") -> 425 | F16: =IFERROR('Annual Medicaid Cost'!F16/12,"") -> 1454.4167 | G16: =IFERROR('Annual Medicaid Cost'!G16/12,"") -> 1260.25 | H16: =IFERROR('Annual Medicaid Cost'!H16/12,"") -> 519.75
A17: ='Annual Medicaid Cost'!A17 -> Indiana | B17: ='Annual Medicaid Cost'!B17 -> Medium concern | C17: =IFERROR('Annual Medicaid Cost'!C17/12,"") -> 749.91667 | D17: =IFERROR('Annual Medicaid Cost'!D17/12,"") -> 268.91667 | E17: =IFERROR('Annual Medicaid Cost'!E17/12,"") -> 736.08333 | F17: =IFERROR('Annual Medicaid Cost'!F17/12,"") -> 1572.9167 | G17: =IFERROR('Annual Medicaid Cost'!G17/12,"") -> 1520.4167 | H17: =IFERROR('Annual Medicaid Cost'!H17/12,"") -> 839.33333
A18: ='Annual Medicaid Cost'!A18 -> Iowa | B18: ='Annual Medicaid Cost'!B18 -> Medium concern | C18: =IFERROR('Annual Medicaid Cost'!C18/12,"") -> 741.41667 | D18: =IFERROR('Annual Medicaid Cost'!D18/12,"") -> 273 | E18: =IFERROR('Annual Medicaid Cost'!E18/12,"") -> 638.91667 | F18: =IFERROR('Annual Medicaid Cost'!F18/12,"") -> 1882.3333 | G18: =IFERROR('Annual Medicaid Cost'!G18/12,"") -> 2103.5 | H18: =IFERROR('Annual Medicaid Cost'!H18/12,"") -> 555.5
A19: ='Annual Medicaid Cost'!A19 -> Kansas | B19: ='Annual Medicaid Cost'!B19 -> Medium concern | C19: =IFERROR('Annual Medicaid Cost'!C19/12,"") -> 828.66667 | D19: =IFERROR('Annual Medicaid Cost'!D19/12,"") -> 341.33333 | E19: =IFERROR('Annual Medicaid Cost'!E19/12,"") -> 1342.4167 | F19: =IFERROR('Annual Medicaid Cost'!F19/12,"") -> 1924.75 | G19: =IFERROR('Annual Medicaid Cost'!G19/12,"") -> 1334.9167 | H19: =IFERROR('Annual Medicaid Cost'!H19/12,"")
A20: ='Annual Medicaid Cost'!A20 -> Kentucky | B20: ='Annual Medicaid Cost'!B20 -> High concern | C20: =IFERROR('Annual Medicaid Cost'!C20/12,"") -> 568.91667 | D20: =IFERROR('Annual Medicaid Cost'!D20/12,"") -> 296.33333 | E20: =IFERROR('Annual Medicaid Cost'!E20/12,"") -> 537.58333 | F20: =IFERROR('Annual Medicaid Cost'!F20/12,"") -> 821.5 | G20: =IFERROR('Annual Medicaid Cost'!G20/12,"") -> 1204.5 | H20: =IFERROR('Annual Medicaid Cost'!H20/12,"") -> 503.83333
A21: ='Annual Medicaid Cost'!A21 -> Louisiana | B21: ='Annual Medicaid Cost'!B21 -> Low concern | C21: =IFERROR('Annual Medicaid Cost'!C21/12,"") -> 583.75 | D21: =IFERROR('Annual Medicaid Cost'!D21/12,"") -> 293.58333 | E21: =IFERROR('Annual Medicaid Cost'!E21/12,"") -> 502.41667 | F21: =IFERROR('Annual Medicaid Cost'!F21/12,"") -> 907.75 | G21: =IFERROR('Annual Medicaid Cost'!G21/12,"") -> 1197.1667 | H21: =IFERROR('Annual Medicaid Cost'!H21/12,"") -> 550.91667
A22: ='Annual Medicaid Cost'!A22 -> Maine | B22: ='Annual Medicaid Cost'!B22 -> Medium concern | C22: =IFERROR('Annual Medicaid Cost'!C22/12,"") -> 891 | D22: =IFERROR('Annual Medicaid Cost'!D22/12,"") -> 375.33333 | E22: =IFERROR('Annual Medicaid Cost'!E22/12,"") -> 406.5 | F22: =IFERROR('Annual Medicaid Cost'!F22/12,"") -> 1143.1667 | G22: =IFERROR('Annual Medicaid Cost'!G22/12,"") -> 1932.1667 | H22: =IFERROR('Annual Medicaid Cost'!H22/12,"") -> 559.91667
A23: ='Annual Medicaid Cost'!A23 -> Maryland | B23: ='Annual Medicaid Cost'!B23 -> Low concern | C23: =IFERROR('Annual Medicaid Cost'!C23/12,"") -> 779.91667 | D23: =IFERROR('Annual Medicaid Cost'!D23/12,"") -> 312.16667 | E23: =IFERROR('Annual Medicaid Cost'!E23/12,"") -> 630.5 | F23: =IFERROR('Annual Medicaid Cost'!F23/12,"") -> 1588 | G23: =IFERROR('Annual Medicaid Cost'!G23/12,"") -> 2137.3333 | H23: =IFERROR('Annual Medicaid Cost'!H23/12,"") -> 739.66667
A24: ='Annual Medicaid Cost'!A24 -> Massachusetts | B24: ='Annual Medicaid Cost'!B24 -> Medium concern | C24: =IFERROR('Annual Medicaid Cost'!C24/12,"") -> 857.33333 | D24: =IFERROR('Annual Medicaid Cost'!D24/12,"") -> 297 | E24: =IFERROR('Annual Medicaid Cost'!E24/12,"") -> 331.16667 | F24: =IFERROR('Annual Medicaid Cost'!F24/12,"") -> 2007.6667 | G24: =IFERROR('Annual Medicaid Cost'!G24/12,"") -> 1676.5833 | H24: =IFERROR('Annual Medicaid Cost'!H24/12,"") -> 561.25
A25: ='Annual Medicaid Cost'!A25 -> Michigan | B25: ='Annual Medicaid Cost'!B25 -> High concern | C25: =IFERROR('Annual Medicaid Cost'!C25/12,"") -> 634 | D25: =IFERROR('Annual Medicaid Cost'!D25/12,"") -> 262.83333 | E25: =IFERROR('Annual Medicaid Cost'!E25/12,"") -> 479.5 | F25: =IFERROR('Annual Medicaid Cost'!F25/12,"") -> 1721.5 | G25: =IFERROR('Annual Medicaid Cost'!G25/12,"") -> 1561.25 | H25: =IFERROR('Annual Medicaid Cost'!H25/12,"") -> 469
A26: ='Annual Medicaid Cost'!A26 -> Minnesota | B26: ='Annual Medicaid Cost'!B26 -> Low concern | C26: =IFERROR('Annual Medicaid Cost'!C26/12,"") -> 985.75 | D26: =IFERROR('Annual Medicaid Cost'!D26/12,"") -> 317.91667 | E26: =IFERROR('Annual Medicaid Cost'!E26/12,"") -> 560.91667 | F26: =IFERROR('Annual Medicaid Cost'!F26/12,"") -> 2737.8333 | G26: =IFERROR('Annual Medicaid Cost'!G26/12,"") -> 3597.5833 | H26: =IFERROR('Annual Medicaid Cost'!H26/12,"") -> 826.75
... A58: ='Annual Medicaid Cost'!A58 -> Max | B58: ='Annual Medicaid Cost'!B58 -> - | C58: =IFERROR('Annual Medicaid Cost'!C58/12,"") -> 1150.9167 | D58: =IFERROR('Annual Medicaid Cost'!D58/12,"") -> 508.58333 | E58: =IFERROR('Annual Medicaid Cost'!E58/12,"") -> 1342.4167 | F58: =IFERROR('Annual Medicaid Cost'!F58/12,"") -> 3073.4167 | G58: =IFERROR('Annual Medicaid Cost'!G58/12,"") -> 3597.5833 | H58: =IFERROR('Annual Medicaid Cost'!H58/12,"") -> 1163.8333
