Workbook
Name Adjusted_Gross_Income: [1]Calc1!$N$66:INDEX([1]Calc1!$N$66:$HH$66,COUNTIF([1]Calc1!$N$66:$HH$66,”<>”&””))
Name AgeAdult: [1]Lists!$F$10:$F$60
Name AgeChild: [1]Lists!$H$10:$H$29
Name CCA_RateCategoryEntireCol: INDEX([1]!CCA_RateCategory[#Data],,CCA_RateCategoryStateColNum)
Name CCA_RateCategoryLookup: INDEX([1]!CCA_RateCategory[#Data],1,CCA_RateCategoryStateColNum):INDEX([1]!CCA_RateCategory[#Data],COUNTA(CCA_RateCategoryEntireCol),CCA_RateCategoryStateColNum)
Name CCA_RateCategoryStateColNum: MATCH(InputStateName,[1]!CCA_RateCategory[#Headers],0)
Name CCA_SettingsEntireCol: INDEX([1]!CCA_Settings[#Data],,CCA_SettingsStateColNum)
Name CCA_SettingsLookup: INDEX([1]!CCA_Settings[#Data],1,CCA_SettingsStateColNum):INDEX([1]!CCA_Settings[#Data],COUNTA(CCA_SettingsEntireCol),CCA_SettingsStateColNum)
Name CCA_SettingsStateColNum: MATCH(InputStateName,[1]!CCA_Settings[#Headers],0)
Name CHIP_GroupLookup1: [1]Calc1!$C$384:$G$391
Name CompareAlabamaAdjusted_Gross_Income: [1]Calc1!$N$66:INDEX([1]Calc1!$N$66:$HH$66,COUNTIF([1]Calc1!$N$66:$HH$66,”<>”&””))
Name CompareAlabamaHousehold_Annual_Earned_Income: [1]Calc1!$N$46:INDEX([1]Calc1!$N$46:$HH$46,COUNTIF([1]Calc1!$N$46:$HH$46,”<>”&””))
Name CompareAlabamaHousehold_Annual_Income: [1]Calc1!$N$50:INDEX([1]Calc1!$N$50:$HH$50,COUNTIF([1]Calc1!$N$50:$HH$50,”<>”&””))
Name CompareAlabamaHousehold_Annual_Unearned_Income: [1]Calc1!$N$48:INDEX([1]Calc1!$N$48:$HH$48,COUNTIF([1]Calc1!$N$48:$HH$48,”<>”&””))
Name CompareAlabamaHousehold_Monthly_Earned_Income: [1]Calc1!$N$45:INDEX([1]Calc1!$N$45:$HH$45,COUNTIF([1]Calc1!$N$45:$HH$45,”<>”&””))
Name CompareAlabamaHousehold_Monthly_Income: [1]Calc1!$N$49:INDEX([1]Calc1!$N$49:$HH$49,COUNTIF([1]Calc1!$N$49:$HH$49,”<>”&””))
Name CompareAlabamaHousehold_Monthly_Unearned_Income: [1]Calc1!$N$47:INDEX([1]Calc1!$N$47:$HH$47,COUNTIF([1]Calc1!$N$47:$HH$47,”<>”&””))
Name CompareAlabamaOutputACTC: [1]Calc1!$N$140:$HF$140
Name CompareAlabamaOutputChildCareSubsidyFinal: [1]Calc1!$N$588:$HF$588
Name CompareAlabamaOutputCHIP: [1]Calc1!$N$419:$HF$419
Name CompareAlabamaOutputComboCashAssistance: CompareAlabamaOutputTANF + CompareAlabamaOutputSSI +CompareAlabamaOutputLIHEAP
Name CompareAlabamaOutputComboFoodAssistance: CompareAlabamaOutputSNAP + CompareAlabamaOutputWIC + CompareAlabamaOutputSubsidizedSchoolMeals
Name CompareAlabamaOutputComboMedicalAssistance: CompareAlabamaOutputMedicaid + CompareAlabamaOutputCHIP + CompareAlabamaOutputHIXPTC
Name CompareAlabamaOutputComboNetEarnings: CompareAlabamaAdjusted_Gross_Income - CompareAlabamaOutputFICA - CompareAlabamaOutputFedTax - CompareAlabamaOutputStateTax
Name CompareAlabamaOutputComboRefundableTaxCredits: CompareAlabamaOutputEITC + CompareAlabamaOutputACTC + CompareAlabamaOutputStateEITC + CompareAlabamaOutputCTC
Name CompareAlabamaOutputCTC: [1]Calc1!$N$108:$HF$108
Name CompareAlabamaOutputEITC: [1]Calc1!$N$122:$HF$122
Name CompareAlabamaOutputFedTax: [1]Calc1!$N$102:$HF$102
Name CompareAlabamaOutputFICA: [1]Calc1!$N$54:$HF$54
Name CompareAlabamaOutputHIXPTC: [1]Calc1!$N$462:$HF$462
Name CompareAlabamaOutputInterval: [1]Calc1!$N$2:$HF$2
Name CompareAlabamaOutputLIHEAP: [1]Calc1!$N$711:$HF$711
Name CompareAlabamaOutputMedicaid: [1]Calc1!$N$375:$HF$375
Name CompareAlabamaOutputMedicaidAndCHIP: CompareAlabamaOutputMedicaid + CompareAlabamaOutputCHIP
Name CompareAlabamaOutputMomHourlyWage: [1]Calc1!$N$10:$HF$10
Name CompareAlabamaOutputMomWeeklyHours: [1]Calc1!$N$5:$HF$5
Name CompareAlabamaOutputSec8Entry: [1]Calc1!$N$685:$HF$685
Name CompareAlabamaOutputSec8Extended: [1]Calc1!$N$690:$HF$690
Name CompareAlabamaOutputSec8Final: [1]Calc1!$N$688:$HF$688
Name CompareAlabamaOutputSNAP: [1]Calc1!$N$313:$HF$313
Name CompareAlabamaOutputSSI: [1]Calc1!$N$280:$HF$280
Name CompareAlabamaOutputStackPlusCashAssistance: CompareAlabamaOutputStackPlusRefundableTaxCredits + CompareAlabamaOutputComboCashAssistance
Name CompareAlabamaOutputStackPlusChildCareFinal: CompareAlabamaOutputStackPlusMedicalAssistance + CompareAlabamaOutputChildCareSubsidyFinal
Name CompareAlabamaOutputStackPlusFoodAssistance: CompareAlabamaOutputStackPlusCashAssistance + CompareAlabamaOutputComboFoodAssistance
Name CompareAlabamaOutputStackPlusHIXPTC: CompareAlabamaOutputStackPlusMedicaidAndCHIP + CompareAlabamaOutputHIXPTC
Name CompareAlabamaOutputStackPlusMedicaidAndCHIP: CompareAlabamaOutputStackPlusFoodAssistance + CompareAlabamaOutputMedicaid + CompareAlabamaOutputCHIP
Name CompareAlabamaOutputStackPlusMedicalAssistance: CompareAlabamaOutputStackPlusFoodAssistance + CompareAlabamaOutputComboMedicalAssistance
Name CompareAlabamaOutputStackPlusRefundableTaxCredits: CompareAlabamaOutputComboNetEarnings+CompareAlabamaOutputComboRefundableTaxCredits
Name CompareAlabamaOutputStackPlusSec8Entry: CompareAlabamaOutputStackPlusChildCareFinal + CompareAlabamaOutputSec8Entry
Name CompareAlabamaOutputStackPlusSec8Entry_Graph: CompareAlabamaOutputStackPlusChildCareFinal + CompareAlabamaOutputSec8Final
Name CompareAlabamaOutputStackPlusSec8Extended: CompareAlabamaOutputStackPlusSec8Entry + CompareAlabamaOutputSec8Extended
Name CompareAlabamaOutputStateEITC: [1]Calc1!$N$221:$HF$221
Name CompareAlabamaOutputStateTax: [1]Calc1!$N$206:$HF$206
Name CompareAlabamaOutputSubsidizedSchoolMeals: [1]Calc1!$N$346:$HF$346
Name CompareAlabamaOutputTANF: [1]Calc1!$N$267:$HF$267
Name CompareAlabamaOutputWIC: [1]Calc1!$N$335:$HF$335
Name CompareFloridaAdjusted_Gross_Income: [1]Calc1!$N$66:INDEX([1]Calc1!$N$66:$HH$66,COUNTIF([1]Calc1!$N$66:$HH$66,”<>”&””))
Name CompareFloridaHousehold_Annual_Earned_Income: [1]Calc1!$N$46:INDEX([1]Calc1!$N$46:$HH$46,COUNTIF([1]Calc1!$N$46:$HH$46,”<>”&””))
Name CompareFloridaHousehold_Annual_Income: [1]Calc1!$N$50:INDEX([1]Calc1!$N$50:$HH$50,COUNTIF([1]Calc1!$N$50:$HH$50,”<>”&””))
Name CompareFloridaHousehold_Annual_Unearned_Income: [1]Calc1!$N$48:INDEX([1]Calc1!$N$48:$HH$48,COUNTIF([1]Calc1!$N$48:$HH$48,”<>”&””))

Sheet BLS Data
A1: Chained Consumer Price Index for All Urban Consumers (C-CPI-U): U.S. city average | R1: Chained Consumer Price Index for All Urban Consumers (C-CPI-U): U.S. city average
A2: Original Data Value | R2: Original Data Value
A4: Series Id: | B4: SUUR0000SAM2 | R4: Series Id: | S4: SUUR0000SAM
A5: Not Seasonally Adjusted | R5: Not Seasonally Adjusted
A6: Series Title: | B6: Medical care services in U.S. city average, all urban consumers, chained, not seasonally adjusted | R6: Series Title: | S6: Medical care in U.S. city average, all urban consumers, chained, not seasonally adjusted
A7: Area: | B7: U.S. city average | R7: Area: | S7: U.S. city average
A8: Item: | B8: Medical care services | R8: Item: | S8: Medical care
A9: Base Period: | B9: DECEMBER 1999=100 | R9: Base Period: | S9: DECEMBER 1999=100
A10: Years: | B10: 2014 to 2024 | R10: Years: | S10: 2014 to 2024
A12: Year | B12: Jan | C12: Feb | D12: Mar | E12: Apr | F12: May | G12: Jun | H12: Jul | I12: Aug | J12: Sep | K12: Oct | L12: Nov | M12: Dec | O12: average | R12: Year | S12: Jan | T12: Feb | U12: Mar | V12: Apr | W12: May | X12: Jun | Y12: Jul | Z12: Aug | AA12: Sep | AB12: Oct | AC12: Nov | AD12: Dec
A13: 2014 | B13: 175.801 | C13: 177.026 | D13: 177.383 | E13: 177.591 | F13: 177.864 | G13: 177.776 | H13: 177.864 | I13: 177.683 | J13: 177.877 | K13: 178.116 | L13: 178.616 | M13: 178.971 | R13: 2014 | S13: 166.347 | T13: 167.597 | U13: 167.763 | V13: 168.027 | W13: 168.332 | X13: 168.445 | Y13: 168.638 | Z13: 168.514 | AA13: 168.83 | AB13: 169.01 | AC13: 169.508 | AD13: 169.993
A14: 2015 | B14: 179.709 | C14: 179.793 | D14: 180.654 | E14: 182.094 | F14: 182.266 | G14: 181.666 | H14: 181.737 | I14: 181.491 | J14: 182.003 | K14: 183.585 | L14: 184.206 | M14: 184.243 | R14: 2015 | S14: 170.609 | T14: 171.039 | U14: 171.719 | V14: 172.838 | W14: 172.991 | X14: 172.506 | Y14: 172.628 | Z14: 172.579 | AA14: 172.909 | AB14: 174.109 | AC14: 174.612 | AD14: 174.5
A15: 2016 | B15: 185.643 | C15: 187.13 | D15: 187.256 | E15: 187.711 | F15: 188.724 | G15: 188.842 | H15: 189.511 | I15: 190.87 | J15: 190.979 | K15: 190.989 | L15: 191.338 | M15: 191.41 | R15: 2016 | S15: 175.772 | T15: 177.273 | U15: 177.437 | V15: 177.869 | W15: 178.388 | X15: 178.74 | Y15: 179.489 | Z15: 181.028 | AA15: 181.294 | AB15: 181.302 | AC15: 181.35 | AD15: 181.416
A16: 2017 | B16: 192.249 | C16: 193.405 | D16: 193.393 | E16: 193.209 | F16: 193.121 | G16: 193.094 | H16: 193.442 | I16: 193.81 | J16: 194.081 | K16: 194.454 | L16: 194.305 | M16: 194.34 | R16: 2017 | S16: 182.282 | T16: 183.309 | U16: 183.328 | V16: 182.9 | W16: 182.86 | X16: 183.042 | Y16: 183.624 | Z16: 183.999 | AA16: 183.942 | AB16: 184.159 | AC16: 184.147 | AD16: 184.317
A17: 2018 | B17: 195.67 | C17: 196.37 | D17: 196.971 | E17: 197.158 | F17: 197.064 | G17: 197.44 | H17: 197.346 | I17: 196.741 | J17: 197.173 | K17: 197.547 | L17: 198.14 | M17: 198.677 | R17: 2018 | S17: 185.361 | T17: 186.032 | U17: 186.483 | V17: 186.525 | W17: 186.736 | X17: 187.148 | Y17: 186.798 | Z17: 186.317 | AA17: 186.506 | AB17: 186.73 | AC17: 187.271 | AD17: 187.441
A18: 2019 | B18: 199.81 | C18: 200.645 | D18: 200.906 | E18: 201.088 | F18: 201.919 | G18: 202.404 | H18: 203.241 | I18: 204.427 | J18: 205.033 | K18: 206.483 | L18: 207.155 | M18: 207.516 | R18: 2019 | S18: 188.415 | T18: 188.896 | U18: 189.21 | V18: 189.513 | W18: 190.157 | X18: 190.43 | Y18: 191.158 | Z18: 192.296 | AA18: 192.449 | AB18: 193.749 | AC18: 194.233 | AD18: 194.678
A19: 2020 | B19: 208.707 | C19: 209.641 | D19: 210.279 | E19: 210.883 | F19: 211.658 | G19: 212.323 | H19: 213.148 | I19: 213.237 | J19: 213.369 | K19: 212.915 | L19: 212.842 | M19: 212.575 | P19: Factor | R19: 2020 | S19: 195.414 | T19: 196.045 | U19: 196.531 | V19: 196.899 | W19: 197.531 | X19: 198.025 | Y19: 198.661 | Z19: 198.805 | AA19: 198.674 | AB19: 198.093 | AC19: 197.832 | AD19: 197.529 | AG19: Factor | AH19: FFY | AI19: CY | AJ19: Factor
A20: 2021 | B20: 214.466 | C20: 216.05 | D20: 216.423 | E20: 216.131 | F20: 215.874 | G20: 215.69 | H20: 216.346 | I20: 216.926 | J20: 216.643 | K20: 217.606 | L20: 218.099 | M20: 218.536 | O20: =AVERAGE(B20:M20) -> 216.56583 | R20: 2021 | S20: 198.949 | T20: 199.923 | U20: 200.211 | V20: 200.139 | W20: 199.982 | X20: 199.718 | Y20: 200.284 | Z20: 200.66 | AA20: 200.573 | AB20: 201.478 | AC20: 201.882 | AD20: 202.283 | AF20: =AVERAGE(S18:AD18) -> 191.26533 | AH20: =AVERAGE(AB17:AD17,S18:AA18) -> 189.49717 | AI20: =AVERAGE(S18:AD18) -> 191.26533 | AJ20: =AI20/AH$22 -> 0.95876633 | AK20: 2019
A21: 2022 | B21: 220.691 | C21: 221.538 | D21: 222.771 | E21: 223.611 | F21: 224.479 | G21: 225.725 | H21: 226.769 | I21: 228.648 | J21: 230.049 | K21: 228.914 | L21: 227.214 | M21: 226.996 | O21: =AVERAGE(B21:M21) -> 225.61708 | R21: 2022 | S21: 204.148 | T21: 204.917 | U21: 205.993 | V21: 206.67 | W21: 207.439 | X21: 208.532 | Y21: 209.562 | Z21: 211.077 | AA21: 212.052 | AB21: 211.173 | AC21: 209.973 | AD21: 209.862 | AF21: =AVERAGE(S19:AD19) -> 197.50325 | AH21: =AVERAGE(AB18:AD18,S19:AA19) -> 196.60375 | AI21: =AVERAGE(S19:AD19) -> 197.50325 | AJ21: =AI21/AH$22 -> 0.99003548 | AK21: 2020
A22: 2023 | B22: 226.763 | C22: 225.502 | D22: 223.901 | E22: 223.119 | F22: 222.705 | G22: 222.378 | H22: 221.638 | I22: 221.872 | J22: 222.017 | K22: 222.399 | L22: 223.184 | M22: 224.051 | O22: =AVERAGE(B22:M22) -> 223.29408 | P22: =O22/O20 -> 1.0310679 | R22: 2023 | S22: 210.103 | T22: 209.225 | U22: 208.283 | V22: 207.907 | W22: 207.908 | X22: 207.813 | Y22: 207.439 | Z22: 207.827 | AA22: 207.814 | AB22: 208.256 | AC22: 209.022 | AD22: 209.637 | AF22: =AVERAGE(S20:AD20) -> 200.50683 | AH22: =AVERAGE(AB19:AD19,S20:AA20) -> 199.49108 | AI22: =AVERAGE(S20:AD20) -> 200.50683 | AJ22: =AI22/AH$22 -> 1.0050917 | AK22: 2021
A23: 2024 | B23: 226.252 | C23: 226.175 | D23: 227.485 | E23: 228.095 | F23: 228.74 | G23: 229.161 | R23: 2024 | S23: 211.079 | T23: 211.052 | U23: 212.119 | V23: 212.753 | W23: 213.741 | X23: 214.134 | AF23: =AVERAGE(S21:AD21) -> 208.44983 | AI23: =AVERAGE(S21:AD21) -> 208.44983 | AJ23: =AI23/AH$22 -> 1.044908 | AK23: 2022
AF24: =AVERAGE(S22:AD22) -> 208.43617 | AG24: =AF24/AF22 -> 1.0395464 | AI24: =AVERAGE(S22:AD22) -> 208.43617 | AJ24: =AI24/AH$22 -> 1.0448395 | AK24: 2023
AH25: Projected | AI25: =(X23/S23)^(1/6) -> 1.0023978 | AJ25: =AI25^12*AJ24 -> 1.0753028 | AK25: 2024

Sheet Mcaid
A1: Mcaid | B1: Medicaid
B3: Statute
C4: 42 U.S. Code Chapter 7 - Social Secuirty Subchapter XIX— Grants to States for Medical Assistance Programs
C5: https://www.law.cornell.edu/uscode/text/42/chapter-7/subchapter-XIX
B7: Federal Administration
C8: U.S. Department of Health and Human Services
C9: Center for Medicare and Medicaid Services (CMS)
C10: Medicaid.Gov
C11: https://www.medicaid.gov | F11: 2019 | G11: 2020 | H11: 2021 | I11: 2022 | J11: 2023
E12: Effective Date | F12: 43556 | G12: 43556 | H12: 44105 | I12: 44743 | J12: 44743
B13: Lookup Table: MedicaidIncomeEligibility
C15: State | D15: Year | E15: Children Medicaid Ages 0 | F15: Children Medicaid Ages 1-5 | G15: Children Medicaid Ages 6-18 | H15: Children Separate CHIP | I15: Pregnant Women Medicaid | J15: Pregnant Women CHIP | K15: Adults (Medicaid) Parent/Caretaker | L15: Adults (Medicaid) Expansion to Adults
C16: Alabama | D16: 2019 | E16: 1.41 | F16: 1.41 | G16: 1.41 | H16: 3.12 | I16: 1.41 | J16: N/A | K16: 0.13 | L16: No
C17: Alaska | D17: 2019 | E17: 2.03 | F17: 2.03 | G17: 2.03 | H17: N/A | I17: 2 | J17: N/A | K17: 1.35 | L17: 1.33
C18: Arizona | D18: 2019 | E18: 1.47 | F18: 1.41 | G18: 1.33 | H18: 2 | I18: 1.56 | J18: N/A | K18: 1.06 | L18: 1.33
C19: Arkansas | D19: 2019 | E19: 1.42 | F19: 1.42 | G19: 1.42 | H19: 2.11 | I19: 2.09 | J19: N/A | K19: 0.17 | L19: 1.33
C20: California | D20: 2019 | E20: 2.61 | F20: 2.61 | G20: 2.61 | H20: N/A | I20: 2.08 | J20: N/A | K20: 1.09 | L20: 1.33
C21: Colorado | D21: 2019 | E21: 1.42 | F21: 1.42 | G21: 1.42 | H21: 2.6 | I21: 1.95 | J21: 2.6 | K21: 0.68 | L21: 1.33
C22: Connecticut | D22: 2019 | E22: 1.96 | F22: 1.96 | G22: 1.96 | H22: 3.18 | I22: 2.58 | J22: N/A | K22: 1.5 | L22: 1.33
C23: Delaware | D23: 2019 | E23: 2.12 | F23: 1.42 | G23: 1.33 | H23: 2.12 | I23: 2.12 | J23: N/A | K23: 0.87 | L23: 1.33
C24: District of Columbia | D24: 2019 | E24: 3.19 | F24: 3.19 | G24: 3.19 | H24: N/A | I24: 3.19 | J24: N/A | K24: 2.16 | L24: 2.1
C25: Florida | D25: 2019 | E25: 2.06 | F25: 1.4 | G25: 1.33 | H25: 2.1 | I25: 1.91 | J25: N/A | K25: 0.28 | L25: No
C26: Georgia | D26: 2019 | E26: 2.05 | F26: 1.49 | G26: 1.33 | H26: 2.47 | I26: 2.2 | J26: N/A | K26: 0.32 | L26: No
C27: Hawaii | D27: 2019 | E27: 3.08 | F27: 3.08 | G27: 3.08 | H27: N/A | I27: 1.91 | J27: N/A | K27: 1.05 | L27: 1.33
C28: Idaho | D28: 2019 | E28: 1.42 | F28: 1.42 | G28: 1.33 | H28: 1.85 | I28: 1.33 | J28: N/A | K28: 0.23 | L28: No
C29: Illinois | D29: 2019 | E29: 1.42 | F29: 1.42 | G29: 1.42 | H29: 3.13 | I29: 2.08 | J29: N/A | K29: 1.33 | L29: 1.33
C30: Indiana | D30: 2019 | E30: 2.08 | F30: 1.58 | G30: 1.58 | H30: 2.5 | I30: 2.08 | J30: N/A | K30: 0.19 | L30: 1.33
C31: Iowa | D31: 2019 | E31: 3.75 | F31: 1.67 | G31: 1.67 | H31: 3.02 | I31: 3.75 | J31: N/A | K31: 0.51 | L31: 1.33
C32: Kansas | D32: 2019 | E32: 1.66 | F32: 1.49 | G32: 1.33 | H32: 2.3 | I32: 1.66 | J32: N/A | K32: 0.33 | L32: No
C33: Kentucky | D33: 2019 | E33: 1.95 | F33: 1.59 | G33: 1.59 | H33: 2.13 | I33: 1.95 | J33: N/A | K33: 0.24 | L33: 1.33
C34: Louisiana | D34: 2019 | E34: 2.12 | F34: 2.12 | G34: 2.12 | H34: 2.5 | I34: 1.33 | J34: N/A | K34: 0.19 | L34: 1.33
C35: Maine | D35: 2019 | E35: 1.91 | F35: 1.57 | G35: 1.57 | H35: 2.08 | I35: 2.09 | J35: N/A | K35: 1 | L35: Yes
C36: Maryland | D36: 2019 | E36: 3.17 | F36: 3.17 | G36: 3.17 | H36: N/A | I36: 2.59 | J36: N/A | K36: 1.23 | L36: 1.33
C37: Massachusetts | D37: 2019 | E37: 2 | F37: 1.5 | G37: 1.5 | H37: 3 | I37: 2 | J37: N/A | K37: 1.33 | L37: 1.33
C38: Michigan | D38: 2019 | E38: 2.12 | F38: 2.12 | G38: 2.12 | H38: N/A | I38: 1.95 | J38: N/A | K38: 0.54 | L38: 1.33
C39: Minnesota | D39: 2019 | E39: 2.83 | F39: 2.75 | G39: 2.75 | H39: N/A | I39: 2.78 | J39: N/A | K39: 1.33 | L39: 2
C40: Mississippi | D40: 2019 | E40: 1.94 | F40: 1.43 | G40: 1.33 | H40: 2.09 | I40: 1.94 | J40: N/A | K40: 0.23 | L40: No
C41: Missouri | D41: 2019 | E41: 1.96 | F41: 1.5 | G41: 1.5 | H41: 3 | I41: 1.96 | J41: 3 | K41: 0.17 | L41: No
C42: Montana | D42: 2019 | E42: 1.43 | F42: 1.43 | G42: 1.43 | H42: 2.61 | I42: 1.57 | J42: N/A | K42: 0.24 | L42: 1.33
C43: Nebraska | D43: 2019 | E43: 2.13 | F43: 2.13 | G43: 2.13 | H43: N/A | I43: 1.94 | J43: N/A | K43: 0.58 | L43: No
...

Sheet Cliff WB PMPM
A1: State | B1: Year | C1: Total | D1: Child | E1: Expansion Adults | F1: Adults | G1: Disabled | H1: Aged
A2: National | B2: 2019 | C2: =ROUND(C54/'BLS Data'!$AJ$20,2) -> 809.61 | D2: =ROUND(D54/'BLS Data'!$AJ$20,2) -> 316.84 | E2: =ROUND(E54/'BLS Data'!$AJ$20,2) -> 662.48 | F2: =ROUND(F54/'BLS Data'!$AJ$20,2) -> 563.71 | G2: =ROUND(G54/'BLS Data'!$AJ$20,2) -> 2361.43 | H2: =ROUND(H54/'BLS Data'!$AJ$20,2) -> 2139.49
A3: Alabama | B3: 2019 | C3: =ROUND(C55/'BLS Data'!$AJ$20,2) -> 604.27 | D3: =ROUND(D55/'BLS Data'!$AJ$20,2) -> 233.01 | E3: N/A | F3: =ROUND(F55/'BLS Data'!$AJ$20,2) -> 444.05 | G3: =ROUND(G55/'BLS Data'!$AJ$20,2) -> 1540.14 | H3: =ROUND(H55/'BLS Data'!$AJ$20,2) -> 2139.49
A4: Alaska | B4: 2019 | C4: =ROUND(C56/'BLS Data'!$AJ$20,2) -> 801.46 | D4: =ROUND(D56/'BLS Data'!$AJ$20,2) -> 450.9 | E4: =ROUND(E56/'BLS Data'!$AJ$20,2) -> 724.02 | F4: =ROUND(F56/'BLS Data'!$AJ$20,2) -> 625.87 | G4: =ROUND(G56/'BLS Data'!$AJ$20,2) -> 2885.2 | H4: =ROUND(H56/'BLS Data'!$AJ$20,2) -> 2010.88
A5: Arizona | B5: 2019 | C5: =ROUND(C57/'BLS Data'!$AJ$20,2) -> 787.15 | D5: =ROUND(D57/'BLS Data'!$AJ$20,2) -> 316.23 | E5: =ROUND(E57/'BLS Data'!$AJ$20,2) -> 848.25 | F5: =ROUND(F57/'BLS Data'!$AJ$20,2) -> 611.47 | G5: =ROUND(G57/'BLS Data'!$AJ$20,2) -> 2793.45 | H5: =ROUND(H57/'BLS Data'!$AJ$20,2) -> 1101.61
A6: Arkansas | B6: 2019 | C6: =ROUND(C58/'BLS Data'!$AJ$20,2) -> 692.68 | D6: =ROUND(D58/'BLS Data'!$AJ$20,2) -> 358.37 | E6: =ROUND(E58/'BLS Data'!$AJ$20,2) -> 634.47 | F6: =ROUND(F58/'BLS Data'!$AJ$20,2) -> 525.61 | G6: =ROUND(G58/'BLS Data'!$AJ$20,2) -> 1651.02 | H6: =ROUND(H58/'BLS Data'!$AJ$20,2) -> 1929.05
A7: California | B7: 2019 | C7: =ROUND(C59/'BLS Data'!$AJ$20,2) -> 777.49 | D7: =ROUND(D59/'BLS Data'!$AJ$20,2) -> 324.22 | E7: =ROUND(E59/'BLS Data'!$AJ$20,2) -> 549.06 | F7: =ROUND(F59/'BLS Data'!$AJ$20,2) -> 578.98 | G7: =ROUND(G59/'BLS Data'!$AJ$20,2) -> 2792.66 | H7: =ROUND(H59/'BLS Data'!$AJ$20,2) -> 1527.49
A8: Colorado | B8: 2019 | C8: =ROUND(C60/'BLS Data'!$AJ$20,2) -> 673.19 | D8: =ROUND(D60/'BLS Data'!$AJ$20,2) -> 273.12 | E8: =ROUND(E60/'BLS Data'!$AJ$20,2) -> 506.73 | F8: =ROUND(F60/'BLS Data'!$AJ$20,2) -> 505.76 | G8: =ROUND(G60/'BLS Data'!$AJ$20,2) -> 2957.89 | H8: =ROUND(H60/'BLS Data'!$AJ$20,2) -> 2711.11
A9: Connecticut | B9: 2019 | C9: =ROUND(C61/'BLS Data'!$AJ$20,2) -> 816.12 | D9: =ROUND(D61/'BLS Data'!$AJ$20,2) -> 314.74 | E9: =ROUND(E61/'BLS Data'!$AJ$20,2) -> 646.32 | F9: =ROUND(F61/'BLS Data'!$AJ$20,2) -> 510.86 | G9: =ROUND(G61/'BLS Data'!$AJ$20,2) -> 4940.59 | H9: =ROUND(H61/'BLS Data'!$AJ$20,2) -> 3845.56
A10: Delaware | B10: 2019 | C10: =ROUND(C62/'BLS Data'!$AJ$20,2) -> 871.52 | D10: =ROUND(D62/'BLS Data'!$AJ$20,2) -> 401.12 | E10: =ROUND(E62/'BLS Data'!$AJ$20,2) -> 708.66 | F10: =ROUND(F62/'BLS Data'!$AJ$20,2) -> 821.73 | G10: =ROUND(G62/'BLS Data'!$AJ$20,2) -> 3008.99 | H10: =ROUND(H62/'BLS Data'!$AJ$20,2) -> 3363.23
A11: District of Columbia | B11: 2019 | C11: =ROUND(C63/'BLS Data'!$AJ$20,2) -> 1135.76 | D11: =ROUND(D63/'BLS Data'!$AJ$20,2) -> 414.55 | E11: =ROUND(E63/'BLS Data'!$AJ$20,2) -> 635.79 | F11: =ROUND(F63/'BLS Data'!$AJ$20,2) -> 622.01 | G11: =ROUND(G63/'BLS Data'!$AJ$20,2) -> 3793.32 | H11: =ROUND(H63/'BLS Data'!$AJ$20,2) -> 3437.24
A12: Florida | B12: 2019 | C12: =ROUND(C64/'BLS Data'!$AJ$20,2) -> 540.36 | D12: =ROUND(D64/'BLS Data'!$AJ$20,2) -> 221.32 | E12: N/A | F12: =ROUND(F64/'BLS Data'!$AJ$20,2) -> 336.51 | G12: =ROUND(G64/'BLS Data'!$AJ$20,2) -> 1593.51 | H12: =ROUND(H64/'BLS Data'!$AJ$20,2) -> 1539.26
A13: Georgia | B13: 2019 | C13: =ROUND(C65/'BLS Data'!$AJ$20,2) -> 514.45 | D13: =ROUND(D65/'BLS Data'!$AJ$20,2) -> 217.99 | E13: N/A | F13: =ROUND(F65/'BLS Data'!$AJ$20,2) -> 431.86 | G13: =ROUND(G65/'BLS Data'!$AJ$20,2) -> 1450.85 | H13: =ROUND(H65/'BLS Data'!$AJ$20,2) -> 1837.31
A14: Hawaii | B14: 2019 | C14: =ROUND(C66/'BLS Data'!$AJ$20,2) -> 639.48 | D14: =ROUND(D66/'BLS Data'!$AJ$20,2) -> 321.58 | E14: =ROUND(E66/'BLS Data'!$AJ$20,2) -> 545.11 | F14: =ROUND(F66/'BLS Data'!$AJ$20,2) -> 481.89 | G14: =ROUND(G66/'BLS Data'!$AJ$20,2) -> 2419.56 | H14: =ROUND(H66/'BLS Data'!$AJ$20,2) -> 1439.27
A15: Idaho | B15: 2019 | C15: =ROUND(C67/'BLS Data'!$AJ$20,2) -> 690.66 | D15: =ROUND(D67/'BLS Data'!$AJ$20,2) -> 277.25 | E15: =ROUND(E67/'BLS Data'!$AJ$20,2) -> 539.39 | F15: =ROUND(F67/'BLS Data'!$AJ$20,2) -> 561.61 | G15: =ROUND(G67/'BLS Data'!$AJ$20,2) -> 2294.79 | H15: =ROUND(H67/'BLS Data'!$AJ$20,2) -> 1852.41
A16: Illinois | B16: 2019 | C16: =ROUND(C68/'BLS Data'!$AJ$20,2) -> 770.38 | D16: =ROUND(D68/'BLS Data'!$AJ$20,2) -> 364.69 | E16: =ROUND(E68/'BLS Data'!$AJ$20,2) -> 690.22 | F16: =ROUND(F68/'BLS Data'!$AJ$20,2) -> 533.95 | G16: =ROUND(G68/'BLS Data'!$AJ$20,2) -> 1529.34 | H16: =ROUND(H68/'BLS Data'!$AJ$20,2) -> 1936.52
A17: Indiana | B17: 2019 | C17: =ROUND(C69/'BLS Data'!$AJ$20,2) -> 828.59 | D17: =ROUND(D69/'BLS Data'!$AJ$20,2) -> 257.76 | E17: =ROUND(E69/'BLS Data'!$AJ$20,2) -> 804 | F17: =ROUND(F69/'BLS Data'!$AJ$20,2) -> 939.02 | G17: =ROUND(G69/'BLS Data'!$AJ$20,2) -> 1997.18 | H17: =ROUND(H69/'BLS Data'!$AJ$20,2) -> 2952.71
A18: Iowa | B18: 2019 | C18: =ROUND(C70/'BLS Data'!$AJ$20,2) -> 749.13 | D18: =ROUND(D70/'BLS Data'!$AJ$20,2) -> 273.04 | E18: =ROUND(E70/'BLS Data'!$AJ$20,2) -> 577.76 | F18: =ROUND(F70/'BLS Data'!$AJ$20,2) -> 555.55 | G18: =ROUND(G70/'BLS Data'!$AJ$20,2) -> 2383.47 | H18: =ROUND(H70/'BLS Data'!$AJ$20,2) -> 2694.51
A19: Kansas | B19: 2019 | C19: =ROUND(C71/'BLS Data'!$AJ$20,2) -> 890.82 | D19: =ROUND(D71/'BLS Data'!$AJ$20,2) -> 320.7 | E19: N/A | F19: =ROUND(F71/'BLS Data'!$AJ$20,2) -> 572.5 | G19: =ROUND(G71/'BLS Data'!$AJ$20,2) -> 2480.56 | H19: =ROUND(H71/'BLS Data'!$AJ$20,2) -> 2881.07
A20: Kentucky | B20: 2019 | C20: =ROUND(C72/'BLS Data'!$AJ$20,2) -> 824.37 | D20: =ROUND(D72/'BLS Data'!$AJ$20,2) -> 403.58 | E20: =ROUND(E72/'BLS Data'!$AJ$20,2) -> 707.35 | F20: =ROUND(F72/'BLS Data'!$AJ$20,2) -> 721.39 | G20: =ROUND(G72/'BLS Data'!$AJ$20,2) -> 2073.3 | H20: =ROUND(H72/'BLS Data'!$AJ$20,2) -> 2083.12
A21: Louisiana | B21: 2019 | C21: =ROUND(C73/'BLS Data'!$AJ$20,2) -> 675.64 | D21: =ROUND(D73/'BLS Data'!$AJ$20,2) -> 283.22 | E21: =ROUND(E73/'BLS Data'!$AJ$20,2) -> 628.5 | F21: =ROUND(F73/'BLS Data'!$AJ$20,2) -> 592.16 | G21: =ROUND(G73/'BLS Data'!$AJ$20,2) -> 1691.23 | H21: =ROUND(H73/'BLS Data'!$AJ$20,2) -> 1630.21
A22: Maine | B22: 2019 | C22: =ROUND(C74/'BLS Data'!$AJ$20,2) -> 950.52 | D22: =ROUND(D74/'BLS Data'!$AJ$20,2) -> 431.86 | E22: =ROUND(E74/'BLS Data'!$AJ$20,2) -> 579.95 | F22: =ROUND(F74/'BLS Data'!$AJ$20,2) -> 500.33 | G22: =ROUND(G74/'BLS Data'!$AJ$20,2) -> 2322.28 | H22: =ROUND(H74/'BLS Data'!$AJ$20,2) -> 2167.5
A23: Maryland | B23: 2019 | C23: =ROUND(C75/'BLS Data'!$AJ$20,2) -> 843.16 | D23: =ROUND(D75/'BLS Data'!$AJ$20,2) -> 314.12 | E23: =ROUND(E75/'BLS Data'!$AJ$20,2) -> 769.76 | F23: =ROUND(F75/'BLS Data'!$AJ$20,2) -> 569.08 | G23: =ROUND(G75/'BLS Data'!$AJ$20,2) -> 3034.36 | H23: =ROUND(H75/'BLS Data'!$AJ$20,2) -> 3194.83
A24: Massachusetts | B24: 2019 | C24: =ROUND(C76/'BLS Data'!$AJ$20,2) -> 1048.15 | D24: =ROUND(D76/'BLS Data'!$AJ$20,2) -> 396.56 | E24: =ROUND(E76/'BLS Data'!$AJ$20,2) -> 707.61 | F24: =ROUND(F76/'BLS Data'!$AJ$20,2) -> 536.68 | G24: =ROUND(G76/'BLS Data'!$AJ$20,2) -> 1918.96 | H24: =ROUND(H76/'BLS Data'!$AJ$20,2) -> 2438.34
A25: Michigan | B25: 2019 | C25: =ROUND(C77/'BLS Data'!$AJ$20,2) -> 666.87 | D25: =ROUND(D77/'BLS Data'!$AJ$20,2) -> 243.89 | E25: =ROUND(E77/'BLS Data'!$AJ$20,2) -> 572.5 | F25: =ROUND(F77/'BLS Data'!$AJ$20,2) -> 465.2 | G25: =ROUND(G77/'BLS Data'!$AJ$20,2) -> 1734.51 | H25: =ROUND(H77/'BLS Data'!$AJ$20,2) -> 2055.57
A26: Minnesota | B26: 2019 | C26: =ROUND(C78/'BLS Data'!$AJ$20,2) -> 1091.26 | D26: =ROUND(D78/'BLS Data'!$AJ$20,2) -> 349.5 | E26: =ROUND(E78/'BLS Data'!$AJ$20,2) -> 932.88 | F26: =ROUND(F78/'BLS Data'!$AJ$20,2) -> 636.23 | G26: =ROUND(G78/'BLS Data'!$AJ$20,2) -> 4432.27 | H26: =ROUND(H78/'BLS Data'!$AJ$20,2) -> 3430.66
A27: Mississippi | B27: 2019 | C27: =ROUND(C79/'BLS Data'!$AJ$20,2) -> 709.8 | D27: =ROUND(D79/'BLS Data'!$AJ$20,2) -> 294.72 | E27: N/A | F27: =ROUND(F79/'BLS Data'!$AJ$20,2) -> 578.56 | G27: =ROUND(G79/'BLS Data'!$AJ$20,2) -> 1671.83 | H27: =ROUND(H79/'BLS Data'!$AJ$20,2) -> 2095.68
A28: Missouri | B28: 2019 | C28: =ROUND(C80/'BLS Data'!$AJ$20,2) -> 872.57 | D28: =ROUND(D80/'BLS Data'!$AJ$20,2) -> 380.23 | E28: =ROUND(E80/'BLS Data'!$AJ$20,2) -> 532.47 | F28: =ROUND(F80/'BLS Data'!$AJ$20,2) -> 547.3 | G28: =ROUND(G80/'BLS Data'!$AJ$20,2) -> 2465.28 | H28: =ROUND(H80/'BLS Data'!$AJ$20,2) -> 1982.69
A29: Montana | B29: 2019 | C29: =ROUND(C81/'BLS Data'!$AJ$20,2) -> 744.04 | D29: =ROUND(D81/'BLS Data'!$AJ$20,2) -> 374.26 | E29: =ROUND(E81/'BLS Data'!$AJ$20,2) -> 707.09 | F29: =ROUND(F81/'BLS Data'!$AJ$20,2) -> 676.26 | G29: =ROUND(G81/'BLS Data'!$AJ$20,2) -> 2049.59 | H29: =ROUND(H81/'BLS Data'!$AJ$20,2) -> 2198.22
A30: Nebraska | B30: 2019 | C30: =ROUND(C82/'BLS Data'!$AJ$20,2) -> 940.07 | D30: =ROUND(D82/'BLS Data'!$AJ$20,2) -> 322.03 | E30: =ROUND(E82/'BLS Data'!$AJ$20,2) -> 860.27 | F30: =ROUND(F82/'BLS Data'!$AJ$20,2) -> 707.61 | G30: =ROUND(G82/'BLS Data'!$AJ$20,2) -> 2685.12 | H30: =ROUND(H82/'BLS Data'!$AJ$20,2) -> 2801.09
A31: Nevada | B31: 2019 | C31: =ROUND(C83/'BLS Data'!$AJ$20,2) -> 541.85 | D31: =ROUND(D83/'BLS Data'!$AJ$20,2) -> 222.56 | E31: =ROUND(E83/'BLS Data'!$AJ$20,2) -> 568.8 | F31: =ROUND(F83/'BLS Data'!$AJ$20,2) -> 445.19 | G31: =ROUND(G83/'BLS Data'!$AJ$20,2) -> 2032.82 | H31: =ROUND(H83/'BLS Data'!$AJ$20,2) -> 1855.75
A32: New Hampshire | B32: 2019 | C32: =ROUND(C84/'BLS Data'!$AJ$20,2) -> 916.2 | D32: =ROUND(D84/'BLS Data'!$AJ$20,2) -> 399.01 | E32: =ROUND(E84/'BLS Data'!$AJ$20,2) -> 634.03 | F32: =ROUND(F84/'BLS Data'!$AJ$20,2) -> 591.54 | G32: =ROUND(G84/'BLS Data'!$AJ$20,2) -> 2779.32 | H32: =ROUND(H84/'BLS Data'!$AJ$20,2) -> 3893.04
A33: New Jersey | B33: 2019 | C33: =ROUND(C85/'BLS Data'!$AJ$20,2) -> 900.14 | D33: =ROUND(D85/'BLS Data'!$AJ$20,2) -> 316.31 | E33: =ROUND(E85/'BLS Data'!$AJ$20,2) -> 632.28 | F33: =ROUND(F85/'BLS Data'!$AJ$20,2) -> 650.72 | G33: =ROUND(G85/'BLS Data'!$AJ$20,2) -> 3152.35 | H33: =ROUND(H85/'BLS Data'!$AJ$20,2) -> 2235.98
A34: New Mexico | B34: 2019 | C34: =ROUND(C86/'BLS Data'!$AJ$20,2) -> 735.16 | D34: =ROUND(D86/'BLS Data'!$AJ$20,2) -> 378.29 | E34: =ROUND(E86/'BLS Data'!$AJ$20,2) -> 649.4 | F34: =ROUND(F86/'BLS Data'!$AJ$20,2) -> 638.08 | G34: =ROUND(G86/'BLS Data'!$AJ$20,2) -> 2641.31 | H34: =ROUND(H86/'BLS Data'!$AJ$20,2) -> 2428.41
A35: New York | B35: 2019 | C35: =ROUND(C87/'BLS Data'!$AJ$20,2) -> 960.35 | D35: =ROUND(D87/'BLS Data'!$AJ$20,2) -> 293.48 | E35: =ROUND(E87/'BLS Data'!$AJ$20,2) -> 614.89 | F35: =ROUND(F87/'BLS Data'!$AJ$20,2) -> 526.93 | G35: =ROUND(G87/'BLS Data'!$AJ$20,2) -> 3149.19 | H35: =ROUND(H87/'BLS Data'!$AJ$20,2) -> 2896.88
A36: North Carolina | B36: 2019 | C36: =ROUND(C88/'BLS Data'!$AJ$20,2) -> 783.63 | D36: =ROUND(D88/'BLS Data'!$AJ$20,2) -> 304.46 | E36: N/A | F36: =ROUND(F88/'BLS Data'!$AJ$20,2) -> 577.14 | G36: =ROUND(G88/'BLS Data'!$AJ$20,2) -> 1996.47 | H36: =ROUND(H88/'BLS Data'!$AJ$20,2) -> 1840.55
A37: North Dakota | B37: 2019 | C37: =ROUND(C89/'BLS Data'!$AJ$20,2) -> 1106.1 | D37: =ROUND(D89/'BLS Data'!$AJ$20,2) -> 372.42 | E37: =ROUND(E89/'BLS Data'!$AJ$20,2) -> 122.55 | F37: =ROUND(F89/'BLS Data'!$AJ$20,2) -> 493.22 | G37: =ROUND(G89/'BLS Data'!$AJ$20,2) -> 4218.32 | H37: =ROUND(H89/'BLS Data'!$AJ$20,2) -> 5548.29
A38: Ohio | B38: 2019 | C38: =ROUND(C90/'BLS Data'!$AJ$20,2) -> 838.93 | D38: =ROUND(D90/'BLS Data'!$AJ$20,2) -> 313.86 | E38: =ROUND(E90/'BLS Data'!$AJ$20,2) -> 702.77 | F38: =ROUND(F90/'BLS Data'!$AJ$20,2) -> 541.95 | G38: =ROUND(G90/'BLS Data'!$AJ$20,2) -> 2391.72 | H38: =ROUND(H90/'BLS Data'!$AJ$20,2) -> 2696.18
A39: Oklahoma | B39: 2019 | C39: =ROUND(C91/'BLS Data'!$AJ$20,2) -> 616.48 | D39: =ROUND(D91/'BLS Data'!$AJ$20,2) -> 341.07 | E39: =ROUND(E91/'BLS Data'!$AJ$20,2) -> 480.48 | F39: =ROUND(F91/'BLS Data'!$AJ$20,2) -> 464.15 | G39: =ROUND(G91/'BLS Data'!$AJ$20,2) -> 1666.46 | H39: =ROUND(H91/'BLS Data'!$AJ$20,2) -> 1503.53
A40: Oregon | B40: 2019 | C40: =ROUND(C92/'BLS Data'!$AJ$20,2) -> 967.91 | D40: =ROUND(D92/'BLS Data'!$AJ$20,2) -> 373.81 | E40: =ROUND(E92/'BLS Data'!$AJ$20,2) -> 709.97 | F40: =ROUND(F92/'BLS Data'!$AJ$20,2) -> 943.41 | G40: =ROUND(G92/'BLS Data'!$AJ$20,2) -> 2697.5 | H40: =ROUND(H92/'BLS Data'!$AJ$20,2) -> 4570.89
...

Sheet Sheet1
