Workbook
Name ACTC: '[1]State Comparison Data'!#REF!
Name ActiveState: [1]Calc1!$D$3
Name Adjusted_Gross_Income: [1]Calc1!$R$58:INDEX([1]Calc1!$R$58:$HJ$58,COUNTIF([1]Calc1!$R$58:$HJ$58,”<>”&””))
Name Adjusted_Gross_Income: [1]Calc1!$R$58:INDEX([1]Calc1!$R$58:$HJ$58,COUNTIF([1]Calc1!$R$58:$HJ$58,”<>”&””))
Name Adjusted_Gross_Income: [1]Calc1!$R$58:INDEX([1]Calc1!$R$58:$HJ$58,COUNTIF([1]Calc1!$R$58:$HJ$58,”<>”&””))
Name Adjusted_Gross_Income: [1]Calc1!$R$58:INDEX([1]Calc1!$R$58:$HJ$58,COUNTIF([1]Calc1!$R$58:$HJ$58,”<>”&””))
Name Adjusted_Gross_Income: [1]Calc1!$R$58:INDEX([1]Calc1!$R$58:$HJ$58,COUNTIF([1]Calc1!$R$58:$HJ$58,”<>”&””))
Name Adjusted_Gross_Income: [1]Calc1!$R$58:INDEX([1]Calc1!$R$58:$HJ$58,COUNTIF([1]Calc1!$R$58:$HJ$58,”<>”&””))
Name Adjusted_Gross_Income: [1]Calc1!$R$58:INDEX([1]Calc1!$R$58:$HJ$58,COUNTIF([1]Calc1!$R$58:$HJ$58,”<>”&””))
Name Adjusted_Gross_Income: [1]Calc1!$R$58:INDEX([1]Calc1!$R$58:$HJ$58,COUNTIF([1]Calc1!$R$58:$HJ$58,”<>”&””))
Name Adjusted_Gross_Income: [1]Calc1!$R$58:INDEX([1]Calc1!$R$58:$HJ$58,COUNTIF([1]Calc1!$R$58:$HJ$58,”<>”&””))
Name AgeAdult: [1]Lists!$F$10:$F$59
Name AgeChild: [1]Lists!$H$10:$H$33
Name Apply: [1]MarriagePenalties!$B$30
Name CalculatorNewHours: [1]Inputs!$R$7
Name CalculatorNewWage: [1]Inputs!$Q$7
Name CCA_RateCategoryEntireCol: INDEX([1]!CCA_RateCategoryStates[#Data],,CHIP!CCA_RateCategoryStateColNum)
Name CCA_RateCategoryEntireCol: INDEX([1]!CCA_RateCategoryStates[#Data],,FPIG!CCA_RateCategoryStateColNum)
Name CCA_RateCategoryEntireCol: INDEX([1]!CCA_RateCategoryStates[#Data],,Mcaid!CCA_RateCategoryStateColNum)
Name CCA_RateCategoryEntireCol: INDEX([1]!CCA_RateCategoryStates[#Data],,CCA_RateCategoryStateColNum)
Name CCA_RateCategoryLookup: INDEX([1]!CCA_RateCategoryStates[#Data],1,CHIP!CCA_RateCategoryStateColNum):INDEX([1]!CCA_RateCategoryStates[#Data],COUNTA(CHIP!CCA_RateCategoryEntireCol),CHIP!CCA_RateCategoryStateColNum)
Name CCA_RateCategoryLookup: INDEX([1]!CCA_RateCategoryStates[#Data],1,FPIG!CCA_RateCategoryStateColNum):INDEX([1]!CCA_RateCategoryStates[#Data],COUNTA(FPIG!CCA_RateCategoryEntireCol),FPIG!CCA_RateCategoryStateColNum)
Name CCA_RateCategoryLookup: INDEX([1]!CCA_RateCategoryStates[#Data],1,Mcaid!CCA_RateCategoryStateColNum):INDEX([1]!CCA_RateCategoryStates[#Data],COUNTA(Mcaid!CCA_RateCategoryEntireCol),Mcaid!CCA_RateCategoryStateColNum)
Name CCA_RateCategoryLookup: INDEX([1]!CCA_RateCategoryStates[#Data],1,CCA_RateCategoryStateColNum):INDEX([1]!CCA_RateCategoryStates[#Data],COUNTA(CCA_RateCategoryEntireCol),CCA_RateCategoryStateColNum)
Name CCA_RateCategoryStateColNum: MATCH(InputStateName,[1]!CCA_RateCategoryStates[#Headers],0)
Name CCA_RateCategoryStateColNum: MATCH(InputStateName,[1]!CCA_RateCategoryStates[#Headers],0)
Name CCA_RateCategoryStateColNum: MATCH(InputStateName,[1]!CCA_RateCategoryStates[#Headers],0)
Name CCA_RateCategoryStateColNum: MATCH(InputStateName,[1]!CCA_RateCategoryStates[#Headers],0)
Name CCA_RateCategoryStatesEntireCol: INDEX([1]!CCA_RateCategoryStates[#Data],,CHIP!CCA_RateCategoryStatesStateColNum)
Name CCA_RateCategoryStatesEntireCol: INDEX([1]!CCA_RateCategoryStates[#Data],,FPIG!CCA_RateCategoryStatesStateColNum)
Name CCA_RateCategoryStatesEntireCol: INDEX([1]!CCA_RateCategoryStates[#Data],,Mcaid!CCA_RateCategoryStatesStateColNum)
Name CCA_RateCategoryStatesEntireCol: INDEX([1]!CCA_RateCategoryStates[#Data],,CCA_RateCategoryStatesStateColNum)
Name CCA_RateCategoryStatesStateColNum: MATCH(InputStateName,[1]!CCA_RateCategoryStates[#Headers],0)
Name CCA_RateCategoryStatesStateColNum: MATCH(InputStateName,[1]!CCA_RateCategoryStates[#Headers],0)
Name CCA_RateCategoryStatesStateColNum: MATCH(InputStateName,[1]!CCA_RateCategoryStates[#Headers],0)
Name CCA_RateCategoryStatesStateColNum: MATCH(InputStateName,[1]!CCA_RateCategoryStates[#Headers],0)
Name CCA_SettingsEntireCol: INDEX([1]!CCA_SettingsStates[#Data],,CHIP!CCA_SettingsStateColNum)
Name CCA_SettingsEntireCol: INDEX([1]!CCA_SettingsStates[#Data],,FPIG!CCA_SettingsStateColNum)
Name CCA_SettingsEntireCol: INDEX([1]!CCA_SettingsStates[#Data],,Mcaid!CCA_SettingsStateColNum)
Name CCA_SettingsEntireCol: INDEX([1]!CCA_SettingsStates[#Data],,CCA_SettingsStateColNum)
Name CCA_SettingsLookup: INDEX([1]!CCA_SettingsStates[#Data],1,CHIP!CCA_SettingsStateColNum):INDEX([1]!CCA_SettingsStates[#Data],COUNTA(CHIP!CCA_SettingsEntireCol),CHIP!CCA_SettingsStateColNum)
Name CCA_SettingsLookup: INDEX([1]!CCA_SettingsStates[#Data],1,FPIG!CCA_SettingsStateColNum):INDEX([1]!CCA_SettingsStates[#Data],COUNTA(FPIG!CCA_SettingsEntireCol),FPIG!CCA_SettingsStateColNum)
Name CCA_SettingsLookup: INDEX([1]!CCA_SettingsStates[#Data],1,Mcaid!CCA_SettingsStateColNum):INDEX([1]!CCA_SettingsStates[#Data],COUNTA(Mcaid!CCA_SettingsEntireCol),Mcaid!CCA_SettingsStateColNum)
Name CCA_SettingsLookup: INDEX([1]!CCA_SettingsStates[#Data],1,CCA_SettingsStateColNum):INDEX([1]!CCA_SettingsStates[#Data],COUNTA(CCA_SettingsEntireCol),CCA_SettingsStateColNum)
Name CCA_SettingsStateColNum: MATCH(InputStateName,[1]!CCA_SettingsStates[#Headers],0)
Name CCA_SettingsStateColNum: MATCH(InputStateName,[1]!CCA_SettingsStates[#Headers],0)
Name CCA_SettingsStateColNum: MATCH(InputStateName,[1]!CCA_SettingsStates[#Headers],0)
Name CCA_SettingsStateColNum: MATCH(InputStateName,[1]!CCA_SettingsStates[#Headers],0)
Name CCA_SettingsStatesEntireCol: INDEX([1]!CCA_SettingsStates[#Data],,CHIP!CCA_SettingsStatesStateColNum)
Name CCA_SettingsStatesEntireCol: INDEX([1]!CCA_SettingsStates[#Data],,FPIG!CCA_SettingsStatesStateColNum)
Name CCA_SettingsStatesEntireCol: INDEX([1]!CCA_SettingsStates[#Data],,Mcaid!CCA_SettingsStatesStateColNum)
Name CCA_SettingsStatesEntireCol: INDEX([1]!CCA_SettingsStates[#Data],,CCA_SettingsStatesStateColNum)
Name CCA_SettingsStatesLookup: INDEX([1]!CCA_SettingsStates[#Data],1,CHIP!CCA_SettingsStatesStateColNum):INDEX([1]!CCA_SettingsStates[#Data],COUNTA(CHIP!CCA_SettingsStatesEntireCol),CHIP!CCA_SettingsStatesStateColNum)
Name CCA_SettingsStatesLookup: INDEX([1]!CCA_SettingsStates[#Data],1,FPIG!CCA_SettingsStatesStateColNum):INDEX([1]!CCA_SettingsStates[#Data],COUNTA(FPIG!CCA_SettingsStatesEntireCol),FPIG!CCA_SettingsStatesStateColNum)
Name CCA_SettingsStatesLookup: INDEX([1]!CCA_SettingsStates[#Data],1,Mcaid!CCA_SettingsStatesStateColNum):INDEX([1]!CCA_SettingsStates[#Data],COUNTA(Mcaid!CCA_SettingsStatesEntireCol),Mcaid!CCA_SettingsStatesStateColNum)
Name CCA_SettingsStatesLookup: INDEX([1]!CCA_SettingsStates[#Data],1,CCA_SettingsStatesStateColNum):INDEX([1]!CCA_SettingsStates[#Data],COUNTA(CCA_SettingsStatesEntireCol),CCA_SettingsStatesStateColNum)
Name CCA_SettingsStatesStateColNum: MATCH(InputStateName,[1]!CCA_SettingsStates[#Headers],0)
Name CCA_SettingsStatesStateColNum: MATCH(InputStateName,[1]!CCA_SettingsStates[#Headers],0)
Name CCA_SettingsStatesStateColNum: MATCH(InputStateName,[1]!CCA_SettingsStates[#Headers],0)
Name CCA_SettingsStatesStateColNum: MATCH(InputStateName,[1]!CCA_SettingsStates[#Headers],0)

Sheet Results (2)
A1: Results For USE with UTAH Demonstration Project PowerPoint
B2: Income Eligibility Rules
C3: Children Medicaid Ages 0-1 | D3: Children Medicaid Ages 1-5 | E3: Children Medicaid Ages 6-18 | F3: Children Separate CHIP | G3: Pregnant Women Medicaid | H3: Pregnant Women CHIP | I3: Adults (Medicaid) Parent/ Caretaker | J3: Adults (Medicaid) Expansion to Adults
B4: Eligiblity (FPIG) | C4: ='Eligibility 2024'!S7 -> 2.21 | D4: ='Eligibility 2024'!T7 -> 1.943 | E4: ='Eligibility 2024'!U7 -> 1.899 | F4: ='Eligibility 2024'!V7 -> 2.847 | G4: ='Eligibility 2024'!W7 -> 2.035 | H4: ='Eligibility 2024'!X7 -> N/A | I4: ='Eligibility 2024'!Y7 -> 0.706 | J4: ='Eligibility 2024'!Z7 -> 1.33
B5: Utah | C5: ='Eligibility 2024'!E55 -> 1.39 | D5: ='Eligibility 2024'!G55 -> 1.39 | E5: ='Eligibility 2024'!H55 -> 1.33 | F5: ='Eligibility 2024'!I55 -> 2 | G5: ='Eligibility 2024'!K55 -> 1.39 | J5: 1.33
C7: Per Member Expenditures (Estimated 2024 Data): Full Benefits
D8: All | E8: Seniors | F8: Individuals with Disabilities | G8: Adults | H8: Children | I8: ACA Expansion Adults
C9: National | D9: ='PMPA-MACPAC'!D11 -> 9866 | E9: ='PMPA-MACPAC'!N10 -> 25334 | F9: ='PMPA-MACPAC'!L10 -> 27962 | G9: ='PMPA-MACPAC'!J10 -> 6674 | H9: ='PMPA-MACPAC'!F10 -> 3752 | I9: ='PMPA-MACPAC'!H10 -> 7845
C10: Utah | D10: ='PMPA-MACPAC'!CG61 -> 9745 | E10: ='PMPA-MACPAC'!CP61 -> 23301 | F10: ='PMPA-MACPAC'!CO61 -> 30864 | G10: ='PMPA-MACPAC'!CM61 -> 8149 | H10: ='PMPA-MACPAC'!CI61 -> 3939 | I10: ='PMPA-MACPAC'!CK61 -> 8971
A12: Use this one | B12: MACPAC Data- Full only
C14: U.S. Average | D14: Utah
B15: Children Medicaid Ages 0-1 | C15: 2.21 | D15: 1.39
B16: Children Medicaid Ages 1-5 | C16: 1.943 | D16: 1.39
B17: Children Medicaid Ages 6-18 | C17: 1.899 | D17: 1.33
B18: Children Separate CHIP | C18: 2.123 | D18: 2
B19: Pregnant Women Medicaid | C19: 2.035 | D19: 1.39
B20: Adults (Medicaid) Parent/ Caretaker | C20: 0.706 | D20: 0.36
B21: Adults (Medicaid) Expansion to Adults | C21: 1.33 | D21: 1.33

Sheet Sources
B3: Last downloaded July 31, 2024
B4: CMS
C5: https://data.medicaid.gov/dataset/6165f45b-ca93-5bb5-9d06-db29c692a360/data?conditions%5B0%5D%5Bproperty%5D=report_date&conditions%5B0%5D%5Bvalue%5D=2021-04-01&conditions%5B0%5D%5Boperator%5D=%3D&conditions%5B1%5D%5Bproperty%5D=preliminary_updated&conditions%5B1%5D%5Bvalue%5D=U&conditions%5B1%5D%5Boperator%5D=%3D
C6: https://data.medicaid.gov/dataset/6165f45b-ca93-5bb5-9d06-db29c692a360/data
C7: Back to State Medicaid and CHIP Applications, Eligibility Determinations, and Enrollment Data
C8: State Medicaid and CHIP Applications, Eligibility Determinations, and Enrollment Data
C10: Medicaid, Children's Health Insurance Program, & Basic Health Program Eligibility Levels
D11: Path: Home > Medicaid Program Information > Medicaid & CHIP Eligibility Levels
D12: https://www.medicaid.gov/medicaid/national-medicaid-chip-program-information/medicaid-childrens-health-insurance-program-basic-health-program-eligibility-levels/index.html
D13: Includes summary table of eligibility
B15: KFF
D16: Medicaid Spending per Enrollee (Full or Partial Benefit) by Enrollment Group
D17: https://www.kff.org/medicaid/state-indicator/medicaid-spending-per-enrollee/
D18: Accessed August 2, 2024
D20: Medicaid and CHIP Eligibility, Enrollment, and Cost Sharing Policies as of January 2020: Findings from a 50-State Survey
D21: https://files.kff.org/attachment/Report-Medicaid-and-CHIP-Eligibility,-Enrollment-and-Cost-Sharing-Policies-as-of-January-2020.pdf
D22: Prepared by: Tricia Brooks and Lauren Roygardner Georgetown University Center for Children and Families and Samantha Artiga, Olivia Pham, and Rachel Dolan KFF
E23: Table 14 : Premiums and Enrollment Fees for Children at Selected Income Levels, January 2020: p64
D24: website: | E24: https://www.kff.org/medicaid/report/medicaid-and-chip-eligibility-enrollment-and-cost-sharing-policies-as-of-january-2019-findings-from-a-50-state-survey/
B29: BLS | C29: Bureau of Labor Statistics
D30: Series Id: | E30: SUUR0000SAM2
D31: Not Seasonally Adjusted
D32: Series Title: | E32: Medical care services in U.S. city average, all urban consumers, chained, not seasonally adjusted
D33: Area: | E33: U.S. city average
D34: Item: | E34: Medical care services
D35: Base Period: | E35: DECEMBER 1999=100
D37: Series Id: | E37: SUUR0000SAM
D38: Not Seasonally Adjusted
D39: Series Title: | E39: Medical care in U.S. city average, all urban consumers, chained, not seasonally adjusted
D40: Area: | E40: U.S. city average
D41: Item: | E41: Medical care
D42: Base Period: | E42: DECEMBER 1999=100
D43: Years: | E43: 2014 to 2024
B45: MACPAC | C45: Medicaid and CHIP Payment and Access Commission
D46: MACStats: Medicaid and CHIP Data Book
D47: 45261
D48: https://www.macpac.gov/publication/macstats-medicaid-and-chip-data-book-2/
E49: The Medicaid and CHIP Payment and Access Commission (MACPAC) is a non-partisan legislative branch agency that provides policy and data analysis and makes recommendations to Congress, the Secretary of the U.S. Department of Health and Human Services, and the states on a wide array of issues affecting Medicaid and the State Children’s Health Insurance Program (CHIP). The U.S. Comptroller General appoints MACPAC’s 17 commissioners, who come from diverse regions across the United States and bring broad expertise and a wide range of perspectives on Medicaid and CHIP.
B51: CMS
C52: Income Counting
...

Sheet Results
A1: Results
B2: Income Eligibility Rules
D3: Children Medicaid Ages 0-1 | E3: Children Medicaid Ages 1-5 | F3: Children Medicaid Ages 6-18 | G3: Children Separate CHIP | H3: Pregnant Women Medicaid | I3: Pregnant Women CHIP | J3: Adults (Medicaid) Parent/ Caretaker | K3: Adults (Medicaid) Expansion to Adults
A4: Use this one | B4: Eligibility (FPIG) | D4: ='Eligibility 2024'!S7 -> 2.21 | E4: ='Eligibility 2024'!T7 -> 1.943 | F4: ='Eligibility 2024'!U7 -> 1.899 | G4: ='Eligibility 2024'!V7 -> 2.847 | H4: ='Eligibility 2024'!W7 -> 2.035 | I4: ='Eligibility 2024'!X7 -> N/A | J4: ='Eligibility 2024'!Y7 -> 0.706 | K4: ='Eligibility 2024'!Z7 -> 1.33
B5: Notes | J5: ='Eligibility 2024'!Y8 -> uses % | K5: yes, expanded
B7: Per Member Expenditures (2023)
D8: All Full or Partial Benefit Enrollees | E8: Seniors | F8: Individuals with Disabilities | G8: Adults | H8: Children | I8: ACA Expansion Adults
B9: KFF Data | C9: FY 2021 converted to CY 2023 | D9: ='PMPA-KFF'!B6 -> 7403 | E9: ='PMPA-KFF'!C6 -> 15344 | F9: ='PMPA-KFF'!D6 -> 17734 | G9: ='PMPA-KFF'!E6 -> 4731 | H9: ='PMPA-KFF'!F6 -> 3143 | I9: ='PMPA-KFF'!G6 -> 6678
B12: MACPAC Data- All | C12: FY 2021 | D12: ='PMPA-MACPAC'!C16 -> 8651 | E12: ='PMPA-MACPAC'!M16 -> 18514 | F12: ='PMPA-MACPAC'!K16 -> 23935 | G12: ='PMPA-MACPAC'!I16 -> 5462 | H12: ='PMPA-MACPAC'!E16 -> 3584 | I12: ='PMPA-MACPAC'!G16 -> 7486
B13: MACPAC Data- Full only | C13: FY 2021 | D13: ='PMPA-MACPAC'!D16 -> 9175 | E13: ='PMPA-MACPAC'!N16 -> 24247 | F13: ='PMPA-MACPAC'!L16 -> 26762 | G13: ='PMPA-MACPAC'!J16 -> 6388 | H13: ='PMPA-MACPAC'!F16 -> 3591 | I13: ='PMPA-MACPAC'!H16 -> 7508
B14: MACPAC Data- All | C14: FY 2021 converted to CY 2023 | D14: ='PMPA-MACPAC'!C10 -> 9039 | E14: ='PMPA-MACPAC'!M10 -> 19344 | F14: ='PMPA-MACPAC'!K10 -> 25008 | G14: ='PMPA-MACPAC'!I10 -> 5707 | H14: ='PMPA-MACPAC'!E10 -> 3745 | I14: ='PMPA-MACPAC'!G10 -> 7822
A15: Use this one | B15: MACPAC Data- Full only | C15: FY 2021 converted to CY 2023 | D15: ='PMPA-MACPAC'!D10 -> 9586 | E15: ='PMPA-MACPAC'!N10 -> 25334 | F15: ='PMPA-MACPAC'!L10 -> 27962 | G15: ='PMPA-MACPAC'!J10 -> 6674 | H15: ='PMPA-MACPAC'!F10 -> 3752 | I15: ='PMPA-MACPAC'!H10 -> 7845
C17: Premium Shares for Children
D18: FPL | E18: Annual Cost Per Child
C19: Group 1 | D19: ='KFF Premium Cost Sharing'!Q3 -> 1.51 | E19: ='KFF Premium Cost Sharing'!Q8 -> 37.51
C20: Group 2 | D20: ='KFF Premium Cost Sharing'!S3 -> 2.01 | E20: ='KFF Premium Cost Sharing'!S8 -> 139.34
C21: Group 3 | D21: ='KFF Premium Cost Sharing'!U3 -> 2.51 | E21: ='KFF Premium Cost Sharing'!U8 -> 332.76
C22: Group 4 | D22: ='KFF Premium Cost Sharing'!W3 -> 3.01 | E22: ='KFF Premium Cost Sharing'!W8 -> 463.34
C23: [Group 5--Not needed*] | D23: ='KFF Premium Cost Sharing'!Y3 -> 3.51 | E23: ='KFF Premium Cost Sharing'!Y8 -> 514.43
C24: *Exceeds maximum eligibility of 285% FPL
C25: Interpretation: maximum FPL for annual cost per child.
C26: Use these annual cost for when child comes off Medicaid until 285% FPL when they become ineligible.
B32: IMAGES
B71: Note:
B72: Don't count EITC or SSI as income

Sheet Weighting
B2: Select Enrollment Type = | C2: Total Medicaid and CHIP Enrollment
B3: Preliminary or Updated = | C3: U | F3: Number missing =
B4: Final Report = | C4: Y | F4: =COUNTIF(F7:F57,0) -> 0 | G4: =COUNTIF(G7:G57,0) -> 0 | H4: =COUNTIF(H7:H57,0) -> 0 | I4: =COUNTIF(I7:I57,0) -> 0 | J4: =COUNTIF(J7:J57,0) -> 0 | K4: =COUNTIF(K7:K57,0) -> 0 | L4: =COUNTIF(L7:L57,0) -> 0 | M4: =COUNTIF(M7:M57,0) -> 0 | ... Q4: =COUNTIF(Q7:Q57,0) -> 0
D5: State Expanded Medicaid
B6: Post Code | C6: State | D6: 44927 | E6: 45261 | F6: 44927 | G6: 44958 | H6: 44986 | I6: 45017 | J6: 45047 | K6: 45078 | L6: 45108 | M6: 45139 | N6: 45170 | O6: 45200 | P6: 45231 | Q6: 45261 | R6: average | U6: Enrollment Type | V6: Preliminary or Updated | W6: Final Report
A7: 1 | B7: AL | C7: Alabama | D7: {=INDEX(MData[],MATCH(1,(MData[State Abbreviation]=$B7)*(MData[Report Date]=D$6)*(MData[Preliminary or Updated]=$C$3)*(MData[Final Report]=$C$4),0),MATCH($D$5,MData[#Headers],0))} -> N | E7: {=INDEX(MData[],MATCH(1,(MData[State Abbreviation]=$B7)*(MData[Report Date]=E$6)*(MData[Preliminary or Updated]=$C$3)*(MData[Final Report]=$C$4),0),MATCH($D$5,MData[#Headers],0))} -> N | F7: {=INDEX(MData[],MATCH(1,(MData[State Abbreviation]=$B7)*(MData[Report Date]=F$6)*(MData[Preliminary or Updated]=$C$3)*(MData[Final Report]=$C$4),0),MATCH($C$2,MData[#Headers],0))} -> 1178842 | G7: {=INDEX(MData[],MATCH(1,(MData[State Abbreviation]=$B7)*(MData[Report Date]=G$6)*(MData[Preliminary or Updated]=$C$3)*(MData[Final Report]=$C$4),0),MATCH($C$2,MData[#Headers],0))} -> 1197673 | H7: {=INDEX(MData[],MATCH(1,(MData[State Abbreviation]=$B7)*(MData[Report Date]=H$6)*(MData[Preliminary or Updated]=$C$3)*(MData[Final Report]=$C$4),0),MATCH($C$2,MData[#Headers],0))} -> 1205375 | I7: {=INDEX(MData[],MATCH(1,(MData[State Abbreviation]=$B7)*(MData[Report Date]=I$6)*(MData[Preliminary or Updated]=$C$3)*(MData[Final Report]=$C$4),0),MATCH($C$2,MData[#Headers],0))} -> 1210198 | J7: {=INDEX(MData[],MATCH(1,(MData[State Abbreviation]=$B7)*(MData[Report Date]=J$6)*(MData[Preliminary or Updated]=$C$3)*(MData[Final Report]=$C$4),0),MATCH($C$2,MData[#Headers],0))} -> 1207604 | K7: {=INDEX(MData[],MATCH(1,(MData[State Abbreviation]=$B7)*(MData[Report Date]=K$6)*(MData[Preliminary or Updated]=$C$3)*(MData[Final Report]=$C$4),0),MATCH($C$2,MData[#Headers],0))} -> 1213189 | L7: {=INDEX(MData[],MATCH(1,(MData[State Abbreviation]=$B7)*(MData[Report Date]=L$6)*(MData[Preliminary or Updated]=$C$3)*(MData[Final Report]=$C$4),0),MATCH($C$2,MData[#Headers],0))} -> 1192748 | M7: {=INDEX(MData[],MATCH(1,(MData[State Abbreviation]=$B7)*(MData[Report Date]=M$6)*(MData[Preliminary or Updated]=$C$3)*(MData[Final Report]=$C$4),0),MATCH($C$2,MData[#Headers],0))} -> 1170429 | ... Q7: {=INDEX(MData[],MATCH(1,(MData[State Abbreviation]=$B7)*(MData[Report Date]=Q$6)*(MData[Preliminary or Updated]=$C$3)*(MData[Final Report]=$C$4),0),MATCH($C$2,MData[#Headers],0))} -> 1093532 | R7: =AVERAGE(F7:Q7) -> 1171764.9 | U7: Total Medicaid and CHIP Enrollment | V7: P | W7: Y
A8: 2 | B8: AK | C8: Alaska | D8: {=INDEX(MData[],MATCH(1,(MData[State Abbreviation]=$B8)*(MData[Report Date]=D$6)*(MData[Preliminary or Updated]=$C$3)*(MData[Final Report]=$C$4),0),MATCH($D$5,MData[#Headers],0))} -> Y | E8: {=INDEX(MData[],MATCH(1,(MData[State Abbreviation]=$B8)*(MData[Report Date]=E$6)*(MData[Preliminary or Updated]=$C$3)*(MData[Final Report]=$C$4),0),MATCH($D$5,MData[#Headers],0))} -> Y | F8: {=INDEX(MData[],MATCH(1,(MData[State Abbreviation]=$B8)*(MData[Report Date]=F$6)*(MData[Preliminary or Updated]=$C$3)*(MData[Final Report]=$C$4),0),MATCH($C$2,MData[#Headers],0))} -> 265528 | G8: {=INDEX(MData[],MATCH(1,(MData[State Abbreviation]=$B8)*(MData[Report Date]=G$6)*(MData[Preliminary or Updated]=$C$3)*(MData[Final Report]=$C$4),0),MATCH($C$2,MData[#Headers],0))} -> 266213 | H8: {=INDEX(MData[],MATCH(1,(MData[State Abbreviation]=$B8)*(MData[Report Date]=H$6)*(MData[Preliminary or Updated]=$C$3)*(MData[Final Report]=$C$4),0),MATCH($C$2,MData[#Headers],0))} -> 267278 | I8: {=INDEX(MData[],MATCH(1,(MData[State Abbreviation]=$B8)*(MData[Report Date]=I$6)*(MData[Preliminary or Updated]=$C$3)*(MData[Final Report]=$C$4),0),MATCH($C$2,MData[#Headers],0))} -> 268069 | J8: {=INDEX(MData[],MATCH(1,(MData[State Abbreviation]=$B8)*(MData[Report Date]=J$6)*(MData[Preliminary or Updated]=$C$3)*(MData[Final Report]=$C$4),0),MATCH($C$2,MData[#Headers],0))} -> 266917 | K8: {=INDEX(MData[],MATCH(1,(MData[State Abbreviation]=$B8)*(MData[Report Date]=K$6)*(MData[Preliminary or Updated]=$C$3)*(MData[Final Report]=$C$4),0),MATCH($C$2,MData[#Headers],0))} -> 265952 | L8: {=INDEX(MData[],MATCH(1,(MData[State Abbreviation]=$B8)*(MData[Report Date]=L$6)*(MData[Preliminary or Updated]=$C$3)*(MData[Final Report]=$C$4),0),MATCH($C$2,MData[#Headers],0))} -> 262806 | M8: {=INDEX(MData[],MATCH(1,(MData[State Abbreviation]=$B8)*(MData[Report Date]=M$6)*(MData[Preliminary or Updated]=$C$3)*(MData[Final Report]=$C$4),0),MATCH($C$2,MData[#Headers],0))} -> 256543 | ... Q8: {=INDEX(MData[],MATCH(1,(MData[State Abbreviation]=$B8)*(MData[Report Date]=Q$6)*(MData[Preliminary or Updated]=$C$3)*(MData[Final Report]=$C$4),0),MATCH($C$2,MData[#Headers],0))} -> 242860 | R8: =AVERAGE(F8:Q8) -> 258266.83 | U8: Medicaid and CHIP Child Enrollment | V8: U | W8: N
A9: 3 | B9: AZ | C9: Arizona | D9: {=INDEX(MData[],MATCH(1,(MData[State Abbreviation]=$B9)*(MData[Report Date]=D$6)*(MData[Preliminary or Updated]=$C$3)*(MData[Final Report]=$C$4),0),MATCH($D$5,MData[#Headers],0))} -> Y | E9: {=INDEX(MData[],MATCH(1,(MData[State Abbreviation]=$B9)*(MData[Report Date]=E$6)*(MData[Preliminary or Updated]=$C$3)*(MData[Final Report]=$C$4),0),MATCH($D$5,MData[#Headers],0))} -> Y | F9: {=INDEX(MData[],MATCH(1,(MData[State Abbreviation]=$B9)*(MData[Report Date]=F$6)*(MData[Preliminary or Updated]=$C$3)*(MData[Final Report]=$C$4),0),MATCH($C$2,MData[#Headers],0))} -> 2309576 | G9: {=INDEX(MData[],MATCH(1,(MData[State Abbreviation]=$B9)*(MData[Report Date]=G$6)*(MData[Preliminary or Updated]=$C$3)*(MData[Final Report]=$C$4),0),MATCH($C$2,MData[#Headers],0))} -> 2319692 | H9: {=INDEX(MData[],MATCH(1,(MData[State Abbreviation]=$B9)*(MData[Report Date]=H$6)*(MData[Preliminary or Updated]=$C$3)*(MData[Final Report]=$C$4),0),MATCH($C$2,MData[#Headers],0))} -> 2332111 | I9: {=INDEX(MData[],MATCH(1,(MData[State Abbreviation]=$B9)*(MData[Report Date]=I$6)*(MData[Preliminary or Updated]=$C$3)*(MData[Final Report]=$C$4),0),MATCH($C$2,MData[#Headers],0))} -> 2303620 | J9: {=INDEX(MData[],MATCH(1,(MData[State Abbreviation]=$B9)*(MData[Report Date]=J$6)*(MData[Preliminary or Updated]=$C$3)*(MData[Final Report]=$C$4),0),MATCH($C$2,MData[#Headers],0))} -> 2283588 | K9: {=INDEX(MData[],MATCH(1,(MData[State Abbreviation]=$B9)*(MData[Report Date]=K$6)*(MData[Preliminary or Updated]=$C$3)*(MData[Final Report]=$C$4),0),MATCH($C$2,MData[#Headers],0))} -> 2181664 | L9: {=INDEX(MData[],MATCH(1,(MData[State Abbreviation]=$B9)*(MData[Report Date]=L$6)*(MData[Preliminary or Updated]=$C$3)*(MData[Final Report]=$C$4),0),MATCH($C$2,MData[#Headers],0))} -> 2134921 | M9: {=INDEX(MData[],MATCH(1,(MData[State Abbreviation]=$B9)*(MData[Report Date]=M$6)*(MData[Preliminary or Updated]=$C$3)*(MData[Final Report]=$C$4),0),MATCH($C$2,MData[#Headers],0))} -> 2108891 | ... Q9: {=INDEX(MData[],MATCH(1,(MData[State Abbreviation]=$B9)*(MData[Report Date]=Q$6)*(MData[Preliminary or Updated]=$C$3)*(MData[Final Report]=$C$4),0),MATCH($C$2,MData[#Headers],0))} -> 2037255 | R9: =AVERAGE(F9:Q9) -> 2176738.6 | U9: Total Medicaid Enrollment
A10: 4 | B10: AR | C10: Arkansas | D10: {=INDEX(MData[],MATCH(1,(MData[State Abbreviation]=$B10)*(MData[Report Date]=D$6)*(MData[Preliminary or Updated]=$C$3)*(MData[Final Report]=$C$4),0),MATCH($D$5,MData[#Headers],0))} -> Y | E10: {=INDEX(MData[],MATCH(1,(MData[State Abbreviation]=$B10)*(MData[Report Date]=E$6)*(MData[Preliminary or Updated]=$C$3)*(MData[Final Report]=$C$4),0),MATCH($D$5,MData[#Headers],0))} -> Y | F10: {=INDEX(MData[],MATCH(1,(MData[State Abbreviation]=$B10)*(MData[Report Date]=F$6)*(MData[Preliminary or Updated]=$C$3)*(MData[Final Report]=$C$4),0),MATCH($C$2,MData[#Headers],0))} -> 1048216 | G10: {=INDEX(MData[],MATCH(1,(MData[State Abbreviation]=$B10)*(MData[Report Date]=G$6)*(MData[Preliminary or Updated]=$C$3)*(MData[Final Report]=$C$4),0),MATCH($C$2,MData[#Headers],0))} -> 1047297 | H10: {=INDEX(MData[],MATCH(1,(MData[State Abbreviation]=$B10)*(MData[Report Date]=H$6)*(MData[Preliminary or Updated]=$C$3)*(MData[Final Report]=$C$4),0),MATCH($C$2,MData[#Headers],0))} -> 1049471 | I10: {=INDEX(MData[],MATCH(1,(MData[State Abbreviation]=$B10)*(MData[Report Date]=I$6)*(MData[Preliminary or Updated]=$C$3)*(MData[Final Report]=$C$4),0),MATCH($C$2,MData[#Headers],0))} -> 1041808 | J10: {=INDEX(MData[],MATCH(1,(MData[State Abbreviation]=$B10)*(MData[Report Date]=J$6)*(MData[Preliminary or Updated]=$C$3)*(MData[Final Report]=$C$4),0),MATCH($C$2,MData[#Headers],0))} -> 991620 | K10: {=INDEX(MData[],MATCH(1,(MData[State Abbreviation]=$B10)*(MData[Report Date]=K$6)*(MData[Preliminary or Updated]=$C$3)*(MData[Final Report]=$C$4),0),MATCH($C$2,MData[#Headers],0))} -> 947122 | L10: {=INDEX(MData[],MATCH(1,(MData[State Abbreviation]=$B10)*(MData[Report Date]=L$6)*(MData[Preliminary or Updated]=$C$3)*(MData[Final Report]=$C$4),0),MATCH($C$2,MData[#Headers],0))} -> 898622 | M10: {=INDEX(MData[],MATCH(1,(MData[State Abbreviation]=$B10)*(MData[Report Date]=M$6)*(MData[Preliminary or Updated]=$C$3)*(MData[Final Report]=$C$4),0),MATCH($C$2,MData[#Headers],0))} -> 851992 | ... Q10: {=INDEX(MData[],MATCH(1,(MData[State Abbreviation]=$B10)*(MData[Report Date]=Q$6)*(MData[Preliminary or Updated]=$C$3)*(MData[Final Report]=$C$4),0),MATCH($C$2,MData[#Headers],0))} -> 783091 | R10: =AVERAGE(F10:Q10) -> 926134 | U10: Total CHIP Enrollment
A11: 5 | B11: CA | C11: California | D11: {=INDEX(MData[],MATCH(1,(MData[State Abbreviation]=$B11)*(MData[Report Date]=D$6)*(MData[Preliminary or Updated]=$C$3)*(MData[Final Report]=$C$4),0),MATCH($D$5,MData[#Headers],0))} -> Y | E11: {=INDEX(MData[],MATCH(1,(MData[State Abbreviation]=$B11)*(MData[Report Date]=E$6)*(MData[Preliminary or Updated]=$C$3)*(MData[Final Report]=$C$4),0),MATCH($D$5,MData[#Headers],0))} -> Y | F11: {=INDEX(MData[],MATCH(1,(MData[State Abbreviation]=$B11)*(MData[Report Date]=F$6)*(MData[Preliminary or Updated]=$C$3)*(MData[Final Report]=$C$4),0),MATCH($C$2,MData[#Headers],0))} -> 14176618 | G11: {=INDEX(MData[],MATCH(1,(MData[State Abbreviation]=$B11)*(MData[Report Date]=G$6)*(MData[Preliminary or Updated]=$C$3)*(MData[Final Report]=$C$4),0),MATCH($C$2,MData[#Headers],0))} -> 14218802 | H11: {=INDEX(MData[],MATCH(1,(MData[State Abbreviation]=$B11)*(MData[Report Date]=H$6)*(MData[Preliminary or Updated]=$C$3)*(MData[Final Report]=$C$4),0),MATCH($C$2,MData[#Headers],0))} -> 14285643 | I11: {=INDEX(MData[],MATCH(1,(MData[State Abbreviation]=$B11)*(MData[Report Date]=I$6)*(MData[Preliminary or Updated]=$C$3)*(MData[Final Report]=$C$4),0),MATCH($C$2,MData[#Headers],0))} -> 14344876 | J11: {=INDEX(MData[],MATCH(1,(MData[State Abbreviation]=$B11)*(MData[Report Date]=J$6)*(MData[Preliminary or Updated]=$C$3)*(MData[Final Report]=$C$4),0),MATCH($C$2,MData[#Headers],0))} -> 14401941 | K11: {=INDEX(MData[],MATCH(1,(MData[State Abbreviation]=$B11)*(MData[Report Date]=K$6)*(MData[Preliminary or Updated]=$C$3)*(MData[Final Report]=$C$4),0),MATCH($C$2,MData[#Headers],0))} -> 14462560 | L11: {=INDEX(MData[],MATCH(1,(MData[State Abbreviation]=$B11)*(MData[Report Date]=L$6)*(MData[Preliminary or Updated]=$C$3)*(MData[Final Report]=$C$4),0),MATCH($C$2,MData[#Headers],0))} -> 14399877 | M11: {=INDEX(MData[],MATCH(1,(MData[State Abbreviation]=$B11)*(MData[Report Date]=M$6)*(MData[Preliminary or Updated]=$C$3)*(MData[Final Report]=$C$4),0),MATCH($C$2,MData[#Headers],0))} -> 14397473 | ... Q11: {=INDEX(MData[],MATCH(1,(MData[State Abbreviation]=$B11)*(MData[Report Date]=Q$6)*(MData[Preliminary or Updated]=$C$3)*(MData[Final Report]=$C$4),0),MATCH($C$2,MData[#Headers],0))} -> 13805628 | R11: =AVERAGE(F11:Q11) -> 14231316
A12: 6 | B12: CO | C12: Colorado | D12: {=INDEX(MData[],MATCH(1,(MData[State Abbreviation]=$B12)*(MData[Report Date]=D$6)*(MData[Preliminary or Updated]=$C$3)*(MData[Final Report]=$C$4),0),MATCH($D$5,MData[#Headers],0))} -> Y | E12: {=INDEX(MData[],MATCH(1,(MData[State Abbreviation]=$B12)*(MData[Report Date]=E$6)*(MData[Preliminary or Updated]=$C$3)*(MData[Final Report]=$C$4),0),MATCH($D$5,MData[#Headers],0))} -> Y | F12: {=INDEX(MData[],MATCH(1,(MData[State Abbreviation]=$B12)*(MData[Report Date]=F$6)*(MData[Preliminary or Updated]=$C$3)*(MData[Final Report]=$C$4),0),MATCH($C$2,MData[#Headers],0))} -> 1712273 | G12: {=INDEX(MData[],MATCH(1,(MData[State Abbreviation]=$B12)*(MData[Report Date]=G$6)*(MData[Preliminary or Updated]=$C$3)*(MData[Final Report]=$C$4),0),MATCH($C$2,MData[#Headers],0))} -> 1722639 | H12: {=INDEX(MData[],MATCH(1,(MData[State Abbreviation]=$B12)*(MData[Report Date]=H$6)*(MData[Preliminary or Updated]=$C$3)*(MData[Final Report]=$C$4),0),MATCH($C$2,MData[#Headers],0))} -> 1705007 | I12: {=INDEX(MData[],MATCH(1,(MData[State Abbreviation]=$B12)*(MData[Report Date]=I$6)*(MData[Preliminary or Updated]=$C$3)*(MData[Final Report]=$C$4),0),MATCH($C$2,MData[#Headers],0))} -> 1713809 | J12: {=INDEX(MData[],MATCH(1,(MData[State Abbreviation]=$B12)*(MData[Report Date]=J$6)*(MData[Preliminary or Updated]=$C$3)*(MData[Final Report]=$C$4),0),MATCH($C$2,MData[#Headers],0))} -> 1722323 | K12: {=INDEX(MData[],MATCH(1,(MData[State Abbreviation]=$B12)*(MData[Report Date]=K$6)*(MData[Preliminary or Updated]=$C$3)*(MData[Final Report]=$C$4),0),MATCH($C$2,MData[#Headers],0))} -> 1689842 | L12: {=INDEX(MData[],MATCH(1,(MData[State Abbreviation]=$B12)*(MData[Report Date]=L$6)*(MData[Preliminary or Updated]=$C$3)*(MData[Final Report]=$C$4),0),MATCH($C$2,MData[#Headers],0))} -> 1649658 | M12: {=INDEX(MData[],MATCH(1,(MData[State Abbreviation]=$B12)*(MData[Report Date]=M$6)*(MData[Preliminary or Updated]=$C$3)*(MData[Final Report]=$C$4),0),MATCH($C$2,MData[#Headers],0))} -> 1608510 | ... Q12: {=INDEX(MData[],MATCH(1,(MData[State Abbreviation]=$B12)*(MData[Report Date]=Q$6)*(MData[Preliminary or Updated]=$C$3)*(MData[Final Report]=$C$4),0),MATCH($C$2,MData[#Headers],0))} -> 1420075 | R12: =AVERAGE(F12:Q12) -> 1626985.6
A13: 7 | B13: CT | C13: Connecticut | D13: {=INDEX(MData[],MATCH(1,(MData[State Abbreviation]=$B13)*(MData[Report Date]=D$6)*(MData[Preliminary or Updated]=$C$3)*(MData[Final Report]=$C$4),0),MATCH($D$5,MData[#Headers],0))} -> Y | E13: {=INDEX(MData[],MATCH(1,(MData[State Abbreviation]=$B13)*(MData[Report Date]=E$6)*(MData[Preliminary or Updated]=$C$3)*(MData[Final Report]=$C$4),0),MATCH($D$5,MData[#Headers],0))} -> Y | F13: {=INDEX(MData[],MATCH(1,(MData[State Abbreviation]=$B13)*(MData[Report Date]=F$6)*(MData[Preliminary or Updated]=$C$3)*(MData[Final Report]=$C$4),0),MATCH($C$2,MData[#Headers],0))} -> 1012131 | G13: {=INDEX(MData[],MATCH(1,(MData[State Abbreviation]=$B13)*(MData[Report Date]=G$6)*(MData[Preliminary or Updated]=$C$3)*(MData[Final Report]=$C$4),0),MATCH($C$2,MData[#Headers],0))} -> 1016060 | H13: {=INDEX(MData[],MATCH(1,(MData[State Abbreviation]=$B13)*(MData[Report Date]=H$6)*(MData[Preliminary or Updated]=$C$3)*(MData[Final Report]=$C$4),0),MATCH($C$2,MData[#Headers],0))} -> 1020137 | I13: {=INDEX(MData[],MATCH(1,(MData[State Abbreviation]=$B13)*(MData[Report Date]=I$6)*(MData[Preliminary or Updated]=$C$3)*(MData[Final Report]=$C$4),0),MATCH($C$2,MData[#Headers],0))} -> 1021298 | J13: {=INDEX(MData[],MATCH(1,(MData[State Abbreviation]=$B13)*(MData[Report Date]=J$6)*(MData[Preliminary or Updated]=$C$3)*(MData[Final Report]=$C$4),0),MATCH($C$2,MData[#Headers],0))} -> 1008465 | K13: {=INDEX(MData[],MATCH(1,(MData[State Abbreviation]=$B13)*(MData[Report Date]=K$6)*(MData[Preliminary or Updated]=$C$3)*(MData[Final Report]=$C$4),0),MATCH($C$2,MData[#Headers],0))} -> 1000711 | L13: {=INDEX(MData[],MATCH(1,(MData[State Abbreviation]=$B13)*(MData[Report Date]=L$6)*(MData[Preliminary or Updated]=$C$3)*(MData[Final Report]=$C$4),0),MATCH($C$2,MData[#Headers],0))} -> 996632 | M13: {=INDEX(MData[],MATCH(1,(MData[State Abbreviation]=$B13)*(MData[Report Date]=M$6)*(MData[Preliminary or Updated]=$C$3)*(MData[Final Report]=$C$4),0),MATCH($C$2,MData[#Headers],0))} -> 976859 | ... Q13: {=INDEX(MData[],MATCH(1,(MData[State Abbreviation]=$B13)*(MData[Report Date]=Q$6)*(MData[Preliminary or Updated]=$C$3)*(MData[Final Report]=$C$4),0),MATCH($C$2,MData[#Headers],0))} -> 980628 | R13: =AVERAGE(F13:Q13) -> 995265.25
A14: 8 | B14: DE | C14: Delaware | D14: {=INDEX(MData[],MATCH(1,(MData[State Abbreviation]=$B14)*(MData[Report Date]=D$6)*(MData[Preliminary or Updated]=$C$3)*(MData[Final Report]=$C$4),0),MATCH($D$5,MData[#Headers],0))} -> Y | E14: {=INDEX(MData[],MATCH(1,(MData[State Abbreviation]=$B14)*(MData[Report Date]=E$6)*(MData[Preliminary or Updated]=$C$3)*(MData[Final Report]=$C$4),0),MATCH($D$5,MData[#Headers],0))} -> Y | F14: {=INDEX(MData[],MATCH(1,(MData[State Abbreviation]=$B14)*(MData[Report Date]=F$6)*(MData[Preliminary or Updated]=$C$3)*(MData[Final Report]=$C$4),0),MATCH($C$2,MData[#Headers],0))} -> 303192 | G14: {=INDEX(MData[],MATCH(1,(MData[State Abbreviation]=$B14)*(MData[Report Date]=G$6)*(MData[Preliminary or Updated]=$C$3)*(MData[Final Report]=$C$4),0),MATCH($C$2,MData[#Headers],0))} -> 305292 | H14: {=INDEX(MData[],MATCH(1,(MData[State Abbreviation]=$B14)*(MData[Report Date]=H$6)*(MData[Preliminary or Updated]=$C$3)*(MData[Final Report]=$C$4),0),MATCH($C$2,MData[#Headers],0))} -> 306822 | I14: {=INDEX(MData[],MATCH(1,(MData[State Abbreviation]=$B14)*(MData[Report Date]=I$6)*(MData[Preliminary or Updated]=$C$3)*(MData[Final Report]=$C$4),0),MATCH($C$2,MData[#Headers],0))} -> 308105 | J14: {=INDEX(MData[],MATCH(1,(MData[State Abbreviation]=$B14)*(MData[Report Date]=J$6)*(MData[Preliminary or Updated]=$C$3)*(MData[Final Report]=$C$4),0),MATCH($C$2,MData[#Headers],0))} -> 309636 | K14: {=INDEX(MData[],MATCH(1,(MData[State Abbreviation]=$B14)*(MData[Report Date]=K$6)*(MData[Preliminary or Updated]=$C$3)*(MData[Final Report]=$C$4),0),MATCH($C$2,MData[#Headers],0))} -> 309753 | L14: {=INDEX(MData[],MATCH(1,(MData[State Abbreviation]=$B14)*(MData[Report Date]=L$6)*(MData[Preliminary or Updated]=$C$3)*(MData[Final Report]=$C$4),0),MATCH($C$2,MData[#Headers],0))} -> 310479 | M14: {=INDEX(MData[],MATCH(1,(MData[State Abbreviation]=$B14)*(MData[Report Date]=M$6)*(MData[Preliminary or Updated]=$C$3)*(MData[Final Report]=$C$4),0),MATCH($C$2,MData[#Headers],0))} -> 303388 | ... Q14: {=INDEX(MData[],MATCH(1,(MData[State Abbreviation]=$B14)*(MData[Report Date]=Q$6)*(MData[Preliminary or Updated]=$C$3)*(MData[Final Report]=$C$4),0),MATCH($C$2,MData[#Headers],0))} -> 289484 | R14: =AVERAGE(F14:Q14) -> 302669.42
A15: 9 | B15: DC | C15: District of Columbia | D15: {=INDEX(MData[],MATCH(1,(MData[State Abbreviation]=$B15)*(MData[Report Date]=D$6)*(MData[Preliminary or Updated]=$C$3)*(MData[Final Report]=$C$4),0),MATCH($D$5,MData[#Headers],0))} -> Y | E15: {=INDEX(MData[],MATCH(1,(MData[State Abbreviation]=$B15)*(MData[Report Date]=E$6)*(MData[Preliminary or Updated]=$C$3)*(MData[Final Report]=$C$4),0),MATCH($D$5,MData[#Headers],0))} -> Y | F15: {=INDEX(MData[],MATCH(1,(MData[State Abbreviation]=$B15)*(MData[Report Date]=F$6)*(MData[Preliminary or Updated]=$C$3)*(MData[Final Report]=$C$4),0),MATCH($C$2,MData[#Headers],0))} -> 293970 | G15: {=INDEX(MData[],MATCH(1,(MData[State Abbreviation]=$B15)*(MData[Report Date]=G$6)*(MData[Preliminary or Updated]=$C$3)*(MData[Final Report]=$C$4),0),MATCH($C$2,MData[#Headers],0))} -> 295152 | H15: {=INDEX(MData[],MATCH(1,(MData[State Abbreviation]=$B15)*(MData[Report Date]=H$6)*(MData[Preliminary or Updated]=$C$3)*(MData[Final Report]=$C$4),0),MATCH($C$2,MData[#Headers],0))} -> 296412 | I15: {=INDEX(MData[],MATCH(1,(MData[State Abbreviation]=$B15)*(MData[Report Date]=I$6)*(MData[Preliminary or Updated]=$C$3)*(MData[Final Report]=$C$4),0),MATCH($C$2,MData[#Headers],0))} -> 297053 | J15: {=INDEX(MData[],MATCH(1,(MData[State Abbreviation]=$B15)*(MData[Report Date]=J$6)*(MData[Preliminary or Updated]=$C$3)*(MData[Final Report]=$C$4),0),MATCH($C$2,MData[#Headers],0))} -> 297395 | K15: {=INDEX(MData[],MATCH(1,(MData[State Abbreviation]=$B15)*(MData[Report Date]=K$6)*(MData[Preliminary or Updated]=$C$3)*(MData[Final Report]=$C$4),0),MATCH($C$2,MData[#Headers],0))} -> 295185 | L15: {=INDEX(MData[],MATCH(1,(MData[State Abbreviation]=$B15)*(MData[Report Date]=L$6)*(MData[Preliminary or Updated]=$C$3)*(MData[Final Report]=$C$4),0),MATCH($C$2,MData[#Headers],0))} -> 292976 | M15: {=INDEX(MData[],MATCH(1,(MData[State Abbreviation]=$B15)*(MData[Report Date]=M$6)*(MData[Preliminary or Updated]=$C$3)*(MData[Final Report]=$C$4),0),MATCH($C$2,MData[#Headers],0))} -> 290845 | ... Q15: {=INDEX(MData[],MATCH(1,(MData[State Abbreviation]=$B15)*(MData[Report Date]=Q$6)*(MData[Preliminary or Updated]=$C$3)*(MData[Final Report]=$C$4),0),MATCH($C$2,MData[#Headers],0))} -> 277511 | R15: =AVERAGE(F15:Q15) -> 290836.67
A16: 10 | B16: FL | C16: Florida | D16: {=INDEX(MData[],MATCH(1,(MData[State Abbreviation]=$B16)*(MData[Report Date]=D$6)*(MData[Preliminary or Updated]=$C$3)*(MData[Final Report]=$C$4),0),MATCH($D$5,MData[#Headers],0))} -> N | E16: {=INDEX(MData[],MATCH(1,(MData[State Abbreviation]=$B16)*(MData[Report Date]=E$6)*(MData[Preliminary or Updated]=$C$3)*(MData[Final Report]=$C$4),0),MATCH($D$5,MData[#Headers],0))} -> N | F16: {=INDEX(MData[],MATCH(1,(MData[State Abbreviation]=$B16)*(MData[Report Date]=F$6)*(MData[Preliminary or Updated]=$C$3)*(MData[Final Report]=$C$4),0),MATCH($C$2,MData[#Headers],0))} -> 4924826 | G16: {=INDEX(MData[],MATCH(1,(MData[State Abbreviation]=$B16)*(MData[Report Date]=G$6)*(MData[Preliminary or Updated]=$C$3)*(MData[Final Report]=$C$4),0),MATCH($C$2,MData[#Headers],0))} -> 4949019 | H16: {=INDEX(MData[],MATCH(1,(MData[State Abbreviation]=$B16)*(MData[Report Date]=H$6)*(MData[Preliminary or Updated]=$C$3)*(MData[Final Report]=$C$4),0),MATCH($C$2,MData[#Headers],0))} -> 4978001 | I16: {=INDEX(MData[],MATCH(1,(MData[State Abbreviation]=$B16)*(MData[Report Date]=I$6)*(MData[Preliminary or Updated]=$C$3)*(MData[Final Report]=$C$4),0),MATCH($C$2,MData[#Headers],0))} -> 5007292 | J16: {=INDEX(MData[],MATCH(1,(MData[State Abbreviation]=$B16)*(MData[Report Date]=J$6)*(MData[Preliminary or Updated]=$C$3)*(MData[Final Report]=$C$4),0),MATCH($C$2,MData[#Headers],0))} -> 4751303 | K16: {=INDEX(MData[],MATCH(1,(MData[State Abbreviation]=$B16)*(MData[Report Date]=K$6)*(MData[Preliminary or Updated]=$C$3)*(MData[Final Report]=$C$4),0),MATCH($C$2,MData[#Headers],0))} -> 4606431 | L16: {=INDEX(MData[],MATCH(1,(MData[State Abbreviation]=$B16)*(MData[Report Date]=L$6)*(MData[Preliminary or Updated]=$C$3)*(MData[Final Report]=$C$4),0),MATCH($C$2,MData[#Headers],0))} -> 4521012 | M16: {=INDEX(MData[],MATCH(1,(MData[State Abbreviation]=$B16)*(MData[Report Date]=M$6)*(MData[Preliminary or Updated]=$C$3)*(MData[Final Report]=$C$4),0),MATCH($C$2,MData[#Headers],0))} -> 4394460 | ... Q16: {=INDEX(MData[],MATCH(1,(MData[State Abbreviation]=$B16)*(MData[Report Date]=Q$6)*(MData[Preliminary or Updated]=$C$3)*(MData[Final Report]=$C$4),0),MATCH($C$2,MData[#Headers],0))} -> 4155117 | R16: =AVERAGE(F16:Q16) -> 4575955.5
A17: 11 | B17: GA | C17: Georgia | D17: {=INDEX(MData[],MATCH(1,(MData[State Abbreviation]=$B17)*(MData[Report Date]=D$6)*(MData[Preliminary or Updated]=$C$3)*(MData[Final Report]=$C$4),0),MATCH($D$5,MData[#Headers],0))} -> N | E17: {=INDEX(MData[],MATCH(1,(MData[State Abbreviation]=$B17)*(MData[Report Date]=E$6)*(MData[Preliminary or Updated]=$C$3)*(MData[Final Report]=$C$4),0),MATCH($D$5,MData[#Headers],0))} -> N | F17: {=INDEX(MData[],MATCH(1,(MData[State Abbreviation]=$B17)*(MData[Report Date]=F$6)*(MData[Preliminary or Updated]=$C$3)*(MData[Final Report]=$C$4),0),MATCH($C$2,MData[#Headers],0))} -> 2491677 | G17: {=INDEX(MData[],MATCH(1,(MData[State Abbreviation]=$B17)*(MData[Report Date]=G$6)*(MData[Preliminary or Updated]=$C$3)*(MData[Final Report]=$C$4),0),MATCH($C$2,MData[#Headers],0))} -> 2502475 | H17: {=INDEX(MData[],MATCH(1,(MData[State Abbreviation]=$B17)*(MData[Report Date]=H$6)*(MData[Preliminary or Updated]=$C$3)*(MData[Final Report]=$C$4),0),MATCH($C$2,MData[#Headers],0))} -> 2511599 | I17: {=INDEX(MData[],MATCH(1,(MData[State Abbreviation]=$B17)*(MData[Report Date]=I$6)*(MData[Preliminary or Updated]=$C$3)*(MData[Final Report]=$C$4),0),MATCH($C$2,MData[#Headers],0))} -> 2542085 | J17: {=INDEX(MData[],MATCH(1,(MData[State Abbreviation]=$B17)*(MData[Report Date]=J$6)*(MData[Preliminary or Updated]=$C$3)*(MData[Final Report]=$C$4),0),MATCH($C$2,MData[#Headers],0))} -> 2552798 | K17: {=INDEX(MData[],MATCH(1,(MData[State Abbreviation]=$B17)*(MData[Report Date]=K$6)*(MData[Preliminary or Updated]=$C$3)*(MData[Final Report]=$C$4),0),MATCH($C$2,MData[#Headers],0))} -> 2548372 | L17: {=INDEX(MData[],MATCH(1,(MData[State Abbreviation]=$B17)*(MData[Report Date]=L$6)*(MData[Preliminary or Updated]=$C$3)*(MData[Final Report]=$C$4),0),MATCH($C$2,MData[#Headers],0))} -> 2539809 | M17: {=INDEX(MData[],MATCH(1,(MData[State Abbreviation]=$B17)*(MData[Report Date]=M$6)*(MData[Preliminary or Updated]=$C$3)*(MData[Final Report]=$C$4),0),MATCH($C$2,MData[#Headers],0))} -> 2408413 | ... Q17: {=INDEX(MData[],MATCH(1,(MData[State Abbreviation]=$B17)*(MData[Report Date]=Q$6)*(MData[Preliminary or Updated]=$C$3)*(MData[Final Report]=$C$4),0),MATCH($C$2,MData[#Headers],0))} -> 2151282 | R17: =AVERAGE(F17:Q17) -> 2428986.7
A18: 12 | B18: HI | C18: Hawaii | D18: {=INDEX(MData[],MATCH(1,(MData[State Abbreviation]=$B18)*(MData[Report Date]=D$6)*(MData[Preliminary or Updated]=$C$3)*(MData[Final Report]=$C$4),0),MATCH($D$5,MData[#Headers],0))} -> Y | E18: {=INDEX(MData[],MATCH(1,(MData[State Abbreviation]=$B18)*(MData[Report Date]=E$6)*(MData[Preliminary or Updated]=$C$3)*(MData[Final Report]=$C$4),0),MATCH($D$5,MData[#Headers],0))} -> Y | F18: {=INDEX(MData[],MATCH(1,(MData[State Abbreviation]=$B18)*(MData[Report Date]=F$6)*(MData[Preliminary or Updated]=$C$3)*(MData[Final Report]=$C$4),0),MATCH($C$2,MData[#Headers],0))} -> 461990 | G18: {=INDEX(MData[],MATCH(1,(MData[State Abbreviation]=$B18)*(MData[Report Date]=G$6)*(MData[Preliminary or Updated]=$C$3)*(MData[Final Report]=$C$4),0),MATCH($C$2,MData[#Headers],0))} -> 463842 | H18: {=INDEX(MData[],MATCH(1,(MData[State Abbreviation]=$B18)*(MData[Report Date]=H$6)*(MData[Preliminary or Updated]=$C$3)*(MData[Final Report]=$C$4),0),MATCH($C$2,MData[#Headers],0))} -> 465474 | I18: {=INDEX(MData[],MATCH(1,(MData[State Abbreviation]=$B18)*(MData[Report Date]=I$6)*(MData[Preliminary or Updated]=$C$3)*(MData[Final Report]=$C$4),0),MATCH($C$2,MData[#Headers],0))} -> 461504 | J18: {=INDEX(MData[],MATCH(1,(MData[State Abbreviation]=$B18)*(MData[Report Date]=J$6)*(MData[Preliminary or Updated]=$C$3)*(MData[Final Report]=$C$4),0),MATCH($C$2,MData[#Headers],0))} -> 461349 | K18: {=INDEX(MData[],MATCH(1,(MData[State Abbreviation]=$B18)*(MData[Report Date]=K$6)*(MData[Preliminary or Updated]=$C$3)*(MData[Final Report]=$C$4),0),MATCH($C$2,MData[#Headers],0))} -> 443621 | L18: {=INDEX(MData[],MATCH(1,(MData[State Abbreviation]=$B18)*(MData[Report Date]=L$6)*(MData[Preliminary or Updated]=$C$3)*(MData[Final Report]=$C$4),0),MATCH($C$2,MData[#Headers],0))} -> 438194 | M18: {=INDEX(MData[],MATCH(1,(MData[State Abbreviation]=$B18)*(MData[Report Date]=M$6)*(MData[Preliminary or Updated]=$C$3)*(MData[Final Report]=$C$4),0),MATCH($C$2,MData[#Headers],0))} -> 437390 | ... Q18: {=INDEX(MData[],MATCH(1,(MData[State Abbreviation]=$B18)*(MData[Report Date]=Q$6)*(MData[Preliminary or Updated]=$C$3)*(MData[Final Report]=$C$4),0),MATCH($C$2,MData[#Headers],0))} -> 469301 | R18: =AVERAGE(F18:Q18) -> 457257.58
A19: 13 | B19: ID | C19: Idaho | D19: {=INDEX(MData[],MATCH(1,(MData[State Abbreviation]=$B19)*(MData[Report Date]=D$6)*(MData[Preliminary or Updated]=$C$3)*(MData[Final Report]=$C$4),0),MATCH($D$5,MData[#Headers],0))} -> Y | E19: {=INDEX(MData[],MATCH(1,(MData[State Abbreviation]=$B19)*(MData[Report Date]=E$6)*(MData[Preliminary or Updated]=$C$3)*(MData[Final Report]=$C$4),0),MATCH($D$5,MData[#Headers],0))} -> Y | F19: {=INDEX(MData[],MATCH(1,(MData[State Abbreviation]=$B19)*(MData[Report Date]=F$6)*(MData[Preliminary or Updated]=$C$3)*(MData[Final Report]=$C$4),0),MATCH($C$2,MData[#Headers],0))} -> 455548 | G19: {=INDEX(MData[],MATCH(1,(MData[State Abbreviation]=$B19)*(MData[Report Date]=G$6)*(MData[Preliminary or Updated]=$C$3)*(MData[Final Report]=$C$4),0),MATCH($C$2,MData[#Headers],0))} -> 457355 | H19: {=INDEX(MData[],MATCH(1,(MData[State Abbreviation]=$B19)*(MData[Report Date]=H$6)*(MData[Preliminary or Updated]=$C$3)*(MData[Final Report]=$C$4),0),MATCH($C$2,MData[#Headers],0))} -> 460085 | I19: {=INDEX(MData[],MATCH(1,(MData[State Abbreviation]=$B19)*(MData[Report Date]=I$6)*(MData[Preliminary or Updated]=$C$3)*(MData[Final Report]=$C$4),0),MATCH($C$2,MData[#Headers],0))} -> 443371 | J19: {=INDEX(MData[],MATCH(1,(MData[State Abbreviation]=$B19)*(MData[Report Date]=J$6)*(MData[Preliminary or Updated]=$C$3)*(MData[Final Report]=$C$4),0),MATCH($C$2,MData[#Headers],0))} -> 432712 | K19: {=INDEX(MData[],MATCH(1,(MData[State Abbreviation]=$B19)*(MData[Report Date]=K$6)*(MData[Preliminary or Updated]=$C$3)*(MData[Final Report]=$C$4),0),MATCH($C$2,MData[#Headers],0))} -> 385133 | L19: {=INDEX(MData[],MATCH(1,(MData[State Abbreviation]=$B19)*(MData[Report Date]=L$6)*(MData[Preliminary or Updated]=$C$3)*(MData[Final Report]=$C$4),0),MATCH($C$2,MData[#Headers],0))} -> 363567 | M19: {=INDEX(MData[],MATCH(1,(MData[State Abbreviation]=$B19)*(MData[Report Date]=M$6)*(MData[Preliminary or Updated]=$C$3)*(MData[Final Report]=$C$4),0),MATCH($C$2,MData[#Headers],0))} -> 344660 | ... Q19: {=INDEX(MData[],MATCH(1,(MData[State Abbreviation]=$B19)*(MData[Report Date]=Q$6)*(MData[Preliminary or Updated]=$C$3)*(MData[Final Report]=$C$4),0),MATCH($C$2,MData[#Headers],0))} -> 338380 | R19: =AVERAGE(F19:Q19) -> 387596.58
A20: 14 | B20: IL | C20: Illinois | D20: {=INDEX(MData[],MATCH(1,(MData[State Abbreviation]=$B20)*(MData[Report Date]=D$6)*(MData[Preliminary or Updated]=$C$3)*(MData[Final Report]=$C$4),0),MATCH($D$5,MData[#Headers],0))} -> Y | E20: {=INDEX(MData[],MATCH(1,(MData[State Abbreviation]=$B20)*(MData[Report Date]=E$6)*(MData[Preliminary or Updated]=$C$3)*(MData[Final Report]=$C$4),0),MATCH($D$5,MData[#Headers],0))} -> Y | F20: {=INDEX(MData[],MATCH(1,(MData[State Abbreviation]=$B20)*(MData[Report Date]=F$6)*(MData[Preliminary or Updated]=$C$3)*(MData[Final Report]=$C$4),0),MATCH($C$2,MData[#Headers],0))} -> 3808385 | G20: {=INDEX(MData[],MATCH(1,(MData[State Abbreviation]=$B20)*(MData[Report Date]=G$6)*(MData[Preliminary or Updated]=$C$3)*(MData[Final Report]=$C$4),0),MATCH($C$2,MData[#Headers],0))} -> 3818769 | H20: {=INDEX(MData[],MATCH(1,(MData[State Abbreviation]=$B20)*(MData[Report Date]=H$6)*(MData[Preliminary or Updated]=$C$3)*(MData[Final Report]=$C$4),0),MATCH($C$2,MData[#Headers],0))} -> 3826461 | I20: {=INDEX(MData[],MATCH(1,(MData[State Abbreviation]=$B20)*(MData[Report Date]=I$6)*(MData[Preliminary or Updated]=$C$3)*(MData[Final Report]=$C$4),0),MATCH($C$2,MData[#Headers],0))} -> 3839112 | J20: {=INDEX(MData[],MATCH(1,(MData[State Abbreviation]=$B20)*(MData[Report Date]=J$6)*(MData[Preliminary or Updated]=$C$3)*(MData[Final Report]=$C$4),0),MATCH($C$2,MData[#Headers],0))} -> 3851907 | K20: {=INDEX(MData[],MATCH(1,(MData[State Abbreviation]=$B20)*(MData[Report Date]=K$6)*(MData[Preliminary or Updated]=$C$3)*(MData[Final Report]=$C$4),0),MATCH($C$2,MData[#Headers],0))} -> 3866234 | L20: {=INDEX(MData[],MATCH(1,(MData[State Abbreviation]=$B20)*(MData[Report Date]=L$6)*(MData[Preliminary or Updated]=$C$3)*(MData[Final Report]=$C$4),0),MATCH($C$2,MData[#Headers],0))} -> 3872945 | M20: {=INDEX(MData[],MATCH(1,(MData[State Abbreviation]=$B20)*(MData[Report Date]=M$6)*(MData[Preliminary or Updated]=$C$3)*(MData[Final Report]=$C$4),0),MATCH($C$2,MData[#Headers],0))} -> 3846699 | ... Q20: {=INDEX(MData[],MATCH(1,(MData[State Abbreviation]=$B20)*(MData[Report Date]=Q$6)*(MData[Preliminary or Updated]=$C$3)*(MData[Final Report]=$C$4),0),MATCH($C$2,MData[#Headers],0))} -> 3664724 | R20: =AVERAGE(F20:Q20) -> 3806069.2
A21: 15 | B21: IN | C21: Indiana | D21: {=INDEX(MData[],MATCH(1,(MData[State Abbreviation]=$B21)*(MData[Report Date]=D$6)*(MData[Preliminary or Updated]=$C$3)*(MData[Final Report]=$C$4),0),MATCH($D$5,MData[#Headers],0))} -> Y | E21: {=INDEX(MData[],MATCH(1,(MData[State Abbreviation]=$B21)*(MData[Report Date]=E$6)*(MData[Preliminary or Updated]=$C$3)*(MData[Final Report]=$C$4),0),MATCH($D$5,MData[#Headers],0))} -> Y | F21: {=INDEX(MData[],MATCH(1,(MData[State Abbreviation]=$B21)*(MData[Report Date]=F$6)*(MData[Preliminary or Updated]=$C$3)*(MData[Final Report]=$C$4),0),MATCH($C$2,MData[#Headers],0))} -> 2025386 | G21: {=INDEX(MData[],MATCH(1,(MData[State Abbreviation]=$B21)*(MData[Report Date]=G$6)*(MData[Preliminary or Updated]=$C$3)*(MData[Final Report]=$C$4),0),MATCH($C$2,MData[#Headers],0))} -> 2038189 | H21: {=INDEX(MData[],MATCH(1,(MData[State Abbreviation]=$B21)*(MData[Report Date]=H$6)*(MData[Preliminary or Updated]=$C$3)*(MData[Final Report]=$C$4),0),MATCH($C$2,MData[#Headers],0))} -> 2048631 | I21: {=INDEX(MData[],MATCH(1,(MData[State Abbreviation]=$B21)*(MData[Report Date]=I$6)*(MData[Preliminary or Updated]=$C$3)*(MData[Final Report]=$C$4),0),MATCH($C$2,MData[#Headers],0))} -> 2059657 | J21: {=INDEX(MData[],MATCH(1,(MData[State Abbreviation]=$B21)*(MData[Report Date]=J$6)*(MData[Preliminary or Updated]=$C$3)*(MData[Final Report]=$C$4),0),MATCH($C$2,MData[#Headers],0))} -> 2056226 | K21: {=INDEX(MData[],MATCH(1,(MData[State Abbreviation]=$B21)*(MData[Report Date]=K$6)*(MData[Preliminary or Updated]=$C$3)*(MData[Final Report]=$C$4),0),MATCH($C$2,MData[#Headers],0))} -> 2012845 | L21: {=INDEX(MData[],MATCH(1,(MData[State Abbreviation]=$B21)*(MData[Report Date]=L$6)*(MData[Preliminary or Updated]=$C$3)*(MData[Final Report]=$C$4),0),MATCH($C$2,MData[#Headers],0))} -> 1978780 | M21: {=INDEX(MData[],MATCH(1,(MData[State Abbreviation]=$B21)*(MData[Report Date]=M$6)*(MData[Preliminary or Updated]=$C$3)*(MData[Final Report]=$C$4),0),MATCH($C$2,MData[#Headers],0))} -> 1950151 | ... Q21: {=INDEX(MData[],MATCH(1,(MData[State Abbreviation]=$B21)*(MData[Report Date]=Q$6)*(MData[Preliminary or Updated]=$C$3)*(MData[Final Report]=$C$4),0),MATCH($C$2,MData[#Headers],0))} -> 1861409 | R21: =AVERAGE(F21:Q21) -> 1978495.8
A22: 16 | B22: IA | C22: Iowa | D22: {=INDEX(MData[],MATCH(1,(MData[State Abbreviation]=$B22)*(MData[Report Date]=D$6)*(MData[Preliminary or Updated]=$C$3)*(MData[Final Report]=$C$4),0),MATCH($D$5,MData[#Headers],0))} -> Y | E22: {=INDEX(MData[],MATCH(1,(MData[State Abbreviation]=$B22)*(MData[Report Date]=E$6)*(MData[Preliminary or Updated]=$C$3)*(MData[Final Report]=$C$4),0),MATCH($D$5,MData[#Headers],0))} -> Y | F22: {=INDEX(MData[],MATCH(1,(MData[State Abbreviation]=$B22)*(MData[Report Date]=F$6)*(MData[Preliminary or Updated]=$C$3)*(MData[Final Report]=$C$4),0),MATCH($C$2,MData[#Headers],0))} -> 855602 | G22: {=INDEX(MData[],MATCH(1,(MData[State Abbreviation]=$B22)*(MData[Report Date]=G$6)*(MData[Preliminary or Updated]=$C$3)*(MData[Final Report]=$C$4),0),MATCH($C$2,MData[#Headers],0))} -> 859437 | H22: {=INDEX(MData[],MATCH(1,(MData[State Abbreviation]=$B22)*(MData[Report Date]=H$6)*(MData[Preliminary or Updated]=$C$3)*(MData[Final Report]=$C$4),0),MATCH($C$2,MData[#Headers],0))} -> 862577 | I22: {=INDEX(MData[],MATCH(1,(MData[State Abbreviation]=$B22)*(MData[Report Date]=I$6)*(MData[Preliminary or Updated]=$C$3)*(MData[Final Report]=$C$4),0),MATCH($C$2,MData[#Headers],0))} -> 866496 | J22: {=INDEX(MData[],MATCH(1,(MData[State Abbreviation]=$B22)*(MData[Report Date]=J$6)*(MData[Preliminary or Updated]=$C$3)*(MData[Final Report]=$C$4),0),MATCH($C$2,MData[#Headers],0))} -> 860981 | K22: {=INDEX(MData[],MATCH(1,(MData[State Abbreviation]=$B22)*(MData[Report Date]=K$6)*(MData[Preliminary or Updated]=$C$3)*(MData[Final Report]=$C$4),0),MATCH($C$2,MData[#Headers],0))} -> 830677 | L22: {=INDEX(MData[],MATCH(1,(MData[State Abbreviation]=$B22)*(MData[Report Date]=L$6)*(MData[Preliminary or Updated]=$C$3)*(MData[Final Report]=$C$4),0),MATCH($C$2,MData[#Headers],0))} -> 802222 | M22: {=INDEX(MData[],MATCH(1,(MData[State Abbreviation]=$B22)*(MData[Report Date]=M$6)*(MData[Preliminary or Updated]=$C$3)*(MData[Final Report]=$C$4),0),MATCH($C$2,MData[#Headers],0))} -> 774745 | ... Q22: {=INDEX(MData[],MATCH(1,(MData[State Abbreviation]=$B22)*(MData[Report Date]=Q$6)*(MData[Preliminary or Updated]=$C$3)*(MData[Final Report]=$C$4),0),MATCH($C$2,MData[#Headers],0))} -> 710281 | R22: =AVERAGE(F22:Q22) -> 802633.92
... A57: 51 | B57: WY | C57: Wyoming | D57: {=INDEX(MData[],MATCH(1,(MData[State Abbreviation]=$B57)*(MData[Report Date]=D$6)*(MData[Preliminary or Updated]=$C$3)*(MData[Final Report]=$C$4),0),MATCH($D$5,MData[#Headers],0))} -> N | E57: {=INDEX(MData[],MATCH(1,(MData[State Abbreviation]=$B57)*(MData[Report Date]=E$6)*(MData[Preliminary or Updated]=$C$3)*(MData[Final Report]=$C$4),0),MATCH($D$5,MData[#Headers],0))} -> N | F57: {=INDEX(MData[],MATCH(1,(MData[State Abbreviation]=$B57)*(MData[Report Date]=F$6)*(MData[Preliminary or Updated]=$C$3)*(MData[Final Report]=$C$4),0),MATCH($C$2,MData[#Headers],0))} -> 83979 | G57: {=INDEX(MData[],MATCH(1,(MData[State Abbreviation]=$B57)*(MData[Report Date]=G$6)*(MData[Preliminary or Updated]=$C$3)*(MData[Final Report]=$C$4),0),MATCH($C$2,MData[#Headers],0))} -> 84746 | H57: {=INDEX(MData[],MATCH(1,(MData[State Abbreviation]=$B57)*(MData[Report Date]=H$6)*(MData[Preliminary or Updated]=$C$3)*(MData[Final Report]=$C$4),0),MATCH($C$2,MData[#Headers],0))} -> 85018 | I57: {=INDEX(MData[],MATCH(1,(MData[State Abbreviation]=$B57)*(MData[Report Date]=I$6)*(MData[Preliminary or Updated]=$C$3)*(MData[Final Report]=$C$4),0),MATCH($C$2,MData[#Headers],0))} -> 85281 | J57: {=INDEX(MData[],MATCH(1,(MData[State Abbreviation]=$B57)*(MData[Report Date]=J$6)*(MData[Preliminary or Updated]=$C$3)*(MData[Final Report]=$C$4),0),MATCH($C$2,MData[#Headers],0))} -> 85193 | K57: {=INDEX(MData[],MATCH(1,(MData[State Abbreviation]=$B57)*(MData[Report Date]=K$6)*(MData[Preliminary or Updated]=$C$3)*(MData[Final Report]=$C$4),0),MATCH($C$2,MData[#Headers],0))} -> 84816 | L57: {=INDEX(MData[],MATCH(1,(MData[State Abbreviation]=$B57)*(MData[Report Date]=L$6)*(MData[Preliminary or Updated]=$C$3)*(MData[Final Report]=$C$4),0),MATCH($C$2,MData[#Headers],0))} -> 85818 | M57: {=INDEX(MData[],MATCH(1,(MData[State Abbreviation]=$B57)*(MData[Report Date]=M$6)*(MData[Preliminary or Updated]=$C$3)*(MData[Final Report]=$C$4),0),MATCH($C$2,MData[#Headers],0))} -> 76785 | ... Q57: {=INDEX(MData[],MATCH(1,(MData[State Abbreviation]=$B57)*(MData[Report Date]=Q$6)*(MData[Preliminary or Updated]=$C$3)*(MData[Final Report]=$C$4),0),MATCH($C$2,MData[#Headers],0))} -> 75000 | R57: =AVERAGE(F57:Q57) -> 81218.917
D58: State Expanded Medicaid
B59: Post Code | C59: State | D59: 44562 | E59: 44896 | F59: 44562 | G59: 44593 | H59: 44621 | I59: 44652 | J59: 44682 | K59: 44713 | L59: 44743 | M59: 44774 | N59: 44805 | O59: 44835 | P59: 44866 | Q59: 44896 | R59: average
A60: 1 | B60: AL | C60: Alabama | D60: {=INDEX(MData[],MATCH(1,(MData[State Abbreviation]=$B60)*(MData[Report Date]=D$6)*(MData[Preliminary or Updated]=$C$3)*(MData[Final Report]=$C$4),0),MATCH($D$5,MData[#Headers],0))} -> N | E60: {=INDEX(MData[],MATCH(1,(MData[State Abbreviation]=$B60)*(MData[Report Date]=E$6)*(MData[Preliminary or Updated]=$C$3)*(MData[Final Report]=$C$4),0),MATCH($D$5,MData[#Headers],0))} -> N | F60: {=INDEX(MData[],MATCH(1,(MData[State Abbreviation]=$B60)*(MData[Report Date]=F$59)*(MData[Preliminary or Updated]=$C$3)*(MData[Final Report]=$C$4),0),MATCH($C$2,MData[#Headers],0))} -> 1099586 | G60: {=INDEX(MData[],MATCH(1,(MData[State Abbreviation]=$B60)*(MData[Report Date]=G$59)*(MData[Preliminary or Updated]=$C$3)*(MData[Final Report]=$C$4),0),MATCH($C$2,MData[#Headers],0))} -> 1105544 | H60: {=INDEX(MData[],MATCH(1,(MData[State Abbreviation]=$B60)*(MData[Report Date]=H$59)*(MData[Preliminary or Updated]=$C$3)*(MData[Final Report]=$C$4),0),MATCH($C$2,MData[#Headers],0))} -> 1111770 | I60: {=INDEX(MData[],MATCH(1,(MData[State Abbreviation]=$B60)*(MData[Report Date]=I$59)*(MData[Preliminary or Updated]=$C$3)*(MData[Final Report]=$C$4),0),MATCH($C$2,MData[#Headers],0))} -> 1117611 | J60: {=INDEX(MData[],MATCH(1,(MData[State Abbreviation]=$B60)*(MData[Report Date]=J$59)*(MData[Preliminary or Updated]=$C$3)*(MData[Final Report]=$C$4),0),MATCH($C$2,MData[#Headers],0))} -> 1124220 | K60: {=INDEX(MData[],MATCH(1,(MData[State Abbreviation]=$B60)*(MData[Report Date]=K$59)*(MData[Preliminary or Updated]=$C$3)*(MData[Final Report]=$C$4),0),MATCH($C$2,MData[#Headers],0))} -> 1131459 | L60: {=INDEX(MData[],MATCH(1,(MData[State Abbreviation]=$B60)*(MData[Report Date]=L$59)*(MData[Preliminary or Updated]=$C$3)*(MData[Final Report]=$C$4),0),MATCH($C$2,MData[#Headers],0))} -> 1138406 | M60: {=INDEX(MData[],MATCH(1,(MData[State Abbreviation]=$B60)*(MData[Report Date]=M$59)*(MData[Preliminary or Updated]=$C$3)*(MData[Final Report]=$C$4),0),MATCH($C$2,MData[#Headers],0))} -> 1145553 | ... Q60: {=INDEX(MData[],MATCH(1,(MData[State Abbreviation]=$B60)*(MData[Report Date]=Q$59)*(MData[Preliminary or Updated]=$C$3)*(MData[Final Report]=$C$4),0),MATCH($C$2,MData[#Headers],0))} -> 1171540 | R60: =AVERAGE(F60:Q60) -> 1135104.8
A61: 2 | B61: AK | C61: Alaska | D61: {=INDEX(MData[],MATCH(1,(MData[State Abbreviation]=$B61)*(MData[Report Date]=D$6)*(MData[Preliminary or Updated]=$C$3)*(MData[Final Report]=$C$4),0),MATCH($D$5,MData[#Headers],0))} -> Y | E61: {=INDEX(MData[],MATCH(1,(MData[State Abbreviation]=$B61)*(MData[Report Date]=E$6)*(MData[Preliminary or Updated]=$C$3)*(MData[Final Report]=$C$4),0),MATCH($D$5,MData[#Headers],0))} -> Y | F61: {=INDEX(MData[],MATCH(1,(MData[State Abbreviation]=$B61)*(MData[Report Date]=F$59)*(MData[Preliminary or Updated]=$C$3)*(MData[Final Report]=$C$4),0),MATCH($C$2,MData[#Headers],0))} -> 257035 | G61: {=INDEX(MData[],MATCH(1,(MData[State Abbreviation]=$B61)*(MData[Report Date]=G$59)*(MData[Preliminary or Updated]=$C$3)*(MData[Final Report]=$C$4),0),MATCH($C$2,MData[#Headers],0))} -> 257691 | H61: {=INDEX(MData[],MATCH(1,(MData[State Abbreviation]=$B61)*(MData[Report Date]=H$59)*(MData[Preliminary or Updated]=$C$3)*(MData[Final Report]=$C$4),0),MATCH($C$2,MData[#Headers],0))} -> 259457 | I61: {=INDEX(MData[],MATCH(1,(MData[State Abbreviation]=$B61)*(MData[Report Date]=I$59)*(MData[Preliminary or Updated]=$C$3)*(MData[Final Report]=$C$4),0),MATCH($C$2,MData[#Headers],0))} -> 259971 | J61: {=INDEX(MData[],MATCH(1,(MData[State Abbreviation]=$B61)*(MData[Report Date]=J$59)*(MData[Preliminary or Updated]=$C$3)*(MData[Final Report]=$C$4),0),MATCH($C$2,MData[#Headers],0))} -> 260768 | K61: {=INDEX(MData[],MATCH(1,(MData[State Abbreviation]=$B61)*(MData[Report Date]=K$59)*(MData[Preliminary or Updated]=$C$3)*(MData[Final Report]=$C$4),0),MATCH($C$2,MData[#Headers],0))} -> 262031 | L61: {=INDEX(MData[],MATCH(1,(MData[State Abbreviation]=$B61)*(MData[Report Date]=L$59)*(MData[Preliminary or Updated]=$C$3)*(MData[Final Report]=$C$4),0),MATCH($C$2,MData[#Headers],0))} -> 261816 | M61: {=INDEX(MData[],MATCH(1,(MData[State Abbreviation]=$B61)*(MData[Report Date]=M$59)*(MData[Preliminary or Updated]=$C$3)*(MData[Final Report]=$C$4),0),MATCH($C$2,MData[#Headers],0))} -> 262417 | ... Q61: {=INDEX(MData[],MATCH(1,(MData[State Abbreviation]=$B61)*(MData[Report Date]=Q$59)*(MData[Preliminary or Updated]=$C$3)*(MData[Final Report]=$C$4),0),MATCH($C$2,MData[#Headers],0))} -> 263656 | R61: =AVERAGE(F61:Q61) -> 261131.75
