Workbook
Name _2016_HIXCOMPAREclean: '2016_HIXCOMPARE'!$B$2:$J$667
Name AgeFactors: AgeFactors!$D$18:$E$25
Name AREA: '2014&2019 Data'!$F$3:$F$2233
Name Carrier: '2014&2019 Data'!$G$3:$G$2233
Name Metal: '2014&2019 Data'!$I$3:$I$2233
Name PERMI2C30: '2014&2019 Data'!$N$3:$N$2233
Name PREMC2CA30: '2014&2019 Data'!$O$3:$O$2233
Name PREMI27: '2014&2019 Data'!$L$3:$L$2233
Name PREMI50: '2014&2019 Data'!$M$3:$M$2233
Name Silverplans: '2015'!$A$3:$J$6486
Name Silverplans: '2016(p)'!$A$3:$J$6486
Name Silverplans: '2014'!$A$3:$J$6486
Name State: '2014&2019 Data'!$E$3:$E$2233
Name Weight: Weight!$D$3:$G$504
Name YEAR: '2014&2019 Data'!$B$3:$B$2233

Sheet ByCounty
C3: Rating Area ID | D3: County Name | E3: Rating Area
C4: (for federal systems)
C5: Rating Area 1 | D5: Baker | E5: 1 | H5: 1 | I5: =COUNTIF(E5:E163,H5) -> 12
C6: Rating Area 1 | D6: Calhoun | E6: 1 | H6: 2 | I6: =COUNTIF(E6:E164,H6) -> 9
C7: Rating Area 1 | D7: Clay | E7: 1 | H7: 3 | I7: =COUNTIF(E7:E165,H7) -> 21
C8: Rating Area 1 | D8: Crisp | E8: 1 | H8: 4 | I8: =COUNTIF(E8:E166,H8) -> 3
C9: Rating Area 1 | D9: Dougherty | E9: 1 | H9: 5 | I9: =COUNTIF(E9:E167,H9) -> 12
C10: Rating Area 1 | D10: Lee | E10: 1 | H10: 6 | I10: =COUNTIF(E10:E168,H10) -> 9
C11: Rating Area 1 | D11: Mitchell | E11: 1 | H11: 7 | I11: =COUNTIF(E11:E169,H11) -> 3
C12: Rating Area 1 | D12: Randolph | E12: 1 | H12: 8 | I12: =COUNTIF(E12:E170,H12) -> 13
C13: Rating Area 1 | D13: Schley | E13: 1 | H13: 9 | I13: =COUNTIF(E13:E171,H13) -> 3
C14: Rating Area 1 | D14: Sumter | E14: 1 | H14: 10 | I14: =COUNTIF(E14:E172,H14) -> 12
C15: Rating Area 1 | D15: Terrell | E15: 1 | H15: 11 | I15: =COUNTIF(E15:E173,H15) -> 10
C16: Rating Area 1 | D16: Worth | E16: 1 | H16: 12 | I16: =COUNTIF(E16:E174,H16) -> 13
... C20: Rating Area 2 | D20: Greene | E20: 2 | H20: 16 | I20: =COUNTIF(E20:E178,H20) -> 4
C21: Rating Area 2 | D21: Jackson | E21: 2
C22: Rating Area 2 | D22: Madison | E22: 2
C23: Rating Area 2 | D23: Morgan | E23: 2
C24: Rating Area 2 | D24: Oconee | E24: 2
C25: Rating Area 2 | D25: Oglethorpe | E25: 2
C26: Rating Area 3 | D26: Bartow | E26: 3
C27: Rating Area 3 | D27: Butts | E27: 3
C28: Rating Area 3 | D28: Cherokee | E28: 3
C29: Rating Area 3 | D29: Clayton | E29: 3
C30: Rating Area 3 | D30: Cobb | E30: 3
C31: Rating Area 3 | D31: Coweta | E31: 3
C32: Rating Area 3 | D32: DeKalb | E32: 3
... C163: Rating Area 16 | D163: Wilkinson | E163: 16
C165: Source:

Sheet ByArea
E2: 2014 | F2: 2015 | G2: 2016 (p)
C3: Rating Area 1 | D3: 1 | E3: ='2014'!V3 -> 376.5458 | F3: ='2015'!V3 -> 291.82252 | G3: ='2016(p)'!V3 -> 320.2958
C4: Rating Area 2 | D4: 2 | E4: ='2014'!V4 -> 189.92366 | F4: ='2015'!V4 -> 182.29008 | G4: ='2016(p)'!V4 -> 206.55534
C5: Rating Area 3 | D5: 3 | E5: ='2014'!V5 -> 195.97328 | F5: ='2015'!V5 -> 199.8187 | G5: ='2016(p)'!V5 -> 198.90267
C6: Rating Area 4 | D6: 4 | E6: ='2014'!V6 -> 231.87023 | F6: ='2015'!V6 -> 249.45611 | G6: ='2016(p)'!V6 -> 251.4313
C7: Rating Area 5 | D7: 5 | E7: ='2014'!V7 -> 251.29771 | F7: ='2015'!V7 -> 199.16985 | G7: ='2016(p)'!V7 -> 224.3416
C8: Rating Area 6 | D8: 6 | E8: ='2014'!V8 -> 318.40649 | F8: ='2015'!V8 -> 238.1584 | G8: ='2016(p)'!V8 -> 274.19847
C9: Rating Area 7 | D9: 7 | E9: ='2014'!V9 -> 273.6355 | F9: ='2015'!V9 -> 221.47901 | G9: ='2016(p)'!V9 -> 254.35115
C10: Rating Area 8 | D10: 8 | E10: ='2014'!V10 -> 199.55153 | F10: ='2015'!V10 -> 203.81679 | G10: ='2016(p)'!V10 -> 226.50763
C11: Rating Area 9 | D11: 9 | E11: ='2014'!V11 -> 262.58588 | F11: ='2015'!V11 -> 218.08206 | G11: ='2016(p)'!V11 -> 258.59733
C12: Rating Area 10 | D12: 10 | E12: ='2014'!V12 -> 191.65076 | F12: ='2015'!V12 -> 207.75763 | G12: ='2016(p)'!V12 -> 245.33397
C13: Rating Area 11 | D13: 11 | E13: ='2014'!V13 -> 297.51908 | F13: ='2015'!V13 -> 233.23473 | G13: ='2016(p)'!V13 -> 278.29198
C14: Rating Area 12 | D14: 12 | E14: ='2014'!V14 -> 246.46947 | F14: ='2015'!V14 -> 219.1126 | G14: ='2016(p)'!V14 -> 255.6584
... C18: Rating Area 16 | D18: 16 | E18: ='2014'!V18 -> 248.6355 | F18: ='2015'!V18 -> 210.66794 | G18: ='2016(p)'!V18 -> 259.42748
C19: Median | E19: ='2014'!V19 -> 249.9666 | F19: ='2015'!V19 -> 218.59733 | G19: ='2016(p)'!V19 -> 252.89122
C20: Mean | E20: ='2014'!V20 -> 256.62572 | F20: ='2015'!V20 -> 222.00322 | G20: ='2016(p)'!V20 -> 250.88502
C21: Weighted average | E21: ='2014'!V21 -> 217.99644 | F21: ='2015'!V21 -> 205.87129 | G21: ='2016(p)'!V21 -> 215.12593
C23: Weighted based on 2015 QHP plan selections

Sheet 2014
C1: Original Data | M1: Calculations
C2: State | D2: Issuer Name | E2: Plan ID - Standard Component | F2: Plan Marketing Name | G2: Plan Type | H2: Rating Area | I2: Rating Area | J2: Premium Adult Individual Age 27 | M2: Code | N2: State | P2: Rating Area # | Q2: Number of Silver Plans | R2: Find Rowin Table | S2: Second Lowest Silver Plan | T2: Alternative Lookup | U2: Age Factor | V2: Age 21 Premium | W2: Weight | X2: Weight with no NA | Y2: Age21 x Weight | AA2: See below "Calculations" to check below formulae
A3: 1 | B3: =CONCATENATE(C3,I3) -> GA1 | C3: GA | D3: Anthem Blue Cross and Blue Shield | E3: 49046GA0410007 | F3: BCBSHP Silver DirectAccess w/HSA - cbbg | G3: HMO | H3: Rating Area 1 | I3: 1 | J3: 377.92 | M3: =CONCATENATE(N3,P3) -> GA1 | N3: GA | O3: Rating Area 1 | P3: 1 | Q3: =COUNTIF(B$3:B$343,M3) -> 5 | R3: =MATCH(M3,B$3:B$343,0) -> 1 | S3: =INDEX(J$3:J$343,R3+1) -> 394.62 | T3: =VLOOKUP(R3+1,Silverplans,10,FALSE) -> 394.62 | U3: =_xlfn.IFNA(VLOOKUP(N3,AgeFactors,2,FALSE),AgeFactors!$E$25) -> 1.048 | V3: =T3/U3 -> 376.5458 | W3: =VLOOKUP(M3,Weight,4,FALSE) -> 9027 | X3: =_xlfn.IFNA(W3,0) -> 9027 | Y3: =_xlfn.IFNA(W3*V3,0) -> 3399079 | AA3: weighted average | AB3: =V21 -> 217.99644
A4: 2 | B4: =CONCATENATE(C4,I4) -> GA1 | C4: GA | D4: Anthem Blue Cross and Blue Shield | E4: 49046GA0410010 | F4: BCBSHP Silver DirectAccess - cbds | G4: HMO | H4: Rating Area 1 | I4: 1 | J4: 394.62 | M4: =CONCATENATE(N4,P4) -> GA2 | N4: GA | O4: Rating Area 2 | P4: 2 | Q4: =COUNTIF(B$3:B$343,M4) -> 23 | R4: =MATCH(M4,B$3:B$343,0) -> 6 | S4: =INDEX(J$3:J$343,R4+1) -> 199.04 | T4: =VLOOKUP(R4+1,Silverplans,10,FALSE) -> 199.04 | U4: =_xlfn.IFNA(VLOOKUP(N4,AgeFactors,2,FALSE),AgeFactors!$E$25) -> 1.048 | V4: =T4/U4 -> 189.92366 | W4: =VLOOKUP(M4,Weight,4,FALSE) -> 14591 | X4: =_xlfn.IFNA(W4,0) -> 14591 | Y4: =_xlfn.IFNA(W4*V4,0) -> 2771176.2 | AA4: Median | AB4: =V19 -> 249.9666
A5: 3 | B5: =CONCATENATE(C5,I5) -> GA1 | C5: GA | D5: Anthem Blue Cross and Blue Shield | E5: 49046GA0410009 | F5: BCBSHP Silver DirectAccess - cbiq | G5: HMO | H5: Rating Area 1 | I5: 1 | J5: 405.62 | M5: =CONCATENATE(N5,P5) -> GA3 | N5: GA | O5: Rating Area 3 | P5: 3 | Q5: =COUNTIF(B$3:B$343,M5) -> 24 | R5: =MATCH(M5,B$3:B$343,0) -> 29 | S5: =INDEX(J$3:J$343,R5+1) -> 205.38 | T5: =VLOOKUP(R5+1,Silverplans,10,FALSE) -> 205.38 | U5: =_xlfn.IFNA(VLOOKUP(N5,AgeFactors,2,FALSE),AgeFactors!$E$25) -> 1.048 | V5: =T5/U5 -> 195.97328 | W5: =VLOOKUP(M5,Weight,4,FALSE) -> 341300 | X5: =_xlfn.IFNA(W5,0) -> 341300 | Y5: =_xlfn.IFNA(W5*V5,0) -> 66885681 | AA5: simple average | AB5: =V20 -> 256.62572
A6: 4 | B6: =CONCATENATE(C6,I6) -> GA1 | C6: GA | D6: Anthem Blue Cross and Blue Shield | E6: 49046GA0610001 | F6: Blue Cross and Blue Shield Healthcare Plan of Georgia Silver DirectAccess, a Multi-State Plan | G6: HMO | H6: Rating Area 1 | I6: 1 | J6: 405.62 | M6: =CONCATENATE(N6,P6) -> GA4 | N6: GA | O6: Rating Area 4 | P6: 4 | Q6: =COUNTIF(B$3:B$343,M6) -> 11 | R6: =MATCH(M6,B$3:B$343,0) -> 53 | S6: =INDEX(J$3:J$343,R6+1) -> 243 | T6: =VLOOKUP(R6+1,Silverplans,10,FALSE) -> 243 | U6: =_xlfn.IFNA(VLOOKUP(N6,AgeFactors,2,FALSE),AgeFactors!$E$25) -> 1.048 | V6: =T6/U6 -> 231.87023 | W6: =VLOOKUP(M6,Weight,4,FALSE) -> 7945 | X6: =_xlfn.IFNA(W6,0) -> 7945 | Y6: =_xlfn.IFNA(W6*V6,0) -> 1842209
A7: 5 | B7: =CONCATENATE(C7,I7) -> GA1 | C7: GA | D7: Anthem Blue Cross and Blue Shield | E7: 49046GA0410008 | F7: BCBSHP Silver DirectAccess - cbaa | G7: HMO | H7: Rating Area 1 | I7: 1 | J7: 410.15 | M7: =CONCATENATE(N7,P7) -> GA5 | N7: GA | O7: Rating Area 5 | P7: 5 | Q7: =COUNTIF(B$3:B$343,M7) -> 6 | R7: =MATCH(M7,B$3:B$343,0) -> 64 | S7: =INDEX(J$3:J$343,R7+1) -> 263.36 | T7: =VLOOKUP(R7+1,Silverplans,10,FALSE) -> 263.36 | U7: =_xlfn.IFNA(VLOOKUP(N7,AgeFactors,2,FALSE),AgeFactors!$E$25) -> 1.048 | V7: =T7/U7 -> 251.29771 | W7: =VLOOKUP(M7,Weight,4,FALSE) -> 22577 | X7: =_xlfn.IFNA(W7,0) -> 22577 | Y7: =_xlfn.IFNA(W7*V7,0) -> 5673548.4
A8: 6 | B8: =CONCATENATE(C8,I8) -> GA2 | C8: GA | D8: Ambetter from Peach State Health Plan | E8: 45495GA0010009 | F8: Ambetter Silver 5 | G8: HMO | H8: Rating Area 2 | I8: 2 | J8: 196.57 | M8: =CONCATENATE(N8,P8) -> GA6 | N8: GA | O8: Rating Area 6 | P8: 6 | Q8: =COUNTIF(B$3:B$343,M8) -> 6 | R8: =MATCH(M8,B$3:B$343,0) -> 70 | S8: =INDEX(J$3:J$343,R8+1) -> 333.69 | T8: =VLOOKUP(R8+1,Silverplans,10,FALSE) -> 333.69 | U8: =_xlfn.IFNA(VLOOKUP(N8,AgeFactors,2,FALSE),AgeFactors!$E$25) -> 1.048 | V8: =T8/U8 -> 318.40649 | W8: =VLOOKUP(M8,Weight,4,FALSE) -> 12955 | X8: =_xlfn.IFNA(W8,0) -> 12955 | Y8: =_xlfn.IFNA(W8*V8,0) -> 4124956.1
A9: 7 | B9: =CONCATENATE(C9,I9) -> GA2 | C9: GA | D9: Ambetter from Peach State Health Plan | E9: 45495GA0010007 | F9: Ambetter Silver 3 | G9: HMO | H9: Rating Area 2 | I9: 2 | J9: 199.04 | M9: =CONCATENATE(N9,P9) -> GA7 | N9: GA | O9: Rating Area 7 | P9: 7 | Q9: =COUNTIF(B$3:B$343,M9) -> 7 | R9: =MATCH(M9,B$3:B$343,0) -> 76 | S9: =INDEX(J$3:J$343,R9+1) -> 286.77 | T9: =VLOOKUP(R9+1,Silverplans,10,FALSE) -> 286.77 | U9: =_xlfn.IFNA(VLOOKUP(N9,AgeFactors,2,FALSE),AgeFactors!$E$25) -> 1.048 | V9: =T9/U9 -> 273.6355 | W9: =VLOOKUP(M9,Weight,4,FALSE) -> 5220 | X9: =_xlfn.IFNA(W9,0) -> 5220 | Y9: =_xlfn.IFNA(W9*V9,0) -> 1428377.3
A10: 8 | B10: =CONCATENATE(C10,I10) -> GA2 | C10: GA | D10: Ambetter from Peach State Health Plan | E10: 45495GA0020009 | F10: Ambetter Silver 5 + Vision | G10: HMO | H10: Rating Area 2 | I10: 2 | J10: 200.25 | M10: =CONCATENATE(N10,P10) -> GA8 | N10: GA | O10: Rating Area 8 | P10: 8 | Q10: =COUNTIF(B$3:B$343,M10) -> 22 | R10: =MATCH(M10,B$3:B$343,0) -> 83 | S10: =INDEX(J$3:J$343,R10+1) -> 209.13 | T10: =VLOOKUP(R10+1,Silverplans,10,FALSE) -> 209.13 | U10: =_xlfn.IFNA(VLOOKUP(N10,AgeFactors,2,FALSE),AgeFactors!$E$25) -> 1.048 | V10: =T10/U10 -> 199.55153 | W10: =VLOOKUP(M10,Weight,4,FALSE) -> 13483 | X10: =_xlfn.IFNA(W10,0) -> 13483 | Y10: =_xlfn.IFNA(W10*V10,0) -> 2690553.2
A11: 9 | B11: =CONCATENATE(C11,I11) -> GA2 | C11: GA | D11: Ambetter from Peach State Health Plan | E11: 45495GA0020007 | F11: Ambetter Silver 3 + Vision | G11: HMO | H11: Rating Area 2 | I11: 2 | J11: 202.77 | M11: =CONCATENATE(N11,P11) -> GA9 | N11: GA | O11: Rating Area 9 | P11: 9 | Q11: =COUNTIF(B$3:B$343,M11) -> 7 | R11: =MATCH(M11,B$3:B$343,0) -> 105 | S11: =INDEX(J$3:J$343,R11+1) -> 275.19 | T11: =VLOOKUP(R11+1,Silverplans,10,FALSE) -> 275.19 | U11: =_xlfn.IFNA(VLOOKUP(N11,AgeFactors,2,FALSE),AgeFactors!$E$25) -> 1.048 | V11: =T11/U11 -> 262.58588 | W11: =VLOOKUP(M11,Weight,4,FALSE) -> 5564 | X11: =_xlfn.IFNA(W11,0) -> 5564 | Y11: =_xlfn.IFNA(W11*V11,0) -> 1461027.8
A12: 10 | B12: =CONCATENATE(C12,I12) -> GA2 | C12: GA | D12: Ambetter from Peach State Health Plan | E12: 45495GA0010008 | F12: Ambetter Silver 4 | G12: HMO | H12: Rating Area 2 | I12: 2 | J12: 206.25 | M12: =CONCATENATE(N12,P12) -> GA10 | N12: GA | O12: Rating Area 10 | P12: 10 | Q12: =COUNTIF(B$3:B$343,M12) -> 12 | R12: =MATCH(M12,B$3:B$343,0) -> 112 | S12: =INDEX(J$3:J$343,R12+1) -> 200.85 | T12: =VLOOKUP(R12+1,Silverplans,10,FALSE) -> 200.85 | U12: =_xlfn.IFNA(VLOOKUP(N12,AgeFactors,2,FALSE),AgeFactors!$E$25) -> 1.048 | V12: =T12/U12 -> 191.65076 | W12: =VLOOKUP(M12,Weight,4,FALSE) -> 20614 | X12: =_xlfn.IFNA(W12,0) -> 20614 | Y12: =_xlfn.IFNA(W12*V12,0) -> 3950688.8
A13: 11 | B13: =CONCATENATE(C13,I13) -> GA2 | C13: GA | D13: Ambetter from Peach State Health Plan | E13: 45495GA0030009 | F13: Ambetter Silver 5 + Vision + Adult Dental | G13: HMO | H13: Rating Area 2 | I13: 2 | J13: 207.26 | M13: =CONCATENATE(N13,P13) -> GA11 | N13: GA | O13: Rating Area 11 | P13: 11 | Q13: =COUNTIF(B$3:B$343,M13) -> 6 | R13: =MATCH(M13,B$3:B$343,0) -> 124 | S13: =INDEX(J$3:J$343,R13+1) -> 311.8 | T13: =VLOOKUP(R13+1,Silverplans,10,FALSE) -> 311.8 | U13: =_xlfn.IFNA(VLOOKUP(N13,AgeFactors,2,FALSE),AgeFactors!$E$25) -> 1.048 | V13: =T13/U13 -> 297.51908 | W13: =VLOOKUP(M13,Weight,4,FALSE) -> 6195 | X13: =_xlfn.IFNA(W13,0) -> 6195 | Y13: =_xlfn.IFNA(W13*V13,0) -> 1843130.7
A14: 12 | B14: =CONCATENATE(C14,I14) -> GA2 | C14: GA | D14: Ambetter from Peach State Health Plan | E14: 45495GA0010005 | F14: Ambetter Silver 1 | G14: HMO | H14: Rating Area 2 | I14: 2 | J14: 209.13 | M14: =CONCATENATE(N14,P14) -> GA12 | N14: GA | O14: Rating Area 12 | P14: 12 | Q14: =COUNTIF(B$3:B$343,M14) -> 6 | R14: =MATCH(M14,B$3:B$343,0) -> 130 | S14: =INDEX(J$3:J$343,R14+1) -> 258.3 | T14: =VLOOKUP(R14+1,Silverplans,10,FALSE) -> 258.3 | U14: =_xlfn.IFNA(VLOOKUP(N14,AgeFactors,2,FALSE),AgeFactors!$E$25) -> 1.048 | V14: =T14/U14 -> 246.46947 | W14: =VLOOKUP(M14,Weight,4,FALSE) -> 18563 | X14: =_xlfn.IFNA(W14,0) -> 18563 | Y14: =_xlfn.IFNA(W14*V14,0) -> 4575212.7
A15: 13 | B15: =CONCATENATE(C15,I15) -> GA2 | C15: GA | D15: Ambetter from Peach State Health Plan | E15: 45495GA0030007 | F15: Ambetter Silver 3 + Vision + Adult Dental | G15: HMO | H15: Rating Area 2 | I15: 2 | J15: 209.86 | M15: =CONCATENATE(N15,P15) -> GA13 | N15: GA | O15: Rating Area 13 | P15: 13 | Q15: =COUNTIF(B$3:B$343,M15) -> 12 | R15: =MATCH(M15,B$3:B$343,0) -> 136 | S15: =INDEX(J$3:J$343,R15+1) -> 219.17 | T15: =VLOOKUP(R15+1,Silverplans,10,FALSE) -> 219.17 | U15: =_xlfn.IFNA(VLOOKUP(N15,AgeFactors,2,FALSE),AgeFactors!$E$25) -> 1.048 | V15: =T15/U15 -> 209.13168 | W15: =VLOOKUP(M15,Weight,4,FALSE) -> 11235 | X15: =_xlfn.IFNA(W15,0) -> 11235 | Y15: =_xlfn.IFNA(W15*V15,0) -> 2349594.4
A16: 14 | B16: =CONCATENATE(C16,I16) -> GA2 | C16: GA | D16: Ambetter from Peach State Health Plan | E16: 45495GA0020008 | F16: Ambetter Silver 4 + Vision | G16: HMO | H16: Rating Area 2 | I16: 2 | J16: 210.11 | M16: =CONCATENATE(N16,P16) -> GA14 | N16: GA | O16: Rating Area 14 | P16: 14 | Q16: =COUNTIF(B$3:B$343,M16) -> 6 | R16: =MATCH(M16,B$3:B$343,0) -> 148 | S16: =INDEX(J$3:J$343,R16+1) -> 280.52 | T16: =VLOOKUP(R16+1,Silverplans,10,FALSE) -> 280.52 | U16: =_xlfn.IFNA(VLOOKUP(N16,AgeFactors,2,FALSE),AgeFactors!$E$25) -> 1.048 | V16: =T16/U16 -> 267.67176 | W16: =VLOOKUP(M16,Weight,4,FALSE) -> 33895 | X16: =_xlfn.IFNA(W16,0) -> 33895 | Y16: =_xlfn.IFNA(W16*V16,0) -> 9072734.2
A17: 15 | B17: =CONCATENATE(C17,I17) -> GA2 | C17: GA | D17: Ambetter from Peach State Health Plan | E17: 45495GA0020005 | F17: Ambetter Silver 1 + Vision | G17: HMO | H17: Rating Area 2 | I17: 2 | J17: 213.04 | M17: =CONCATENATE(N17,P17) -> GA15 | N17: GA | O17: Rating Area 15 | P17: 15 | Q17: =COUNTIF(B$3:B$343,M17) -> 5 | R17: =MATCH(M17,B$3:B$343,0) -> 154 | S17: =INDEX(J$3:J$343,R17+1) -> 361.71 | T17: =VLOOKUP(R17+1,Silverplans,10,FALSE) -> 361.71 | U17: =_xlfn.IFNA(VLOOKUP(N17,AgeFactors,2,FALSE),AgeFactors!$E$25) -> 1.048 | V17: =T17/U17 -> 345.14313 | W17: =VLOOKUP(M17,Weight,4,FALSE) -> 14843 | X17: =_xlfn.IFNA(W17,0) -> 14843 | Y17: =_xlfn.IFNA(W17*V17,0) -> 5122959.5
A18: 16 | B18: =CONCATENATE(C18,I18) -> GA2 | C18: GA | D18: Ambetter from Peach State Health Plan | E18: 45495GA0030008 | F18: Ambetter Silver 4 + Vision + Adult Dental | G18: HMO | H18: Rating Area 2 | I18: 2 | J18: 217.46 | M18: =CONCATENATE(N18,P18) -> GA16 | N18: GA | O18: Rating Area 16 | P18: 16 | Q18: =COUNTIF(B$3:B$343,M18) -> 6 | R18: =MATCH(M18,B$3:B$343,0) -> 159 | S18: =INDEX(J$3:J$343,R18+1) -> 260.57 | T18: =VLOOKUP(R18+1,Silverplans,10,FALSE) -> 260.57 | U18: =_xlfn.IFNA(VLOOKUP(N18,AgeFactors,2,FALSE),AgeFactors!$E$25) -> 1.048 | V18: =T18/U18 -> 248.6355 | W18: =VLOOKUP(M18,Weight,4,FALSE) -> 3025 | X18: =_xlfn.IFNA(W18,0) -> 3025 | Y18: =_xlfn.IFNA(W18*V18,0) -> 752122.38
A19: 17 | B19: =CONCATENATE(C19,I19) -> GA2 | C19: GA | D19: Ambetter from Peach State Health Plan | E19: 45495GA0030005 | F19: Ambetter Silver 1 + Vision + Adult Dental | G19: HMO | H19: Rating Area 2 | I19: 2 | J19: 220.5 | U19: median | V19: =MEDIAN(V3:V18) -> 249.9666
A20: 18 | B20: =CONCATENATE(C20,I20) -> GA2 | C20: GA | D20: Humana Employers Health Plan of Georgia, Inc. | E20: 93332GA0720004 | F20: Humana National Preferred Silver 4250/6250 Plan | G20: POS | H20: Rating Area 2 | I20: 2 | J20: 227.95 | U20: mean | V20: =AVERAGE(V3:V18) -> 256.62572 | X20: =SUM(X3:X18) -> 541032 | Y20: =SUM(Y3:Y18) -> 1.1794305e+08
A21: 19 | B21: =CONCATENATE(C21,I21) -> GA2 | C21: GA | D21: Kaiser Foundation Health Plan of Georgia | E21: 89942GA0050006 | F21: KP GA Silver 1750/25%/HSA | G21: HMO | H21: Rating Area 2 | I21: 2 | J21: 243 | U21: weight average | V21: =Y20/X20 -> 217.99644
A22: 20 | B22: =CONCATENATE(C22,I22) -> GA2 | C22: GA | D22: Anthem Blue Cross and Blue Shield | E22: 49046GA0410007 | F22: BCBSHP Silver DirectAccess w/HSA - cbbg | G22: HMO | H22: Rating Area 2 | I22: 2 | J22: 254.56 | U22: min | V22: =MIN(V3:V18) -> 189.92366
A23: 21 | B23: =CONCATENATE(C23,I23) -> GA2 | C23: GA | D23: Kaiser Foundation Health Plan of Georgia | E23: 89942GA0050005 | F23: KP GA Silver 2500/30 | G23: HMO | H23: Rating Area 2 | I23: 2 | J23: 258 | U23: max | V23: =MAX(V3:V18) -> 376.5458
A24: 22 | B24: =CONCATENATE(C24,I24) -> GA2 | C24: GA | D24: Anthem Blue Cross and Blue Shield | E24: 49046GA0410010 | F24: BCBSHP Silver DirectAccess - cbds | G24: HMO | H24: Rating Area 2 | I24: 2 | J24: 265.81
A25: 23 | B25: =CONCATENATE(C25,I25) -> GA2 | C25: GA | D25: Kaiser Foundation Health Plan of Georgia | E25: 89942GA0050004 | F25: KP GA Silver 1500/30 | G25: HMO | H25: Rating Area 2 | I25: 2 | J25: 273
A26: 24 | B26: =CONCATENATE(C26,I26) -> GA2 | C26: GA | D26: Anthem Blue Cross and Blue Shield | E26: 49046GA0410009 | F26: BCBSHP Silver DirectAccess - cbiq | G26: HMO | H26: Rating Area 2 | I26: 2 | J26: 273.2
A27: 25 | B27: =CONCATENATE(C27,I27) -> GA2 | C27: GA | D27: Anthem Blue Cross and Blue Shield | E27: 49046GA0610001 | F27: Blue Cross and Blue Shield Healthcare Plan of Georgia Silver DirectAccess, a Multi-State Plan | G27: HMO | H27: Rating Area 2 | I27: 2 | J27: 273.2
A28: 26 | B28: =CONCATENATE(C28,I28) -> GA2 | C28: GA | D28: Anthem Blue Cross and Blue Shield | E28: 49046GA0410008 | F28: BCBSHP Silver DirectAccess - cbaa | G28: HMO | H28: Rating Area 2 | I28: 2 | J28: 276.27
A29: 27 | B29: =CONCATENATE(C29,I29) -> GA2 | C29: GA | D29: Alliant Health Plans | E29: 83761GA0040015 | F29: SoloCare | G29: PPO | H29: Rating Area 2 | I29: 2 | J29: 288.95
A30: 28 | B30: =CONCATENATE(C30,I30) -> GA2 | C30: GA | D30: Alliant Health Plans | E30: 83761GA0040010 | F30: SoloCare | G30: PPO | H30: Rating Area 2 | I30: 2 | J30: 301.12
A31: 29 | B31: =CONCATENATE(C31,I31) -> GA3 | C31: GA | D31: Humana Employers Health Plan of Georgia, Inc. | E31: 93332GA0710004 | F31: Humana Connect Silver 4600/6300 Plan | G31: HMO | H31: Rating Area 3 | I31: 3 | J31: 187.8
A32: 30 | B32: =CONCATENATE(C32,I32) -> GA3 | C32: GA | D32: Humana Employers Health Plan of Georgia, Inc. | E32: 93332GA0720004 | F32: Humana National Preferred Silver 4250/6250 Plan | G32: POS | H32: Rating Area 3 | I32: 3 | J32: 205.38
A33: 31 | B33: =CONCATENATE(C33,I33) -> GA3 | C33: GA | D33: Kaiser Foundation Health Plan of Georgia | E33: 89942GA0050006 | F33: KP GA Silver 1750/25%/HSA | G33: HMO | H33: Rating Area 3 | I33: 3 | J33: 243
A34: 32 | B34: =CONCATENATE(C34,I34) -> GA3 | C34: GA | D34: Ambetter from Peach State Health Plan | E34: 45495GA0010009 | F34: Ambetter Silver 5 | G34: HMO | H34: Rating Area 3 | I34: 3 | J34: 247.03
A35: 33 | B35: =CONCATENATE(C35,I35) -> GA3 | C35: GA | D35: Alliant Health Plans | E35: 83761GA0040015 | F35: SoloCare | G35: PPO | H35: Rating Area 3 | I35: 3 | J35: 247.67
... A166: 164 | B166: =CONCATENATE(C166,I166) -> GA16 | C166: GA | D166: Anthem Blue Cross and Blue Shield | E166: 49046GA0410008 | F166: BCBSHP Silver DirectAccess - cbaa | G166: HMO | H166: Rating Area 16 | I166: 16 | J166: 282.79

Sheet 2014&2019 Data
B2: YEAR | C2: DATECAPTURE | D2: PLANID | E2: ST | F2: AREA | G2: CARRIER | H2: PLANNAME | I2: METAL | J2: PLANTYPE | K2: PREMIC | L2: PREMI27 | M2: PREMI50 | N2: PREMI2C30 | O2: PREMC2C30 | P2: CSR | Q2: PLANMARKET | R2: CHILDONLY | S2: NETWORKID | T2: actively_marketed | W2: Family of Four
B3: 2019 | C3: 43399 | D3: 70893GA0020002-04 | E3: GA | F3: GA07 | G3: Ambetter | H3: Ambetter Balanced Care 2 (2019) + Vision | I3: Silver | J3: 2 | L3: 373.56 | M3: 636.63 | N3: 949.96 | O3: 1354.54 | P3: 1 | Q3: 1 | R3: 0 | S3: 200138 | T3: TRUE
B4: 2019 | C4: 43399 | D4: 70893GA0020002-04 | E4: GA | F4: GA03 | G4: Ambetter | H4: Ambetter Balanced Care 2 (2019) + Vision | I4: Silver | J4: 2 | L4: 394.45 | M4: 672.22 | N4: 1003.05 | O4: 1430.24 | P4: 1 | Q4: 1 | R4: 0 | S4: 200138 | T4: TRUE
B5: 2019 | C5: 43399 | D5: 70893GA0020002-04 | E5: GA | F5: GA09 | G5: Ambetter | H5: Ambetter Balanced Care 2 (2019) + Vision | I5: Silver | J5: 2 | L5: 355.78 | M5: 606.31 | N5: 904.71 | O5: 1290.02 | P5: 1 | Q5: 1 | R5: 0 | S5: 200138 | T5: TRUE
B6: 2019 | C6: 43399 | D6: 70893GA0020001-06 | E6: GA | F6: GA07 | G6: Ambetter | H6: Ambetter Balanced Care 1 (2019) + Vision | I6: Silver | J6: 2 | L6: 377.93 | M6: 644.06 | N6: 961.04 | O6: 1370.34 | P6: 1 | Q6: 1 | R6: 0 | S6: 200138 | T6: TRUE
B7: 2019 | C7: 43399 | D7: 70893GA0020001-06 | E7: GA | F7: GA09 | G7: Ambetter | H7: Ambetter Balanced Care 1 (2019) + Vision | I7: Silver | J7: 2 | L7: 359.93 | M7: 613.39 | N7: 915.27 | O7: 1305.08 | P7: 1 | Q7: 1 | R7: 0 | S7: 200138 | T7: TRUE
B8: 2019 | C8: 43399 | D8: 70893GA0020001-05 | E8: GA | F8: GA09 | G8: Ambetter | H8: Ambetter Balanced Care 1 (2019) + Vision | I8: Silver | J8: 2 | L8: 359.93 | M8: 613.39 | N8: 915.27 | O8: 1305.08 | P8: 1 | Q8: 1 | R8: 0 | S8: 200138 | T8: TRUE
B9: 2019 | C9: 43399 | D9: 70893GA0020001-05 | E9: GA | F9: GA03 | G9: Ambetter | H9: Ambetter Balanced Care 1 (2019) + Vision | I9: Silver | J9: 2 | L9: 399.05 | M9: 680.06 | N9: 1014.76 | O9: 1446.94 | P9: 1 | Q9: 1 | R9: 0 | S9: 200138 | T9: TRUE
B10: 2019 | C10: 43399 | D10: 70893GA0020001-06 | E10: GA | F10: GA13 | G10: Ambetter | H10: Ambetter Balanced Care 1 (2019) + Vision | I10: Silver | J10: 2 | L10: 319.63 | M10: 544.72 | N10: 812.81 | O10: 1158.98 | P10: 1 | Q10: 1 | R10: 0 | S10: 200138 | T10: TRUE
B11: 2019 | C11: 43399 | D11: 70893GA0020001-05 | E11: GA | F11: GA07 | G11: Ambetter | H11: Ambetter Balanced Care 1 (2019) + Vision | I11: Silver | J11: 2 | L11: 377.93 | M11: 644.06 | N11: 961.04 | O11: 1370.34 | P11: 1 | Q11: 1 | R11: 0 | S11: 200138 | T11: TRUE
B12: 2019 | C12: 43399 | D12: 70893GA0020002-04 | E12: GA | F12: GA13 | G12: Ambetter | H12: Ambetter Balanced Care 2 (2019) + Vision | I12: Silver | J12: 2 | L12: 315.94 | M12: 538.43 | N12: 803.43 | O12: 1145.6 | P12: 1 | Q12: 1 | R12: 0 | S12: 200138 | T12: TRUE
B13: 2019 | C13: 43399 | D13: 70893GA0020001-06 | E13: GA | F13: GA03 | G13: Ambetter | H13: Ambetter Balanced Care 1 (2019) + Vision | I13: Silver | J13: 2 | L13: 399.05 | M13: 680.06 | N13: 1014.76 | O13: 1446.94 | P13: 1 | Q13: 1 | R13: 0 | S13: 200138 | T13: TRUE
B14: 2019 | C14: 43399 | D14: 70893GA0020001-05 | E14: GA | F14: GA13 | G14: Ambetter | H14: Ambetter Balanced Care 1 (2019) + Vision | I14: Silver | J14: 2 | L14: 319.63 | M14: 544.72 | N14: 812.81 | O14: 1158.98 | P14: 1 | Q14: 1 | R14: 0 | S14: 200138 | T14: TRUE
... B1240: 2019 | C1240: 43400 | D1240: 83761GA0040234-05 | E1240: GA | F1240: GA10 | G1240: Alliant Health Plans | H1240: SoloCare Silver Copay Lumpkin | I1240: Silver | J1240: 1 | L1240: 578.27 | M1240: 985.48 | N1240: 1470.49 | O1240: 2096.76 | P1240: 1 | Q1240: 1 | R1240: 0 | S1240: 200289 | T1240: TRUE
B1241: 2014 | C1241: 42795 | D1241: 45495GA0030007-06 | E1241: GA | F1241: GA02 | G1241: Ambetter | H1241: Ambetter Silver 3 + Vision + Adult Dental | I1241: Silver | J1241: 2 | L1241: 209.86 | M1241: 357.65 | N1241: 481.61 | O1241: 708.9 | P1241: 1 | Q1241: 1 | R1241: 0 | T1241: TRUE
B1242: 2014 | C1242: 42795 | D1242: 45495GA0030007-06 | E1242: GA | F1242: GA03 | G1242: Ambetter | H1242: Ambetter Silver 3 + Vision + Adult Dental | I1242: Silver | J1242: 2 | L1242: 263.74 | M1242: 449.46 | N1242: 605.23 | O1242: 890.86 | P1242: 1 | Q1242: 1 | R1242: 0 | T1242: TRUE
B1243: 2014 | C1243: 42795 | D1243: 45495GA0030007-06 | E1243: GA | F1243: GA08 | G1243: Ambetter | H1243: Ambetter Silver 3 + Vision + Adult Dental | I1243: Silver | J1243: 2 | L1243: 231.31 | M1243: 394.2 | N1243: 530.81 | O1243: 781.32 | P1243: 1 | Q1243: 1 | R1243: 0 | T1243: TRUE
B1244: 2014 | C1244: 42795 | D1244: 93332GA0710007 | E1244: GA | F1244: GA10 | G1244: Humana | H1244: Humana Connect Platinum 1000/1500 Plan | I1244: Platinum | J1244: 2 | L1244: 241.5 | M1244: 411.58 | N1244: 554.19 | O1244: 815.74 | P1244: 0 | Q1244: 3 | R1244: 0 | T1244: TRUE
B1245: 2014 | C1245: 42795 | D1245: 93332GA0710007 | E1245: GA | F1245: GA03 | G1245: Humana | H1245: Humana Connect Platinum 1000/1500 Plan | I1245: Platinum | J1245: 2 | L1245: 241.5 | M1245: 411.58 | N1245: 554.19 | O1245: 815.74 | P1245: 0 | Q1245: 3 | R1245: 0 | T1245: TRUE
B1246: 2014 | C1246: 42795 | D1246: 93332GA0710007 | E1246: GA | F1246: GA13 | G1246: Humana | H1246: Humana Connect Platinum 1000/1500 Plan | I1246: Platinum | J1246: 2 | L1246: 241.5 | M1246: 411.58 | N1246: 554.19 | O1246: 815.74 | P1246: 0 | Q1246: 3 | R1246: 0 | T1246: TRUE
B1247: 2014 | C1247: 42795 | D1247: 93332GA0710004-06 | E1247: GA | F1247: GA10 | G1247: Humana | H1247: Humana Connect Silver 4600/6300 Plan | I1247: Silver | J1247: 2 | L1247: 187.8 | M1247: 320.06 | N1247: 430.95 | O1247: 634.34 | P1247: 1 | Q1247: 1 | R1247: 0 | T1247: TRUE
B1248: 2014 | C1248: 42795 | D1248: 93332GA0710004-06 | E1248: GA | F1248: GA13 | G1248: Humana | H1248: Humana Connect Silver 4600/6300 Plan | I1248: Silver | J1248: 2 | L1248: 187.8 | M1248: 320.06 | N1248: 430.95 | O1248: 634.34 | P1248: 1 | Q1248: 1 | R1248: 0 | T1248: TRUE
B1249: 2014 | C1249: 42795 | D1249: 93332GA0710004-06 | E1249: GA | F1249: GA03 | G1249: Humana | H1249: Humana Connect Silver 4600/6300 Plan | I1249: Silver | J1249: 2 | L1249: 187.8 | M1249: 320.06 | N1249: 430.95 | O1249: 634.34 | P1249: 1 | Q1249: 1 | R1249: 0 | T1249: TRUE
B1250: 2014 | C1250: 42795 | D1250: 83761GA0040010-05 | E1250: GA | F1250: GA03 | G1250: Alliant Health Plans | H1250: SoloCare | I1250: Silver | J1250: 1 | L1250: 258.1 | M1250: 439.85 | N1250: 592.31 | O1250: 871.84 | P1250: 1 | Q1250: 1 | R1250: 0 | T1250: TRUE
B1251: 2014 | C1251: 42795 | D1251: 83761GA0040010-05 | E1251: GA | F1251: GA09 | G1251: Alliant Health Plans | H1251: SoloCare | I1251: Silver | J1251: 1 | L1251: 286.78 | M1251: 488.73 | N1251: 658.1 | O1251: 968.68 | P1251: 1 | Q1251: 1 | R1251: 0 | T1251: TRUE
B1252: 2014 | C1252: 42795 | D1252: 83761GA0040010-05 | E1252: GA | F1252: GA10 | G1252: Alliant Health Plans | H1252: SoloCare | I1252: Silver | J1252: 1 | L1252: 272.44 | M1252: 464.29 | N1252: 625.19 | O1252: 920.24 | P1252: 1 | Q1252: 1 | R1252: 0 | T1252: TRUE
... B2233: 2014 | C2233: 42795 | D2233: 83761GA0040010-06 | E2233: GA | F2233: GA02 | G2233: Alliant Health Plans | H2233: SoloCare | I2233: Silver | J2233: 1 | L2233: 301.12 | M2233: 513.16 | N2233: 691.01 | O2233: 1017.12 | P2233: 1 | Q2233: 1 | R2233: 0 | T2233: TRUE

Sheet CostAnalysis
F1: Number of Plans | K1: Sum of Premiums for Family of Four | P1: Average Premium for Family of Four | U1: Number of Plans | Z1: Sum of Premiums for Family of Four | AE1: Average Premium for Family of Four
F2: 2014 | G2: 2014 | H2: 2014 | I2: 2014 | J2: 2014 | K2: 2014 | L2: 2014 | M2: 2014 | N2: 2014 | O2: 2014 | P2: 2014 | Q2: 2014 | R2: 2014 | S2: 2014 | T2: 2014 | U2: 2019 | V2: 2019 | W2: 2019 | X2: 2019 | Y2: 2019 | Z2: 2019 | AA2: 2019 | AB2: 2019 | AC2: 2019 | AD2: 2019 | AE2: 2019 | AF2: 2019 | AG2: 2019 | AH2: 2019 | AI2: 2019 | AK2: Price increases
B3: Code | C3: State | E3: Rating Area # | F3: Catastrophic | G3: Bronze | H3: Silver | I3: Gold | J3: Platinum | K3: Catastrophic | L3: Bronze | M3: Silver | N3: Gold | O3: Platinum | P3: Catastrophic | Q3: Bronze | R3: Silver | S3: Gold | T3: Platinum | U3: Catastrophic | V3: Bronze | W3: Silver | X3: Gold | Y3: Platinum | Z3: Catastrophic | AA3: Bronze | AB3: Silver | AC3: Gold | AD3: Platinum | AE3: Catastrophic | AF3: Bronze | AG3: Silver | AH3: Gold | AI3: Platinum | AK3: Platinum | AL3: Catastrophic | AM3: Bronze | AN3: Silver | AO3: Gold | AP3: Platinum
A4: GA01 | B4: =CONCATENATE(C4,E4) -> GA1 | C4: GA | D4: Rating Area 1 | E4: 1 | F4: =COUNTIFS(Metal,F$3,YEAR,F$2,AREA,$A4) -> 1 | G4: =COUNTIFS(Metal,G$3,YEAR,G$2,AREA,$A4) -> 6 | H4: =COUNTIFS(Metal,H$3,YEAR,H$2,AREA,$A4) -> 20 | I4: =COUNTIFS(Metal,I$3,YEAR,I$2,AREA,$A4) -> 3 | J4: =COUNTIFS(Metal,J$3,YEAR,J$2,AREA,$A4) -> 0 | K4: =SUMIFS(PREMC2CA30,AREA,$A4,YEAR,K$2,Metal,K$3) -> 871.52 | L4: =SUMIFS(PREMC2CA30,AREA,$A4,YEAR,L$2,Metal,L$3) -> 6640.8 | M4: =SUMIFS(PREMC2CA30,AREA,$A4,YEAR,M$2,Metal,M$3) -> 26940.72 | N4: =SUMIFS(PREMC2CA30,AREA,$A4,YEAR,N$2,Metal,N$3) -> 5107.3 | O4: =SUMIFS(PREMC2CA30,AREA,$A4,YEAR,O$2,Metal,O$3) -> 0 | P4: =K4/F4 -> 871.52 | Q4: =L4/G4 -> 1106.8 | R4: =M4/H4 -> 1347.036 | S4: =N4/I4 -> 1702.4333 | T4: =O4/J4 -> #DIV/0! | U4: =COUNTIFS(Metal,U$3,YEAR,U$2,AREA,$A4) -> 0 | V4: =COUNTIFS(Metal,V$3,YEAR,V$2,AREA,$A4) -> 2 | W4: =COUNTIFS(Metal,W$3,YEAR,W$2,AREA,$A4) -> 44 | X4: =COUNTIFS(Metal,X$3,YEAR,X$2,AREA,$A4) -> 1 | Y4: =COUNTIFS(Metal,Y$3,YEAR,Y$2,AREA,$A4) -> 0 | Z4: =SUMIFS(PREMC2CA30,AREA,$A4,YEAR,Z$2,Metal,Z$3) -> 0 | AA4: =SUMIFS(PREMC2CA30,AREA,$A4,YEAR,AA$2,Metal,AA$3) -> 2752.16 | AB4: =SUMIFS(PREMC2CA30,AREA,$A4,YEAR,AB$2,Metal,AB$3) -> 73101.76 | AC4: =SUMIFS(PREMC2CA30,AREA,$A4,YEAR,AC$2,Metal,AC$3) -> 1690.98 | AD4: =SUMIFS(PREMC2CA30,AREA,$A4,YEAR,AD$2,Metal,AD$3) -> 0 | AE4: =Z4/U4 -> #DIV/0! | AF4: =AA4/V4 -> 1376.08 | AG4: =AB4/W4 -> 1661.4036 | AH4: =AC4/X4 -> 1690.98 | AI4: =AD4/Y4 -> #DIV/0! | AK4: =AE4/P4-1 -> #DIV/0! | AL4: =AF4/Q4-1 -> 0.24329599 | AM4: =AG4/R4-1 -> 0.23337731 | AN4: =AH4/S4-1 -> -0.0067276252 | AO4: =AI4/T4-1 -> #DIV/0! | AP4: =AJ4/U4-1 -> #DIV/0!
A5: GA02 | B5: =CONCATENATE(C5,E5) -> GA2 | C5: GA | D5: Rating Area 2 | E5: 2 | F5: =COUNTIFS(Metal,F$3,YEAR,F$2,AREA,$A5) -> 3 | G5: =COUNTIFS(Metal,G$3,YEAR,G$2,AREA,$A5) -> 21 | H5: =COUNTIFS(Metal,H$3,YEAR,H$2,AREA,$A5) -> 92 | I5: =COUNTIFS(Metal,I$3,YEAR,I$2,AREA,$A5) -> 14 | J5: =COUNTIFS(Metal,J$3,YEAR,J$2,AREA,$A5) -> 1 | K5: =SUMIFS(PREMC2CA30,AREA,$A5,YEAR,K$2,Metal,K$3) -> 1617.64 | L5: =SUMIFS(PREMC2CA30,AREA,$A5,YEAR,L$2,Metal,L$3) -> 14095.2 | M5: =SUMIFS(PREMC2CA30,AREA,$A5,YEAR,M$2,Metal,M$3) -> 73329.12 | N5: =SUMIFS(PREMC2CA30,AREA,$A5,YEAR,N$2,Metal,N$3) -> 13673.32 | O5: =SUMIFS(PREMC2CA30,AREA,$A5,YEAR,O$2,Metal,O$3) -> 995.56 | P5: =K5/F5 -> 539.21333 | Q5: =L5/G5 -> 671.2 | R5: =M5/H5 -> 797.05565 | S5: =N5/I5 -> 976.66571 | T5: =O5/J5 -> 995.56 | U5: =COUNTIFS(Metal,U$3,YEAR,U$2,AREA,$A5) -> 1 | V5: =COUNTIFS(Metal,V$3,YEAR,V$2,AREA,$A5) -> 9 | W5: =COUNTIFS(Metal,W$3,YEAR,W$2,AREA,$A5) -> 61 | X5: =COUNTIFS(Metal,X$3,YEAR,X$2,AREA,$A5) -> 4 | Y5: =COUNTIFS(Metal,Y$3,YEAR,Y$2,AREA,$A5) -> 2 | Z5: =SUMIFS(PREMC2CA30,AREA,$A5,YEAR,Z$2,Metal,Z$3) -> 819.12 | AA5: =SUMIFS(PREMC2CA30,AREA,$A5,YEAR,AA$2,Metal,AA$3) -> 11294.26 | AB5: =SUMIFS(PREMC2CA30,AREA,$A5,YEAR,AB$2,Metal,AB$3) -> 86649.34 | AC5: =SUMIFS(PREMC2CA30,AREA,$A5,YEAR,AC$2,Metal,AC$3) -> 7492.34 | AD5: =SUMIFS(PREMC2CA30,AREA,$A5,YEAR,AD$2,Metal,AD$3) -> 4120.3 | AE5: =Z5/U5 -> 819.12 | AF5: =AA5/V5 -> 1254.9178 | AG5: =AB5/W5 -> 1420.481 | AH5: =AC5/X5 -> 1873.085 | AI5: =AD5/Y5 -> 2060.15 | AK5: =AE5/P5-1 -> 0.5191019 | AL5: =AF5/Q5-1 -> 0.86966296 | AM5: =AG5/R5-1 -> 0.78216035 | AN5: =AH5/S5-1 -> 0.91783634 | AO5: =AI5/T5-1 -> 1.0693379 | AP5: =AJ5/U5-1 -> -1
A6: GA03 | B6: =CONCATENATE(C6,E6) -> GA3 | C6: GA | D6: Rating Area 3 | E6: 3 | F6: =COUNTIFS(Metal,F$3,YEAR,F$2,AREA,$A6) -> 4 | G6: =COUNTIFS(Metal,G$3,YEAR,G$2,AREA,$A6) -> 23 | H6: =COUNTIFS(Metal,H$3,YEAR,H$2,AREA,$A6) -> 96 | I6: =COUNTIFS(Metal,I$3,YEAR,I$2,AREA,$A6) -> 15 | J6: =COUNTIFS(Metal,J$3,YEAR,J$2,AREA,$A6) -> 2 | K6: =SUMIFS(PREMC2CA30,AREA,$A6,YEAR,K$2,Metal,K$3) -> 1995.86 | L6: =SUMIFS(PREMC2CA30,AREA,$A6,YEAR,L$2,Metal,L$3) -> 16322.84 | M6: =SUMIFS(PREMC2CA30,AREA,$A6,YEAR,M$2,Metal,M$3) -> 83093.92 | N6: =SUMIFS(PREMC2CA30,AREA,$A6,YEAR,N$2,Metal,N$3) -> 15298.28 | O6: =SUMIFS(PREMC2CA30,AREA,$A6,YEAR,O$2,Metal,O$3) -> 1712.74 | P6: =K6/F6 -> 498.965 | Q6: =L6/G6 -> 709.6887 | R6: =M6/H6 -> 865.56167 | S6: =N6/I6 -> 1019.8853 | T6: =O6/J6 -> 856.37 | U6: =COUNTIFS(Metal,U$3,YEAR,U$2,AREA,$A6) -> 6 | V6: =COUNTIFS(Metal,V$3,YEAR,V$2,AREA,$A6) -> 20 | W6: =COUNTIFS(Metal,W$3,YEAR,W$2,AREA,$A6) -> 126 | X6: =COUNTIFS(Metal,X$3,YEAR,X$2,AREA,$A6) -> 11 | Y6: =COUNTIFS(Metal,Y$3,YEAR,Y$2,AREA,$A6) -> 0 | Z6: =SUMIFS(PREMC2CA30,AREA,$A6,YEAR,Z$2,Metal,Z$3) -> 6128.6 | AA6: =SUMIFS(PREMC2CA30,AREA,$A6,YEAR,AA$2,Metal,AA$3) -> 24442.58 | AB6: =SUMIFS(PREMC2CA30,AREA,$A6,YEAR,AB$2,Metal,AB$3) -> 199738.86 | AC6: =SUMIFS(PREMC2CA30,AREA,$A6,YEAR,AC$2,Metal,AC$3) -> 20987.86 | AD6: =SUMIFS(PREMC2CA30,AREA,$A6,YEAR,AD$2,Metal,AD$3) -> 0 | AE6: =Z6/U6 -> 1021.4333 | AF6: =AA6/V6 -> 1222.129 | AG6: =AB6/W6 -> 1585.229 | AH6: =AC6/X6 -> 1907.9873 | AI6: =AD6/Y6 -> #DIV/0! | AK6: =AE6/P6-1 -> 1.0471042 | AL6: =AF6/Q6-1 -> 0.7220635 | AM6: =AG6/R6-1 -> 0.83144553 | AN6: =AH6/S6-1 -> 0.87078607 | AO6: =AI6/T6-1 -> #DIV/0! | AP6: =AJ6/U6-1 -> -1
A7: GA04 | B7: =CONCATENATE(C7,E7) -> GA4 | C7: GA | D7: Rating Area 4 | E7: 4 | F7: =COUNTIFS(Metal,F$3,YEAR,F$2,AREA,$A7) -> 3 | G7: =COUNTIFS(Metal,G$3,YEAR,G$2,AREA,$A7) -> 12 | H7: =COUNTIFS(Metal,H$3,YEAR,H$2,AREA,$A7) -> 44 | I7: =COUNTIFS(Metal,I$3,YEAR,I$2,AREA,$A7) -> 8 | J7: =COUNTIFS(Metal,J$3,YEAR,J$2,AREA,$A7) -> 1 | K7: =SUMIFS(PREMC2CA30,AREA,$A7,YEAR,K$2,Metal,K$3) -> 1731.08 | L7: =SUMIFS(PREMC2CA30,AREA,$A7,YEAR,L$2,Metal,L$3) -> 9875.74 | M7: =SUMIFS(PREMC2CA30,AREA,$A7,YEAR,M$2,Metal,M$3) -> 44132 | N7: =SUMIFS(PREMC2CA30,AREA,$A7,YEAR,N$2,Metal,N$3) -> 9442.42 | O7: =SUMIFS(PREMC2CA30,AREA,$A7,YEAR,O$2,Metal,O$3) -> 933.52 | P7: =K7/F7 -> 577.02667 | Q7: =L7/G7 -> 822.97833 | R7: =M7/H7 -> 1003 | S7: =N7/I7 -> 1180.3025 | T7: =O7/J7 -> 933.52 | U7: =COUNTIFS(Metal,U$3,YEAR,U$2,AREA,$A7) -> 1 | V7: =COUNTIFS(Metal,V$3,YEAR,V$2,AREA,$A7) -> 5 | W7: =COUNTIFS(Metal,W$3,YEAR,W$2,AREA,$A7) -> 8 | X7: =COUNTIFS(Metal,X$3,YEAR,X$2,AREA,$A7) -> 1 | Y7: =COUNTIFS(Metal,Y$3,YEAR,Y$2,AREA,$A7) -> 0 | Z7: =SUMIFS(PREMC2CA30,AREA,$A7,YEAR,Z$2,Metal,Z$3) -> 1059.48 | AA7: =SUMIFS(PREMC2CA30,AREA,$A7,YEAR,AA$2,Metal,AA$3) -> 8177.12 | AB7: =SUMIFS(PREMC2CA30,AREA,$A7,YEAR,AB$2,Metal,AB$3) -> 19030.56 | AC7: =SUMIFS(PREMC2CA30,AREA,$A7,YEAR,AC$2,Metal,AC$3) -> 3359.1 | AD7: =SUMIFS(PREMC2CA30,AREA,$A7,YEAR,AD$2,Metal,AD$3) -> 0 | AE7: =Z7/U7 -> 1059.48 | AF7: =AA7/V7 -> 1635.424 | AG7: =AB7/W7 -> 2378.82 | AH7: =AC7/X7 -> 3359.1 | AI7: =AD7/Y7 -> #DIV/0! | AK7: =AE7/P7-1 -> 0.83610232 | AL7: =AF7/Q7-1 -> 0.98720177 | AM7: =AG7/R7-1 -> 1.3717049 | AN7: =AH7/S7-1 -> 1.8459653 | AO7: =AI7/T7-1 -> #DIV/0! | AP7: =AJ7/U7-1 -> -1
A8: GA05 | B8: =CONCATENATE(C8,E8) -> GA5 | C8: GA | D8: Rating Area 5 | E8: 5 | F8: =COUNTIFS(Metal,F$3,YEAR,F$2,AREA,$A8) -> 2 | G8: =COUNTIFS(Metal,G$3,YEAR,G$2,AREA,$A8) -> 7 | H8: =COUNTIFS(Metal,H$3,YEAR,H$2,AREA,$A8) -> 24 | I8: =COUNTIFS(Metal,I$3,YEAR,I$2,AREA,$A8) -> 4 | J8: =COUNTIFS(Metal,J$3,YEAR,J$2,AREA,$A8) -> 1 | K8: =SUMIFS(PREMC2CA30,AREA,$A8,YEAR,K$2,Metal,K$3) -> 1086.26 | L8: =SUMIFS(PREMC2CA30,AREA,$A8,YEAR,L$2,Metal,L$3) -> 5222.9 | M8: =SUMIFS(PREMC2CA30,AREA,$A8,YEAR,M$2,Metal,M$3) -> 21585.84 | N8: =SUMIFS(PREMC2CA30,AREA,$A8,YEAR,N$2,Metal,N$3) -> 4365.52 | O8: =SUMIFS(PREMC2CA30,AREA,$A8,YEAR,O$2,Metal,O$3) -> 908.9 | P8: =K8/F8 -> 543.13 | Q8: =L8/G8 -> 746.12857 | R8: =M8/H8 -> 899.41 | S8: =N8/I8 -> 1091.38 | T8: =O8/J8 -> 908.9 | U8: =COUNTIFS(Metal,U$3,YEAR,U$2,AREA,$A8) -> 2 | V8: =COUNTIFS(Metal,V$3,YEAR,V$2,AREA,$A8) -> 10 | W8: =COUNTIFS(Metal,W$3,YEAR,W$2,AREA,$A8) -> 16 | X8: =COUNTIFS(Metal,X$3,YEAR,X$2,AREA,$A8) -> 2 | Y8: =COUNTIFS(Metal,Y$3,YEAR,Y$2,AREA,$A8) -> 0 | Z8: =SUMIFS(PREMC2CA30,AREA,$A8,YEAR,Z$2,Metal,Z$3) -> 1403.16 | AA8: =SUMIFS(PREMC2CA30,AREA,$A8,YEAR,AA$2,Metal,AA$3) -> 10828.78 | AB8: =SUMIFS(PREMC2CA30,AREA,$A8,YEAR,AB$2,Metal,AB$3) -> 25201.04 | AC8: =SUMIFS(PREMC2CA30,AREA,$A8,YEAR,AC$2,Metal,AC$3) -> 4447.96 | AD8: =SUMIFS(PREMC2CA30,AREA,$A8,YEAR,AD$2,Metal,AD$3) -> 0 | AE8: =Z8/U8 -> 701.58 | AF8: =AA8/V8 -> 1082.878 | AG8: =AB8/W8 -> 1575.065 | AH8: =AC8/X8 -> 2223.98 | AI8: =AD8/Y8 -> #DIV/0! | AK8: =AE8/P8-1 -> 0.29173494 | AL8: =AF8/Q8-1 -> 0.45132896 | AM8: =AG8/R8-1 -> 0.75122024 | AN8: =AH8/S8-1 -> 1.0377687 | AO8: =AI8/T8-1 -> #DIV/0! | AP8: =AJ8/U8-1 -> -1
A9: GA06 | B9: =CONCATENATE(C9,E9) -> GA6 | C9: GA | D9: Rating Area 6 | E9: 6 | F9: =COUNTIFS(Metal,F$3,YEAR,F$2,AREA,$A9) -> 2 | G9: =COUNTIFS(Metal,G$3,YEAR,G$2,AREA,$A9) -> 7 | H9: =COUNTIFS(Metal,H$3,YEAR,H$2,AREA,$A9) -> 24 | I9: =COUNTIFS(Metal,I$3,YEAR,I$2,AREA,$A9) -> 4 | J9: =COUNTIFS(Metal,J$3,YEAR,J$2,AREA,$A9) -> 1 | K9: =SUMIFS(PREMC2CA30,AREA,$A9,YEAR,K$2,Metal,K$3) -> 1226.74 | L9: =SUMIFS(PREMC2CA30,AREA,$A9,YEAR,L$2,Metal,L$3) -> 6431.8 | M9: =SUMIFS(PREMC2CA30,AREA,$A9,YEAR,M$2,Metal,M$3) -> 26472.48 | N9: =SUMIFS(PREMC2CA30,AREA,$A9,YEAR,N$2,Metal,N$3) -> 5279.44 | O9: =SUMIFS(PREMC2CA30,AREA,$A9,YEAR,O$2,Metal,O$3) -> 867.58 | P9: =K9/F9 -> 613.37 | Q9: =L9/G9 -> 918.82857 | R9: =M9/H9 -> 1103.02 | S9: =N9/I9 -> 1319.86 | T9: =O9/J9 -> 867.58 | U9: =COUNTIFS(Metal,U$3,YEAR,U$2,AREA,$A9) -> 1 | V9: =COUNTIFS(Metal,V$3,YEAR,V$2,AREA,$A9) -> 7 | W9: =COUNTIFS(Metal,W$3,YEAR,W$2,AREA,$A9) -> 52 | X9: =COUNTIFS(Metal,X$3,YEAR,X$2,AREA,$A9) -> 2 | Y9: =COUNTIFS(Metal,Y$3,YEAR,Y$2,AREA,$A9) -> 0 | Z9: =SUMIFS(PREMC2CA30,AREA,$A9,YEAR,Z$2,Metal,Z$3) -> 949.2 | AA9: =SUMIFS(PREMC2CA30,AREA,$A9,YEAR,AA$2,Metal,AA$3) -> 9251.04 | AB9: =SUMIFS(PREMC2CA30,AREA,$A9,YEAR,AB$2,Metal,AB$3) -> 68183.2 | AC9: =SUMIFS(PREMC2CA30,AREA,$A9,YEAR,AC$2,Metal,AC$3) -> 4192.22 | AD9: =SUMIFS(PREMC2CA30,AREA,$A9,YEAR,AD$2,Metal,AD$3) -> 0 | AE9: =Z9/U9 -> 949.2 | AF9: =AA9/V9 -> 1321.5771 | AG9: =AB9/W9 -> 1311.2154 | AH9: =AC9/X9 -> 2096.11 | AI9: =AD9/Y9 -> #DIV/0! | AK9: =AE9/P9-1 -> 0.54751618 | AL9: =AF9/Q9-1 -> 0.43832831 | AM9: =AG9/R9-1 -> 0.18875033 | AN9: =AH9/S9-1 -> 0.58813056 | AO9: =AI9/T9-1 -> #DIV/0! | AP9: =AJ9/U9-1 -> -1
A10: GA07 | B10: =CONCATENATE(C10,E10) -> GA7 | C10: GA | D10: Rating Area 7 | E10: 7 | F10: =COUNTIFS(Metal,F$3,YEAR,F$2,AREA,$A10) -> 1 | G10: =COUNTIFS(Metal,G$3,YEAR,G$2,AREA,$A10) -> 8 | H10: =COUNTIFS(Metal,H$3,YEAR,H$2,AREA,$A10) -> 28 | I10: =COUNTIFS(Metal,I$3,YEAR,I$2,AREA,$A10) -> 5 | J10: =COUNTIFS(Metal,J$3,YEAR,J$2,AREA,$A10) -> 0 | K10: =SUMIFS(PREMC2CA30,AREA,$A10,YEAR,K$2,Metal,K$3) -> 673.42 | L10: =SUMIFS(PREMC2CA30,AREA,$A10,YEAR,L$2,Metal,L$3) -> 6755.74 | M10: =SUMIFS(PREMC2CA30,AREA,$A10,YEAR,M$2,Metal,M$3) -> 28410.08 | N10: =SUMIFS(PREMC2CA30,AREA,$A10,YEAR,N$2,Metal,N$3) -> 6071.26 | O10: =SUMIFS(PREMC2CA30,AREA,$A10,YEAR,O$2,Metal,O$3) -> 0 | P10: =K10/F10 -> 673.42 | Q10: =L10/G10 -> 844.4675 | R10: =M10/H10 -> 1014.6457 | S10: =N10/I10 -> 1214.252 | T10: =O10/J10 -> #DIV/0! | U10: =COUNTIFS(Metal,U$3,YEAR,U$2,AREA,$A10) -> 0 | V10: =COUNTIFS(Metal,V$3,YEAR,V$2,AREA,$A10) -> 2 | W10: =COUNTIFS(Metal,W$3,YEAR,W$2,AREA,$A10) -> 44 | X10: =COUNTIFS(Metal,X$3,YEAR,X$2,AREA,$A10) -> 1 | Y10: =COUNTIFS(Metal,Y$3,YEAR,Y$2,AREA,$A10) -> 0 | Z10: =SUMIFS(PREMC2CA30,AREA,$A10,YEAR,Z$2,Metal,Z$3) -> 0 | AA10: =SUMIFS(PREMC2CA30,AREA,$A10,YEAR,AA$2,Metal,AA$3) -> 2276.22 | AB10: =SUMIFS(PREMC2CA30,AREA,$A10,YEAR,AB$2,Metal,AB$3) -> 60458.88 | AC10: =SUMIFS(PREMC2CA30,AREA,$A10,YEAR,AC$2,Metal,AC$3) -> 1398.54 | AD10: =SUMIFS(PREMC2CA30,AREA,$A10,YEAR,AD$2,Metal,AD$3) -> 0 | AE10: =Z10/U10 -> #DIV/0! | AF10: =AA10/V10 -> 1138.11 | AG10: =AB10/W10 -> 1374.0655 | AH10: =AC10/X10 -> 1398.54 | AI10: =AD10/Y10 -> #DIV/0! | AK10: =AE10/P10-1 -> #DIV/0! | AL10: =AF10/Q10-1 -> 0.34772505 | AM10: =AG10/R10-1 -> 0.35423176 | AN10: =AH10/S10-1 -> 0.1517708 | AO10: =AI10/T10-1 -> #DIV/0! | AP10: =AJ10/U10-1 -> #DIV/0!
A11: GA08 | B11: =CONCATENATE(C11,E11) -> GA8 | C11: GA | D11: Rating Area 8 | E11: 8 | F11: =COUNTIFS(Metal,F$3,YEAR,F$2,AREA,$A11) -> 4 | G11: =COUNTIFS(Metal,G$3,YEAR,G$2,AREA,$A11) -> 21 | H11: =COUNTIFS(Metal,H$3,YEAR,H$2,AREA,$A11) -> 88 | I11: =COUNTIFS(Metal,I$3,YEAR,I$2,AREA,$A11) -> 13 | J11: =COUNTIFS(Metal,J$3,YEAR,J$2,AREA,$A11) -> 2 | K11: =SUMIFS(PREMC2CA30,AREA,$A11,YEAR,K$2,Metal,K$3) -> 2047.28 | L11: =SUMIFS(PREMC2CA30,AREA,$A11,YEAR,L$2,Metal,L$3) -> 14258.94 | M11: =SUMIFS(PREMC2CA30,AREA,$A11,YEAR,M$2,Metal,M$3) -> 71840.48 | N11: =SUMIFS(PREMC2CA30,AREA,$A11,YEAR,N$2,Metal,N$3) -> 12768.58 | O11: =SUMIFS(PREMC2CA30,AREA,$A11,YEAR,O$2,Metal,O$3) -> 1774.08 | P11: =K11/F11 -> 511.82 | Q11: =L11/G11 -> 678.99714 | R11: =M11/H11 -> 816.36909 | S11: =N11/I11 -> 982.19846 | T11: =O11/J11 -> 887.04 | U11: =COUNTIFS(Metal,U$3,YEAR,U$2,AREA,$A11) -> 1 | V11: =COUNTIFS(Metal,V$3,YEAR,V$2,AREA,$A11) -> 7 | W11: =COUNTIFS(Metal,W$3,YEAR,W$2,AREA,$A11) -> 52 | X11: =COUNTIFS(Metal,X$3,YEAR,X$2,AREA,$A11) -> 2 | Y11: =COUNTIFS(Metal,Y$3,YEAR,Y$2,AREA,$A11) -> 0 | Z11: =SUMIFS(PREMC2CA30,AREA,$A11,YEAR,Z$2,Metal,Z$3) -> 874.04 | AA11: =SUMIFS(PREMC2CA30,AREA,$A11,YEAR,AA$2,Metal,AA$3) -> 8866.64 | AB11: =SUMIFS(PREMC2CA30,AREA,$A11,YEAR,AB$2,Metal,AB$3) -> 72027.92 | AC11: =SUMIFS(PREMC2CA30,AREA,$A11,YEAR,AC$2,Metal,AC$3) -> 4074.16 | AD11: =SUMIFS(PREMC2CA30,AREA,$A11,YEAR,AD$2,Metal,AD$3) -> 0 | AE11: =Z11/U11 -> 874.04 | AF11: =AA11/V11 -> 1266.6629 | AG11: =AB11/W11 -> 1385.1523 | AH11: =AC11/X11 -> 2037.08 | AI11: =AD11/Y11 -> #DIV/0! | AK11: =AE11/P11-1 -> 0.70770974 | AL11: =AF11/Q11-1 -> 0.8654907 | AM11: =AG11/R11-1 -> 0.69672312 | AN11: =AH11/S11-1 -> 1.0740004 | AO11: =AI11/T11-1 -> #DIV/0! | AP11: =AJ11/U11-1 -> -1
A12: GA09 | B12: =CONCATENATE(C12,E12) -> GA9 | C12: GA | D12: Rating Area 9 | E12: 9 | F12: =COUNTIFS(Metal,F$3,YEAR,F$2,AREA,$A12) -> 1 | G12: =COUNTIFS(Metal,G$3,YEAR,G$2,AREA,$A12) -> 8 | H12: =COUNTIFS(Metal,H$3,YEAR,H$2,AREA,$A12) -> 28 | I12: =COUNTIFS(Metal,I$3,YEAR,I$2,AREA,$A12) -> 5 | J12: =COUNTIFS(Metal,J$3,YEAR,J$2,AREA,$A12) -> 0 | K12: =SUMIFS(PREMC2CA30,AREA,$A12,YEAR,K$2,Metal,K$3) -> 623.32 | L12: =SUMIFS(PREMC2CA30,AREA,$A12,YEAR,L$2,Metal,L$3) -> 6373.8 | M12: =SUMIFS(PREMC2CA30,AREA,$A12,YEAR,M$2,Metal,M$3) -> 26861.04 | N12: =SUMIFS(PREMC2CA30,AREA,$A12,YEAR,N$2,Metal,N$3) -> 5777.66 | O12: =SUMIFS(PREMC2CA30,AREA,$A12,YEAR,O$2,Metal,O$3) -> 0 | P12: =K12/F12 -> 623.32 | Q12: =L12/G12 -> 796.725 | R12: =M12/H12 -> 959.32286 | S12: =N12/I12 -> 1155.532 | T12: =O12/J12 -> #DIV/0! | U12: =COUNTIFS(Metal,U$3,YEAR,U$2,AREA,$A12) -> 1 | V12: =COUNTIFS(Metal,V$3,YEAR,V$2,AREA,$A12) -> 13 | W12: =COUNTIFS(Metal,W$3,YEAR,W$2,AREA,$A12) -> 95 | X12: =COUNTIFS(Metal,X$3,YEAR,X$2,AREA,$A12) -> 8 | Y12: =COUNTIFS(Metal,Y$3,YEAR,Y$2,AREA,$A12) -> 6 | Z12: =SUMIFS(PREMC2CA30,AREA,$A12,YEAR,Z$2,Metal,Z$3) -> 863.12 | AA12: =SUMIFS(PREMC2CA30,AREA,$A12,YEAR,AA$2,Metal,AA$3) -> 16004.9 | AB12: =SUMIFS(PREMC2CA30,AREA,$A12,YEAR,AB$2,Metal,AB$3) -> 146047.44 | AC12: =SUMIFS(PREMC2CA30,AREA,$A12,YEAR,AC$2,Metal,AC$3) -> 13006.46 | AD12: =SUMIFS(PREMC2CA30,AREA,$A12,YEAR,AD$2,Metal,AD$3) -> 10140.58 | AE12: =Z12/U12 -> 863.12 | AF12: =AA12/V12 -> 1231.1462 | AG12: =AB12/W12 -> 1537.3415 | AH12: =AC12/X12 -> 1625.8075 | AI12: =AD12/Y12 -> 1690.0967 | AK12: =AE12/P12-1 -> 0.38471411 | AL12: =AF12/Q12-1 -> 0.54525859 | AM12: =AG12/R12-1 -> 0.60252772 | AN12: =AH12/S12-1 -> 0.40697748 | AO12: =AI12/T12-1 -> #DIV/0! | AP12: =AJ12/U12-1 -> -1
A13: GA10 | B13: =CONCATENATE(C13,E13) -> GA10 | C13: GA | D13: Rating Area 10 | E13: 10 | F13: =COUNTIFS(Metal,F$3,YEAR,F$2,AREA,$A13) -> 4 | G13: =COUNTIFS(Metal,G$3,YEAR,G$2,AREA,$A13) -> 14 | H13: =COUNTIFS(Metal,H$3,YEAR,H$2,AREA,$A13) -> 48 | I13: =COUNTIFS(Metal,I$3,YEAR,I$2,AREA,$A13) -> 9 | J13: =COUNTIFS(Metal,J$3,YEAR,J$2,AREA,$A13) -> 2 | K13: =SUMIFS(PREMC2CA30,AREA,$A13,YEAR,K$2,Metal,K$3) -> 1955.74 | L13: =SUMIFS(PREMC2CA30,AREA,$A13,YEAR,L$2,Metal,L$3) -> 9473.42 | M13: =SUMIFS(PREMC2CA30,AREA,$A13,YEAR,M$2,Metal,M$3) -> 40176.32 | N13: =SUMIFS(PREMC2CA30,AREA,$A13,YEAR,N$2,Metal,N$3) -> 8835.76 | O13: =SUMIFS(PREMC2CA30,AREA,$A13,YEAR,O$2,Metal,O$3) -> 1692.96 | P13: =K13/F13 -> 488.935 | Q13: =L13/G13 -> 676.67286 | R13: =M13/H13 -> 837.00667 | S13: =N13/I13 -> 981.75111 | T13: =O13/J13 -> 846.48 | U13: =COUNTIFS(Metal,U$3,YEAR,U$2,AREA,$A13) -> 1 | V13: =COUNTIFS(Metal,V$3,YEAR,V$2,AREA,$A13) -> 29 | W13: =COUNTIFS(Metal,W$3,YEAR,W$2,AREA,$A13) -> 132 | X13: =COUNTIFS(Metal,X$3,YEAR,X$2,AREA,$A13) -> 25 | Y13: =COUNTIFS(Metal,Y$3,YEAR,Y$2,AREA,$A13) -> 24 | Z13: =SUMIFS(PREMC2CA30,AREA,$A13,YEAR,Z$2,Metal,Z$3) -> 925.96 | AA13: =SUMIFS(PREMC2CA30,AREA,$A13,YEAR,AA$2,Metal,AA$3) -> 42099.78 | AB13: =SUMIFS(PREMC2CA30,AREA,$A13,YEAR,AB$2,Metal,AB$3) -> 256192.32 | AC13: =SUMIFS(PREMC2CA30,AREA,$A13,YEAR,AC$2,Metal,AC$3) -> 46495.44 | AD13: =SUMIFS(PREMC2CA30,AREA,$A13,YEAR,AD$2,Metal,AD$3) -> 49443.6 | AE13: =Z13/U13 -> 925.96 | AF13: =AA13/V13 -> 1451.7166 | AG13: =AB13/W13 -> 1940.8509 | AH13: =AC13/X13 -> 1859.8176 | AI13: =AD13/Y13 -> 2060.15 | AK13: =AE13/P13-1 -> 0.89383047 | AL13: =AF13/Q13-1 -> 1.1453743 | AM13: =AG13/R13-1 -> 1.3187998 | AN13: =AH13/S13-1 -> 0.89438808 | AO13: =AI13/T13-1 -> 1.4337846 | AP13: =AJ13/U13-1 -> -1
A14: GA11 | B14: =CONCATENATE(C14,E14) -> GA11 | C14: GA | D14: Rating Area 11 | E14: 11 | F14: =COUNTIFS(Metal,F$3,YEAR,F$2,AREA,$A14) -> 2 | G14: =COUNTIFS(Metal,G$3,YEAR,G$2,AREA,$A14) -> 7 | H14: =COUNTIFS(Metal,H$3,YEAR,H$2,AREA,$A14) -> 24 | I14: =COUNTIFS(Metal,I$3,YEAR,I$2,AREA,$A14) -> 4 | J14: =COUNTIFS(Metal,J$3,YEAR,J$2,AREA,$A14) -> 1 | K14: =SUMIFS(PREMC2CA30,AREA,$A14,YEAR,K$2,Metal,K$3) -> 1169.38 | L14: =SUMIFS(PREMC2CA30,AREA,$A14,YEAR,L$2,Metal,L$3) -> 6038.6 | M14: =SUMIFS(PREMC2CA30,AREA,$A14,YEAR,M$2,Metal,M$3) -> 24871.52 | N14: =SUMIFS(PREMC2CA30,AREA,$A14,YEAR,N$2,Metal,N$3) -> 4972.12 | O14: =SUMIFS(PREMC2CA30,AREA,$A14,YEAR,O$2,Metal,O$3) -> 854.64 | P14: =K14/F14 -> 584.69 | Q14: =L14/G14 -> 862.65714 | R14: =M14/H14 -> 1036.3133 | S14: =N14/I14 -> 1243.03 | T14: =O14/J14 -> 854.64 | U14: =COUNTIFS(Metal,U$3,YEAR,U$2,AREA,$A14) -> 1 | V14: =COUNTIFS(Metal,V$3,YEAR,V$2,AREA,$A14) -> 7 | W14: =COUNTIFS(Metal,W$3,YEAR,W$2,AREA,$A14) -> 52 | X14: =COUNTIFS(Metal,X$3,YEAR,X$2,AREA,$A14) -> 2 | Y14: =COUNTIFS(Metal,Y$3,YEAR,Y$2,AREA,$A14) -> 0 | Z14: =SUMIFS(PREMC2CA30,AREA,$A14,YEAR,Z$2,Metal,Z$3) -> 970.18 | AA14: =SUMIFS(PREMC2CA30,AREA,$A14,YEAR,AA$2,Metal,AA$3) -> 9257.62 | AB14: =SUMIFS(PREMC2CA30,AREA,$A14,YEAR,AB$2,Metal,AB$3) -> 64429.76 | AC14: =SUMIFS(PREMC2CA30,AREA,$A14,YEAR,AC$2,Metal,AC$3) -> 4163.24 | AD14: =SUMIFS(PREMC2CA30,AREA,$A14,YEAR,AD$2,Metal,AD$3) -> 0 | AE14: =Z14/U14 -> 970.18 | AF14: =AA14/V14 -> 1322.5171 | AG14: =AB14/W14 -> 1239.0338 | AH14: =AC14/X14 -> 2081.62 | AI14: =AD14/Y14 -> #DIV/0! | AK14: =AE14/P14-1 -> 0.65930664 | AL14: =AF14/Q14-1 -> 0.53307389 | AM14: =AG14/R14-1 -> 0.19561701 | AN14: =AH14/S14-1 -> 0.67463376 | AO14: =AI14/T14-1 -> #DIV/0! | AP14: =AJ14/U14-1 -> -1
A15: GA12 | B15: =CONCATENATE(C15,E15) -> GA12 | C15: GA | D15: Rating Area 12 | E15: 12 | F15: =COUNTIFS(Metal,F$3,YEAR,F$2,AREA,$A15) -> 2 | G15: =COUNTIFS(Metal,G$3,YEAR,G$2,AREA,$A15) -> 7 | H15: =COUNTIFS(Metal,H$3,YEAR,H$2,AREA,$A15) -> 24 | I15: =COUNTIFS(Metal,I$3,YEAR,I$2,AREA,$A15) -> 4 | J15: =COUNTIFS(Metal,J$3,YEAR,J$2,AREA,$A15) -> 1 | K15: =SUMIFS(PREMC2CA30,AREA,$A15,YEAR,K$2,Metal,K$3) -> 1160.64 | L15: =SUMIFS(PREMC2CA30,AREA,$A15,YEAR,L$2,Metal,L$3) -> 5240.82 | M15: =SUMIFS(PREMC2CA30,AREA,$A15,YEAR,M$2,Metal,M$3) -> 21730 | N15: =SUMIFS(PREMC2CA30,AREA,$A15,YEAR,N$2,Metal,N$3) -> 4441.98 | O15: =SUMIFS(PREMC2CA30,AREA,$A15,YEAR,O$2,Metal,O$3) -> 1072.16 | P15: =K15/F15 -> 580.32 | Q15: =L15/G15 -> 748.68857 | R15: =M15/H15 -> 905.41667 | S15: =N15/I15 -> 1110.495 | T15: =O15/J15 -> 1072.16 | U15: =COUNTIFS(Metal,U$3,YEAR,U$2,AREA,$A15) -> 1 | V15: =COUNTIFS(Metal,V$3,YEAR,V$2,AREA,$A15) -> 7 | W15: =COUNTIFS(Metal,W$3,YEAR,W$2,AREA,$A15) -> 52 | X15: =COUNTIFS(Metal,X$3,YEAR,X$2,AREA,$A15) -> 2 | Y15: =COUNTIFS(Metal,Y$3,YEAR,Y$2,AREA,$A15) -> 0 | Z15: =SUMIFS(PREMC2CA30,AREA,$A15,YEAR,Z$2,Metal,Z$3) -> 852.54 | AA15: =SUMIFS(PREMC2CA30,AREA,$A15,YEAR,AA$2,Metal,AA$3) -> 8724.12 | AB15: =SUMIFS(PREMC2CA30,AREA,$A15,YEAR,AB$2,Metal,AB$3) -> 72267.36 | AC15: =SUMIFS(PREMC2CA30,AREA,$A15,YEAR,AC$2,Metal,AC$3) -> 4020.42 | AD15: =SUMIFS(PREMC2CA30,AREA,$A15,YEAR,AD$2,Metal,AD$3) -> 0 | AE15: =Z15/U15 -> 852.54 | AF15: =AA15/V15 -> 1246.3029 | AG15: =AB15/W15 -> 1389.7569 | AH15: =AC15/X15 -> 2010.21 | AI15: =AD15/Y15 -> #DIV/0! | AK15: =AE15/P15-1 -> 0.46908602 | AL15: =AF15/Q15-1 -> 0.6646479 | AM15: =AG15/R15-1 -> 0.53493632 | AN15: =AH15/S15-1 -> 0.81019275 | AO15: =AI15/T15-1 -> #DIV/0! | AP15: =AJ15/U15-1 -> -1
... A19: GA16 | B19: =CONCATENATE(C19,E19) -> GA16 | C19: GA | D19: Rating Area 16 | E19: 16 | F19: =COUNTIFS(Metal,F$3,YEAR,F$2,AREA,$A19) -> 2 | G19: =COUNTIFS(Metal,G$3,YEAR,G$2,AREA,$A19) -> 7 | H19: =COUNTIFS(Metal,H$3,YEAR,H$2,AREA,$A19) -> 24 | I19: =COUNTIFS(Metal,I$3,YEAR,I$2,AREA,$A19) -> 4 | J19: =COUNTIFS(Metal,J$3,YEAR,J$2,AREA,$A19) -> 1 | K19: =SUMIFS(PREMC2CA30,AREA,$A19,YEAR,K$2,Metal,K$3) -> 1073.08 | L19: =SUMIFS(PREMC2CA30,AREA,$A19,YEAR,L$2,Metal,L$3) -> 5165.48 | M19: =SUMIFS(PREMC2CA30,AREA,$A19,YEAR,M$2,Metal,M$3) -> 21347.76 | N19: =SUMIFS(PREMC2CA30,AREA,$A19,YEAR,N$2,Metal,N$3) -> 4316.44 | O19: =SUMIFS(PREMC2CA30,AREA,$A19,YEAR,O$2,Metal,O$3) -> 896.04 | P19: =K19/F19 -> 536.54 | Q19: =L19/G19 -> 737.92571 | R19: =M19/H19 -> 889.49 | S19: =N19/I19 -> 1079.11 | T19: =O19/J19 -> 896.04 | U19: =COUNTIFS(Metal,U$3,YEAR,U$2,AREA,$A19) -> 1 | V19: =COUNTIFS(Metal,V$3,YEAR,V$2,AREA,$A19) -> 5 | W19: =COUNTIFS(Metal,W$3,YEAR,W$2,AREA,$A19) -> 8 | X19: =COUNTIFS(Metal,X$3,YEAR,X$2,AREA,$A19) -> 1 | Y19: =COUNTIFS(Metal,Y$3,YEAR,Y$2,AREA,$A19) -> 0 | Z19: =SUMIFS(PREMC2CA30,AREA,$A19,YEAR,Z$2,Metal,Z$3) -> 813.12 | AA19: =SUMIFS(PREMC2CA30,AREA,$A19,YEAR,AA$2,Metal,AA$3) -> 6275.8 | AB19: =SUMIFS(PREMC2CA30,AREA,$A19,YEAR,AB$2,Metal,AB$3) -> 14605.68 | AC19: =SUMIFS(PREMC2CA30,AREA,$A19,YEAR,AC$2,Metal,AC$3) -> 2578.04 | AD19: =SUMIFS(PREMC2CA30,AREA,$A19,YEAR,AD$2,Metal,AD$3) -> 0 | AE19: =Z19/U19 -> 813.12 | AF19: =AA19/V19 -> 1255.16 | AG19: =AB19/W19 -> 1825.71 | AH19: =AC19/X19 -> 2578.04 | AI19: =AD19/Y19 -> #DIV/0! | AK19: =AE19/P19-1 -> 0.51548813 | AL19: =AF19/Q19-1 -> 0.70093002 | AM19: =AG19/R19-1 -> 1.0525357 | AN19: =AH19/S19-1 -> 1.3890428 | AO19: =AI19/T19-1 -> #DIV/0! | AP19: =AJ19/U19-1 -> -1
D20: Total | F20: =COUNTIFS(Metal,F3,YEAR,F2) -> 38 | G20: =COUNTIFS(Metal,G3,YEAR,G2) -> 175 | H20: =COUNTIFS(Metal,H3,YEAR,H2) -> 656 | I20: =COUNTIFS(Metal,I3,YEAR,I2) -> 108 | J20: =COUNTIFS(Metal,J3,YEAR,J2) -> 16 | K20: =SUMIFS(PREMC2CA30,YEAR,K$2,Metal,K$3) -> 21280.98 | L20: =SUMIFS(PREMC2CA30,YEAR,L$2,Metal,L$3) -> 134335.36 | M20: =SUMIFS(PREMC2CA30,YEAR,M$2,Metal,M$3) -> 604138.88 | N20: =SUMIFS(PREMC2CA30,YEAR,N$2,Metal,N$3) -> 119657.5 | O20: =SUMIFS(PREMC2CA30,YEAR,O$2,Metal,O$3) -> 14361.76 | P20: =K20/F20 -> 560.02579 | Q20: =L20/G20 -> 767.63063 | R20: =M20/H20 -> 920.94341 | S20: =N20/I20 -> 1107.9398 | T20: =O20/J20 -> 897.61 | U20: =COUNTIFS(Metal,U3,YEAR,U2) -> 19 | V20: =COUNTIFS(Metal,V3,YEAR,V2) -> 149 | W20: =COUNTIFS(Metal,W3,YEAR,W2) -> 951 | X20: =COUNTIFS(Metal,X3,YEAR,X2) -> 77 | Y20: =COUNTIFS(Metal,Y3,YEAR,Y2) -> 42 | Z20: =SUMIFS(PREMC2CA30,YEAR,Z$2,Metal,Z$3) -> 17634.66 | AA20: =SUMIFS(PREMC2CA30,YEAR,AA$2,Metal,AA$3) -> 195370.36 | AB20: =SUMIFS(PREMC2CA30,YEAR,AB$2,Metal,AB$3) -> 1463511.6 | AC20: =SUMIFS(PREMC2CA30,YEAR,AC$2,Metal,AC$3) -> 145210.06 | AD20: =SUMIFS(PREMC2CA30,YEAR,AD$2,Metal,AD$3) -> 83473.58 | AE20: =Z20/U20 -> 928.14 | AF20: =AA20/V20 -> 1311.2105 | AG20: =AB20/W20 -> 1538.9186 | AH20: =AC20/X20 -> 1885.8449 | AI20: =AD20/Y20 -> 1987.4662 | AK20: =AE20/P20-1 -> 0.65731653 | AL20: =AF20/Q20-1 -> 0.70812683 | AM20: =AG20/R20-1 -> 0.67102402 | AN20: =AH20/S20-1 -> 0.70211857 | AO20: =AI20/T20-1 -> 1.2141756 | AP20: =AJ20/U20-1 -> -1
D21: Check Math | F21: =SUM(F4:F19) -> 38 | G21: =SUM(G4:G19) -> 175 | H21: =SUM(H4:H19) -> 656 | I21: =SUM(I4:I19) -> 108 | J21: =SUM(J4:J19) -> 16 | K21: =SUM(K4:K19) -> 21280.98 | L21: =SUM(L4:L19) -> 134335.36 | M21: =SUM(M4:M19) -> 604138.88 | ... O21: =SUM(O4:O19) -> 14361.76 | P21: =K21/F21 -> 560.02579 | Q21: =L21/G21 -> 767.63063 | R21: =M21/H21 -> 920.94341 | S21: =N21/I21 -> 1107.9398 | T21: =O21/J21 -> 897.61 | U21: =SUM(U4:U19) -> 19 | V21: =SUM(V4:V19) -> 149 | W21: =SUM(W4:W19) -> 951 | X21: =SUM(X4:X19) -> 77 | Y21: =SUM(Y4:Y19) -> 42 | Z21: =SUM(Z4:Z19) -> 17634.66 | AA21: =SUM(AA4:AA19) -> 195370.36 | AB21: =SUM(AB4:AB19) -> 1463511.6 | ... AD21: =SUM(AD4:AD19) -> 83473.58 | AE21: =Z21/U21 -> 928.14 | AF21: =AA21/V21 -> 1311.2105 | AG21: =AB21/W21 -> 1538.9186 | AH21: =AC21/X21 -> 1885.8449 | AI21: =AD21/Y21 -> 1987.4662 | AK21: =AE21/P21-1 -> 0.65731653 | AL21: =AF21/Q21-1 -> 0.70812683 | AM21: =AG21/R21-1 -> 0.67102402 | AN21: =AH21/S21-1 -> 0.70211857 | AO21: =AI21/T21-1 -> 1.2141756 | AP21: =AJ21/U21-1 -> -1
D24: Ambetter
D25: Anthem
D26: Kaiser Permanente
D27: Alliant Health Plans
D28: Humana

Sheet InsurersAnalysis
AH2: 2014 | AI2: 2014 | AJ2: 2014 | AK2: 2014 | AL2: 2014 | AM2: count | AN2: 2019 | AO2: 2019 | AP2: 2019 | AQ2: 2019 | AR2: 2019 | AT2: 2014 | AU2: 2014 | AV2: 2014 | AW2: 2014 | AX2: 2014 | AY2: count | AZ2: 2019 | BA2: 2019 | BB2: 2019 | BC2: 2019 | BD2: 2019 | BF2: 2014 | BG2: 2014 | BH2: 2014 | BI2: 2014 | BJ2: 2014 | BK2: count | BL2: 2019 | BM2: 2019 | BN2: 2019 | BO2: 2019 | BP2: 2019 | BR2: 2014 | BS2: 2014 | BT2: 2014 | BU2: 2014 | BV2: 2014 | BW2: count | BX2: 2019 | BY2: 2019 | BZ2: 2019 | CA2: 2019 | CB2: 2019 | CD2: 2014 | CE2: 2014 | CF2: 2014 | CG2: 2014 | CH2: 2014 | CI2: count | CJ2: 2019 | CK2: 2019 | CL2: 2019 | CM2: 2019 | CN2: 2019
I3: 2014 | O3: 2019 | V3: 2014 | W3: 2014 | X3: 2014 | Y3: 2014 | Z3: 2014 | AA3: count | AB3: 2019 | AC3: 2019 | AD3: 2019 | AE3: 2019 | AF3: 2019 | AH3: Catastrophic | AI3: Catastrophic | AJ3: Catastrophic | AK3: Catastrophic | AL3: Catastrophic | AM3: Catastrophic | AN3: Catastrophic | AO3: Catastrophic | AP3: Catastrophic | AQ3: Catastrophic | AR3: Catastrophic | AT3: Bronze | AU3: Bronze | AV3: Bronze | AW3: Bronze | AX3: Bronze | AY3: Bronze | AZ3: Bronze | BA3: Bronze | BB3: Bronze | BC3: Bronze | BD3: Bronze | BF3: Silver | BG3: Silver | BH3: Silver | BI3: Silver | BJ3: Silver | BK3: Silver | BL3: Silver | BM3: Silver | BN3: Silver | BO3: Silver | BP3: Silver | BR3: Gold | BS3: Gold | BT3: Gold | BU3: Gold | BV3: Gold | BW3: Gold | BX3: Gold | BY3: Gold | BZ3: Gold | CA3: Gold | CB3: Gold | CD3: Platinum | CE3: Platinum | CF3: Platinum | CG3: Platinum | CH3: Platinum | CI3: Platinum | CJ3: Platinum | CK3: Platinum | CL3: Platinum | CM3: Platinum | CN3: Platinum
B4: AREA | C4: Code | D4: State | F4: Rating Area # | G4: # counties | I4: Catastrophic | J4: Bronze | K4: Silver | L4: Gold | M4: Platinum | N4: Any | O4: Catastrophic | P4: Bronze | Q4: Silver | R4: Gold | S4: Platinum | T4: Any | V4: Ambetter | W4: Anthem | X4: Kaiser Permanente | Y4: Alliant Health Plans | Z4: Humana | AA4: overall | AB4: Ambetter | AC4: Anthem | AD4: Kaiser Permanente | AE4: Alliant Health Plans | AF4: Humana | AH4: Ambetter | AI4: Anthem | AJ4: Kaiser Permanente | AK4: Alliant Health Plans | AL4: Humana | AM4: overall | AN4: Ambetter | AO4: Anthem | AP4: Kaiser Permanente | AQ4: Alliant Health Plans | AR4: Humana | AT4: Ambetter | AU4: Anthem | AV4: Kaiser Permanente | AW4: Alliant Health Plans | AX4: Humana | AY4: overall | AZ4: Ambetter | BA4: Anthem | BB4: Kaiser Permanente | BC4: Alliant Health Plans | BD4: Humana | BF4: Ambetter | BG4: Anthem | BH4: Kaiser Permanente | BI4: Alliant Health Plans | BJ4: Humana | BK4: overall | BL4: Ambetter | BM4: Anthem | BN4: Kaiser Permanente | BO4: Alliant Health Plans | BP4: Humana | BR4: Ambetter | BS4: Anthem | BT4: Kaiser Permanente | BU4: Alliant Health Plans | BV4: Humana | BW4: overall | BX4: Ambetter | BY4: Anthem | BZ4: Kaiser Permanente | CA4: Alliant Health Plans | CB4: Humana | CD4: Ambetter | CE4: Anthem | CF4: Kaiser Permanente | CG4: Alliant Health Plans | CH4: Humana | CI4: overall | CJ4: Ambetter | CK4: Anthem | CL4: Kaiser Permanente | CM4: Alliant Health Plans | CN4: Humana
