Workbook

Sheet Medicaid CHIP Income Stand 2021
A1: State Medicaid, CHIP and BHP Income Eligibility Standards
A2: (For selected MAGI Groups, based on state decisions as of October 1, 2020)
A3: State | B3: Children Medicaid Ages 0-11 | C3: Children Medicaid Ages 1-51 | D3: Children Medicaid Ages 6-181 | E3: Children Separate CHIP2 | F3: Pregnant Women Medicaid | G3: Pregnant Women CHIP3 | H3: Adults (Medicaid) Parent/ Caretaker4 | I3: Adults (Medicaid) Expansion to Adults
A4: Alabama | B4: 1.41 | C4: 1.41 | D4: 1.41 | E4: 3.12 | F4: 1.41 | G4: N/A | H4: 0.13 | I4: No
A5: Alaska5 | B5: 2.03 | C5: 2.03 | D5: 2.03 | E5: N/A | F5: 2 | G5: N/A | H5: 132%($) | I5: 1.33
A6: Arizona | B6: 1.47 | C6: 1.41 | D6: 1.33 | E6: 2 | F6: 1.56 | G6: N/A | H6: 1.06 | I6: 1.33
A7: Arkansas | B7: 1.42 | C7: 1.42 | D7: 1.42 | E7: 2.11 | F7: 2.09 | G7: N/A | H7: 15%($) | I7: 1.33
A8: California | B8: 2.61 | C8: 2.61 | D8: 2.61 | E8: See note6 | F8: 2.08 | G8: N/A | H8: 1.09 | I8: 1.33
A9: Colorado | B9: 1.42 | C9: 1.42 | D9: 1.42 | E9: 2.6 | F9: 1.95 | G9: 2.6 | H9: 0.68 | I9: 1.33
A10: Connecticut | B10: 1.96 | C10: 1.96 | D10: 1.96 | E10: 3.18 | F10: 2.58 | G10: N/A | H10: 1.55 | I10: 1.33
A11: Delaware | B11: 2.12 | C11: 1.42 | D11: 1.33 | E11: 212% (1 up to 19) | F11: 2.12 | G11: N/A | H11: 0.87 | I11: 1.33
A12: District of Columbia | B12: 3.19 | C12: 3.19 | D12: 3.19 | E12: N/A | F12: 3.19 | G12: N/A | H12: 2.16 | I12: 210%7
A13: Florida | B13: 2.06 | C13: 1.4 | D13: 1.33 | E13: 210% (1 up to 19) | F13: 1.91 | G13: N/A | H13: 27%($) | I13: No8
A14: Georgia | B14: 2.05 | C14: 1.49 | D14: 1.33 | E14: 2.47 | F14: 2.2 | G14: N/A | H14: 32%($) | I14: No
A15: Hawaii5 | B15: 3.08 | C15: 3.08 | D15: 3.08 | E15: N/A | F15: 1.91 | G15: N/A | H15: 1.05 | I15: 1.33
A16: Idaho | B16: 1.42 | C16: 1.42 | D16: 1.33 | E16: 1.85 | F16: 1.33 | G16: N/A | H16: 22%($) | I16: 1.33
A17: Illinois | B17: 1.42 | C17: 1.42 | D17: 1.42 | E17: 3.13 | F17: 2.08 | G17: N/A | H17: 1.33 | I17: 1.33
A18: Indiana | B18: 2.08 | C18: 1.58 | D18: 1.58 | E18: 2.5 | F18: 2.08 | G18: N/A | H18: 17%($) | I18: 1.33
A19: Iowa | B19: 3.75 | C19: 1.67 | D19: 1.67 | E19: 302% (1 up to 19) | F19: 3.75 | G19: N/A | H19: 50%($) | I19: 1.33
A20: Kansas | B20: % | C20: 1.49 | D20: 1.33 | E20: 2.27 | F20: 1.66 | G20: N/A | H20: 0.33 | I20: No
A21: Kentucky | B21: 1.95 | C21: 1.59 | D21: 1.59 | E21: 2.13 | F21: 1.95 | G21: N/A | H21: 22%($) | I21: 1.33
A22: Louisiana | B22: 2.12 | C22: 2.12 | D22: 2.12 | E22: 2.5 | F22: 1.33 | G22: N/A | H22: 0.19 | I22: 1.33
A23: Maine | B23: 1.91 | C23: 1.57 | D23: 1.57 | E23: 2.08 | F23: 2.09 | G23: N/A | H23: 1 | I23: 133%7
A24: Maryland | B24: 3.17 | C24: 3.17 | D24: 3.17 | E24: N/A | F24: 2.59 | G24: N/A | H24: 1.23 | I24: 1.33
A25: Massachusetts | B25: 2 | C25: 1.5 | D25: 1.5 | E25: 3 | F25: 2 | G25: N/A | H25: 1.33 | I25: 133%7
A26: Michigan | B26: 2.12 | C26: 2.12 | D26: 2.12 | E26: N/A | F26: 1.95 | G26: N/A | H26: 0.54 | I26: 1.33
A27: Minnesota | B27: 283%10 | C27: 2.75 | D27: 2.75 | E27: N/A | F27: 2.78 | G27: N/A | H27: 1.33 | I27: 200%11
A28: Mississippi | B28: 1.94 | C28: 1.43 | D28: 1.33 | E28: 2.09 | F28: 1.94 | G28: N/A | H28: 21%($) | I28: No
A29: Missouri | B29: 1.96 | C29: 1.5 | D29: 1.5 | E29: 3 | F29: 1.96 | G29: 3 | H29: 17%9($) | I29: No9
A30: Montana | B30: 1.43 | C30: 1.43 | D30: 1.43 | E30: 2.61 | F30: 1.57 | G30: N/A | H30: 0.24 | I30: 1.33
A31: Nebraska | B31: 2.13 | C31: 2.13 | D31: 2.13 | E31: N/A | F31: 1.94 | G31: N/A | H31: 0.58 | I31: 1.33
A32: Nevada | B32: 1.6 | C32: 1.6 | D32: 1.33 | E32: 2 | F32: 1.6 | G32: N/A | H32: 31%($) | I32: 1.33
A33: New Hampshire | B33: 3.18 | C33: 3.18 | D33: 3.18 | E33: N/A | F33: 1.96 | G33: N/A | H33: 63%($) | I33: 1.33
A34: New Jersey | B34: 1.94 | C34: 1.42 | D34: 1.42 | E34: 3.5 | F34: 1.94 | G34: 2 | H34: 29%($) | I34: 1.33
A35: New Mexico | B35: 3 | C35: 3 | D35: 2.4 | E35: N/A | F35: 2.5 | G35: N/A | H35: 42%($) | I35: 1.33
A36: New York | B36: 2.18 | C36: 1.49 | D36: 1.49 | E36: 4 | F36: 2.18 | G36: N/A | H36: 1.33 | I36: 200%11
A37: North Carolina | B37: 2.1 | C37: 2.1 | D37: 1.33 | E37: 211% (6 up to 19) | F37: 1.96 | G37: N/A | H37: 41%($) | I37: No8
A38: North Dakota | B38: 1.7 | C38: 1.7 | D38: 1.7 | E38: NA% | F38: 1.57 | G38: N/A | H38: 49%($) | I38: 1.33
A39: Ohio | B39: 2.06 | C39: 2.06 | D39: 2.06 | E39: N/A | F39: 2 | G39: N/A | H39: 0.9 | I39: 1.33
A40: Oklahoma | B40: 2.05 | C40: 2.05 | D40: 2.05 | E40: N/A | F40: 1.33 | G40: N/A | H40: 38%9($) | I40: No9
...

Sheet Medicaid CHIP Income Stand 2022
A1: State Medicaid, CHIP and BHP Income Eligibility Standards
A2: (For selected MAGI Groups, based on state decisions as of July 1, 2021)
A3: State | B3: Children Medicaid Ages 0-1 | C3: Children Medicaid Ages 1-5 | D3: Children Medicaid Ages 6-18 | E3: Children Separate CHIP | F3: Pregnant Women Medicaid | G3: Pregnant Women CHIP | H3: Adults (Medicaid) Parent/ Caretaker Source | I3: Adults (Medicaid) Parent/ Caretaker Derived | J3: Adults (Medicaid) Expansion to Adults | K3: Adults (Medicaid) Parent/ Caretaker converted from Dollar?
A4: Alabama | B4: 1.41 | C4: 1.41 | D4: 1.41 | E4: 3.12 | F4: 1.41 | G4: N/A | H4: 0.13 | I4: 0.13 | J4: No | K4: =IF(LEFT(RIGHT(H4,2),1)="$","Yes","No") -> No
A5: Alaska | B5: 2.03 | C5: 2.03 | D5: 2.03 | E5: N/A | F5: 2 | G5: N/A | H5: 131%($) | I5: 1.31 | J5: 1.33 | K5: =IF(LEFT(RIGHT(H5,2),1)="$","Yes","No") -> Yes
A6: Arizona | B6: 1.47 | C6: 1.41 | D6: 1.33 | E6: 2 | F6: 1.56 | G6: N/A | H6: 1.06 | I6: 1.06 | J6: 1.33 | K6: =IF(LEFT(RIGHT(H6,2),1)="$","Yes","No") -> No
A7: Arkansas | B7: 1.42 | C7: 1.42 | D7: 1.42 | E7: 2.11 | F7: 2.09 | G7: N/A | H7: 15%($) | I7: 0.15 | J7: 1.33 | K7: =IF(LEFT(RIGHT(H7,2),1)="$","Yes","No") -> Yes
A8: California | B8: 2.61 | C8: 2.61 | D8: 2.61 | E8: 3.17 | F8: 2.08 | G8: N/A | H8: 1.09 | I8: 1.09 | J8: 1.33 | K8: =IF(LEFT(RIGHT(H8,2),1)="$","Yes","No") -> No
A9: Colorado | B9: 1.42 | C9: 1.42 | D9: 1.42 | E9: 2.6 | F9: 1.95 | G9: 2.6 | H9: 0.68 | I9: 0.68 | J9: 1.33 | K9: =IF(LEFT(RIGHT(H9,2),1)="$","Yes","No") -> No
A10: Connecticut | B10: 1.96 | C10: 1.96 | D10: 1.96 | E10: 3.18 | F10: 2.58 | G10: N/A | H10: 1.55 | I10: 1.55 | J10: 1.33 | K10: =IF(LEFT(RIGHT(H10,2),1)="$","Yes","No") -> No
A11: Delaware | B11: 2.12 | C11: 1.42 | D11: 1.33 | E11: 2.12 | F11: 2.12 | G11: N/A | H11: 0.87 | I11: 0.87 | J11: 1.33 | K11: =IF(LEFT(RIGHT(H11,2),1)="$","Yes","No") -> No
A12: District of Columbia | B12: 3.19 | C12: 3.19 | D12: 3.19 | E12: N/A | F12: 3.19 | G12: N/A | H12: 2.16 | I12: 2.16 | J12: 2.1 | K12: =IF(LEFT(RIGHT(H12,2),1)="$","Yes","No") -> No
A13: Florida | B13: 2.06 | C13: 1.4 | D13: 1.33 | E13: 2.1 | F13: 1.91 | G13: N/A | H13: 27%($) | I13: 0.27 | J13: No | K13: =IF(LEFT(RIGHT(H13,2),1)="$","Yes","No") -> Yes
A14: Georgia | B14: 2.05 | C14: 1.49 | D14: 1.33 | E14: 2.47 | F14: 2.2 | G14: N/A | H14: 31%($) | I14: 0.31 | J14: No | K14: =IF(LEFT(RIGHT(H14,2),1)="$","Yes","No") -> Yes
A15: Hawaii | B15: 3.08 | C15: 3.08 | D15: 3.08 | E15: N/A | F15: 1.91 | G15: N/A | H15: 1.05 | I15: 1.05 | J15: 1.33 | K15: =IF(LEFT(RIGHT(H15,2),1)="$","Yes","No") -> No
A16: Idaho | B16: 1.42 | C16: 1.42 | D16: 1.33 | E16: 1.85 | F16: 1.33 | G16: N/A | H16: 22%($) | I16: 0.22 | J16: 1.33 | K16: =IF(LEFT(RIGHT(H16,2),1)="$","Yes","No") -> Yes
A17: Illinois | B17: 1.42 | C17: 1.42 | D17: 1.42 | E17: 3.13 | F17: 2.08 | G17: N/A | H17: 1.33 | I17: 1.33 | J17: 1.33 | K17: =IF(LEFT(RIGHT(H17,2),1)="$","Yes","No") -> No
A18: Indiana | B18: 2.08 | C18: 1.58 | D18: 1.58 | E18: 2.5 | F18: 2.08 | G18: N/A | H18: 17%($) | I18: 0.17 | J18: 1.33 | K18: =IF(LEFT(RIGHT(H18,2),1)="$","Yes","No") -> Yes
A19: Iowa | B19: 3.75 | C19: 1.67 | D19: 1.67 | E19: 3.02 | F19: 3.75 | G19: N/A | H19: 49%($) | I19: 0.49 | J19: 1.33 | K19: =IF(LEFT(RIGHT(H19,2),1)="$","Yes","No") -> Yes
A20: Kansas | B20: 1.66 | C20: 1.49 | D20: 1.33 | E20: 2.25 | F20: 1.66 | G20: N/A | H20: 0.33 | I20: 0.33 | J20: No | K20: =IF(LEFT(RIGHT(H20,2),1)="$","Yes","No") -> No
A21: Kentucky | B21: 1.95 | C21: 1.59 | D21: 1.59 | E21: 2.13 | F21: 1.95 | G21: N/A | H21: 22%($) | I21: 0.22 | J21: 1.33 | K21: =IF(LEFT(RIGHT(H21,2),1)="$","Yes","No") -> Yes
A22: Louisiana | B22: 2.12 | C22: 2.12 | D22: 2.12 | E22: 2.5 | F22: 1.33 | G22: N/A | H22: 0.19 | I22: 0.19 | J22: 1.33 | K22: =IF(LEFT(RIGHT(H22,2),1)="$","Yes","No") -> No
A23: Maine | B23: 1.91 | C23: 1.57 | D23: 1.57 | E23: 2.08 | F23: 2.09 | G23: N/A | H23: 1 | I23: 1 | J23: 1.33 | K23: =IF(LEFT(RIGHT(H23,2),1)="$","Yes","No") -> No
A24: Maryland | B24: 3.17 | C24: 3.17 | D24: 3.17 | E24: N/A | F24: 2.59 | G24: N/A | H24: 1.23 | I24: 1.23 | J24: 1.33 | K24: =IF(LEFT(RIGHT(H24,2),1)="$","Yes","No") -> No
A25: Massachusetts | B25: 2 | C25: 1.5 | D25: 1.5 | E25: 3 | F25: 2 | G25: N/A | H25: 1.33 | I25: 1.33 | J25: 1.33 | K25: =IF(LEFT(RIGHT(H25,2),1)="$","Yes","No") -> No
A26: Michigan | B26: 2.12 | C26: 2.12 | D26: 2.12 | E26: N/A | F26: 1.95 | G26: N/A | H26: 0.54 | I26: 0.54 | J26: 1.33 | K26: =IF(LEFT(RIGHT(H26,2),1)="$","Yes","No") -> No
A27: Minnesota | B27: 2.83 | C27: 2.75 | D27: 2.75 | E27: N/A | F27: 2.78 | G27: N/A | H27: 1.33 | I27: 1.33 | J27: 2 | K27: =IF(LEFT(RIGHT(H27,2),1)="$","Yes","No") -> No
A28: Mississippi | B28: 1.94 | C28: 1.43 | D28: 1.33 | E28: 2.09 | F28: 1.94 | G28: N/A | H28: 21%($) | I28: 0.21 | J28: No | K28: =IF(LEFT(RIGHT(H28,2),1)="$","Yes","No") -> Yes
A29: Missouri | B29: 1.96 | C29: 1.5 | D29: 1.5 | E29: 3 | F29: 1.96 | G29: 3 | H29: 17%9($) | I29: 0.17 | J29: 1.33 | K29: =IF(LEFT(RIGHT(H29,2),1)="$","Yes","No") -> Yes
A30: Montana | B30: 1.43 | C30: 1.43 | D30: 1.43 | E30: 2.61 | F30: 1.57 | G30: N/A | H30: 0.24 | I30: 0.24 | J30: 1.33 | K30: =IF(LEFT(RIGHT(H30,2),1)="$","Yes","No") -> No
A31: Nebraska | B31: 2.13 | C31: 2.13 | D31: 2.13 | E31: N/A | F31: 1.94 | G31: N/A | H31: 0.58 | I31: 0.58 | J31: 1.33 | K31: =IF(LEFT(RIGHT(H31,2),1)="$","Yes","No") -> No
A32: Nevada | B32: 1.6 | C32: 1.6 | D32: 1.33 | E32: 2 | F32: 1.6 | G32: N/A | H32: 30%($) | I32: 0.3 | J32: 1.33 | K32: =IF(LEFT(RIGHT(H32,2),1)="$","Yes","No") -> Yes
A33: New Hampshire | B33: 3.18 | C33: 3.18 | D33: 3.18 | E33: N/A | F33: 1.96 | G33: N/A | H33: 62%($) | I33: 0.62 | J33: 1.33 | K33: =IF(LEFT(RIGHT(H33,2),1)="$","Yes","No") -> Yes
A34: New Jersey | B34: 1.94 | C34: 1.42 | D34: 1.42 | E34: 3.5 | F34: 1.94 | G34: 2 | H34: 29%($) | I34: 0.29 | J34: 1.33 | K34: =IF(LEFT(RIGHT(H34,2),1)="$","Yes","No") -> Yes
A35: New Mexico | B35: 3 | C35: 3 | D35: 2.4 | E35: N/A | F35: 2.5 | G35: N/A | H35: 42%($) | I35: 0.42 | J35: 1.33 | K35: =IF(LEFT(RIGHT(H35,2),1)="$","Yes","No") -> Yes
A36: New York | B36: 2.18 | C36: 1.49 | D36: 1.49 | E36: 4 | F36: 2.18 | G36: N/A | H36: 1.33 | I36: 1.33 | J36: 2 | K36: =IF(LEFT(RIGHT(H36,2),1)="$","Yes","No") -> No
A37: North Carolina | B37: 2.1 | C37: 2.1 | D37: 1.33 | E37: 2.11 | F37: 1.96 | G37: N/A | H37: 40%($) | I37: 0.4 | J37: No | K37: =IF(LEFT(RIGHT(H37,2),1)="$","Yes","No") -> Yes
A38: North Dakota | B38: 1.7 | C38: 1.7 | D38: 1.7 | E38: N/A | F38: 1.57 | G38: N/A | H38: 48%($) | I38: 0.48 | J38: 1.33 | K38: =IF(LEFT(RIGHT(H38,2),1)="$","Yes","No") -> Yes
A39: Ohio | B39: 2.06 | C39: 2.06 | D39: 2.06 | E39: N/A | F39: 2 | G39: N/A | H39: 0.9 | I39: 0.9 | J39: 1.33 | K39: =IF(LEFT(RIGHT(H39,2),1)="$","Yes","No") -> No
A40: Oklahoma | B40: 2.05 | C40: 2.05 | D40: 2.05 | E40: N/A | F40: 1.33 | G40: N/A | H40: 38%($) | I40: 0.38 | J40: 1.33 | K40: =IF(LEFT(RIGHT(H40,2),1)="$","Yes","No") -> Yes
...

Sheet Medicaid CHIP Income Stand 2023
A1: State Medicaid, CHIP and BHP Income Eligibility Standards
A2: (For selected MAGI Groups, based on state decisions as of July 1, 2022)
A3: State | B3: Year | C3: Children Medicaid Ages 0-1 | D3: Children Medicaid Ages 1-5 | E3: Children Medicaid Ages 6-18 | F3: Children Separate CHIP | G3: Pregnant Women Medicaid | H3: Pregnant Women CHIP | I3: Adults (Medicaid) Parent/ Caretaker | J3: Adults (Medicaid) Expansion to Adults
A4: Alabama | B4: 2023 | C4: 1.41 | D4: 1.41 | E4: 1.41 | F4: 3.12 | G4: 1.41 | H4: N/A | I4: 0.13 | J4: No
A5: Alaska | B5: 2023 | C5: 2.03 | D5: 2.03 | E5: 2.03 | F5: N/A | G5: 2 | H5: N/A | I5: 1.31 | J5: 1.33
A6: Arizona | B6: 2023 | C6: 1.47 | D6: 1.41 | E6: 1.33 | F6: 2 | G6: 1.56 | H6: N/A | I6: 1.06 | J6: 1.33
A7: Arkansas | B7: 2023 | C7: 1.42 | D7: 1.42 | E7: 1.42 | F7: 2.11 | G7: 2.09 | H7: N/A | I7: 0.14 | J7: 1.33
A8: California | B8: 2023 | C8: 2.61 | D8: 2.61 | E8: 2.61 | G8: 2.08 | H8: N/A | I8: 1.09 | J8: 1.33
A9: Colorado | B9: 2023 | C9: 1.42 | D9: 1.42 | E9: 1.42 | F9: 2.6 | G9: 1.95 | H9: 2.6 | I9: 0.68 | J9: 1.33
A10: Connecticut | B10: 2023 | C10: 1.96 | D10: 1.96 | E10: 1.96 | F10: 3.18 | G10: 2.58 | H10: N/A | I10: 1.55 | J10: 1.33
A11: Delaware | B11: 2023 | C11: 2.12 | D11: 1.42 | E11: 1.33 | F11: 2.12 | G11: 2.12 | H11: N/A | I11: 0.87 | J11: 1.33
A12: District of Columbia | B12: 2023 | C12: 3.19 | D12: 3.19 | E12: 3.19 | F12: N/A | G12: 3.19 | H12: N/A | I12: 2.16 | J12: 2.1
A13: Florida | B13: 2023 | C13: 2.06 | D13: 1.4 | E13: 1.33 | F13: 2.1 | G13: 1.91 | H13: N/A | I13: 0.26 | J13: No
A14: Georgia | B14: 2023 | C14: 2.05 | D14: 1.49 | E14: 1.33 | F14: 2.47 | G14: 2.2 | H14: N/A | I14: 0.3 | J14: No
A15: Hawaii | B15: 2023 | C15: 3.08 | D15: 3.08 | E15: 3.08 | F15: N/A | G15: 1.91 | H15: N/A | I15: 1.05 | J15: 1.33
A16: Idaho | B16: 2023 | C16: 1.42 | D16: 1.42 | E16: 1.33 | F16: 1.85 | G16: 1.33 | H16: N/A | I16: 0.22 | J16: 1.33
A17: Illinois | B17: 2023 | C17: 3.13 | D17: 3.13 | E17: 3.13 | F17: N/A | G17: 2.08 | H17: N/A | I17: 1.33 | J17: 1.33
A18: Indiana | B18: 2023 | C18: 2.08 | D18: 1.58 | E18: 1.58 | F18: 2.5 | G18: 2.08 | H18: N/A | I18: 0.16 | J18: 1.33
A19: Iowa | B19: 2023 | C19: 3.75 | D19: 1.67 | E19: 1.67 | F19: 3.02 | G19: 3.75 | H19: N/A | I19: 0.47 | J19: 1.33
A20: Kansas | B20: 2023 | C20: 1.66 | D20: 1.49 | E20: 1.33 | F20: 2.5 | G20: 1.66 | H20: N/A | I20: 0.33 | J20: No
A21: Kentucky | B21: 2023 | C21: 1.95 | D21: 1.59 | E21: 1.59 | F21: 2.13 | G21: 1.95 | H21: 2.13 | I21: 0.21 | J21: 1.33
A22: Louisiana | B22: 2023 | C22: 2.12 | D22: 2.12 | E22: 2.12 | F22: 2.5 | G22: 1.33 | H22: N/A | I22: 0.19 | J22: 1.33
A23: Maine | B23: 2023 | C23: 1.91 | D23: 1.57 | E23: 1.57 | F23: 2.08 | G23: 2.09 | H23: N/A | I23: 1 | J23: 1.33
A24: Maryland | B24: 2023 | C24: 3.17 | D24: 3.17 | E24: 3.17 | F24: N/A | G24: 2.59 | H24: N/A | I24: 1.23 | J24: 1.33
A25: Massachusetts | B25: 2023 | C25: 2 | D25: 1.5 | E25: 1.5 | F25: 3 | G25: 2 | H25: N/A | I25: 1.33 | J25: 1.33
A26: Michigan | B26: 2023 | C26: 2.12 | D26: 2.12 | E26: 2.12 | F26: N/A | G26: 1.95 | H26: N/A | I26: 0.54 | J26: 1.33
A27: Minnesota | B27: 2023 | C27: 2.83 | D27: 2.75 | E27: 2.75 | F27: N/A | G27: 2.78 | H27: N/A | I27: 1.33 | J27: 2
A28: Mississippi | B28: 2023 | C28: 1.94 | D28: 1.43 | E28: 1.33 | F28: 2.09 | G28: 1.94 | H28: N/A | I28: 0.2 | J28: No
A29: Missouri | B29: 2023 | C29: 1.96 | D29: 1.5 | E29: 1.5 | F29: 3 | G29: 1.96 | H29: 3 | I29: 16%9 | J29: 1.33
A30: Montana | B30: 2023 | C30: 1.43 | D30: 1.43 | E30: 1.43 | F30: 2.61 | G30: 1.57 | H30: N/A | I30: 0.24 | J30: 1.33
A31: Nebraska | B31: 2023 | C31: 2.13 | D31: 2.13 | E31: 2.13 | F31: N/A | G31: 1.94 | H31: N/A | I31: 0.58 | J31: 1.33
A32: Nevada | B32: 2023 | C32: 1.6 | D32: 1.6 | E32: 1.33 | F32: 2 | G32: 1.6 | H32: N/A | I32: 0.28 | J32: 1.33
A33: New Hampshire | B33: 2023 | C33: 3.18 | D33: 3.18 | E33: 3.18 | F33: N/A | G33: 1.96 | H33: N/A | I33: 0.59 | J33: 1.33
A34: New Jersey | B34: 2023 | C34: 1.94 | D34: 1.42 | E34: 1.42 | F34: 3.5 | G34: 1.94 | H34: 2 | I34: 0.28 | J34: 1.33
A35: New Mexico | B35: 2023 | C35: 3 | D35: 3 | E35: 2.4 | F35: N/A | G35: 2.5 | H35: N/A | I35: 0.4 | J35: 1.33
A36: New York | B36: 2023 | C36: 2.18 | D36: 1.49 | E36: 1.49 | F36: 4 | G36: 2.18 | H36: N/A | I36: 1.33 | J36: 2
A37: North Carolina | B37: 2023 | C37: 2.11 | D37: 2.11 | E37: 2.11 | F37: N/A | G37: 1.96 | H37: N/A | I37: 0.38 | J37: No
A38: North Dakota | B38: 2023 | C38: 1.7 | D38: 1.7 | E38: 1.7 | F38: N/A | G38: 1.57 | H38: N/A | I38: 0.46 | J38: 1.33
A39: Ohio | B39: 2023 | C39: 2.06 | D39: 2.06 | E39: 2.06 | F39: N/A | G39: 2 | H39: N/A | I39: 0.9 | J39: 1.33
A40: Oklahoma | B40: 2023 | C40: 2.05 | D40: 2.05 | E40: 2.05 | F40: N/A | G40: 1.33 | H40: N/A | I40: 0.36 | J40: 1.33
...

Sheet Medicaid CHIP Income Stand 2024
A1: State Medicaid, CHIP and BHP Income Eligibility Standards
A2: (For selected MAGI Groups, based on state decisions as of December 1, 2023)
A3: State | B3: Children Medicaid Ages 0-1 | C3: Children Medicaid Ages 1-5 | D3: Children Medicaid Ages 6-18 | E3: Children Separate CHIP | F3: Pregnant Women Medicaid | G3: Pregnant Women CHIP | H3: Adults (Medicaid) Parent/ Caretaker | I3: Adults (Medicaid) Expansion to Adults
A4: Alabama | B4: 1.41 | C4: 1.41 | D4: 1.41 | E4: 3.12 | F4: 1.41 | G4: N/A | H4: 0.13 | I4: No
A5: Alaska | B5: 2.03 | C5: 2.03 | D5: 2.03 | E5: N/A | F5: 2 | G5: N/A | H5: 1.3 | I5: 1.33
A6: Arizona | B6: 1.47 | C6: 1.41 | D6: 1.33 | E6: 2 | F6: 1.56 | G6: N/A | H6: 1.06 | I6: 1.33
A7: Arkansas | B7: 1.42 | C7: 1.42 | D7: 1.42 | E7: 2.11 | F7: 2.09 | G7: N/A | H7: 0.13 | I7: 1.33
A8: California | B8: 2.61 | C8: 2.61 | D8: 2.61 | E8: 3.17 | F8: 2.08 | G8: N/A | H8: 1.09 | I8: 1.33
A9: Colorado | B9: 1.42 | C9: 1.42 | D9: 1.42 | E9: 2.6 | F9: 1.95 | G9: 2.6 | H9: 0.68 | I9: 1.33
A10: Connecticut | B10: 1.96 | C10: 1.96 | D10: 1.96 | E10: 3.18 | F10: 2.58 | G10: N/A | H10: 1.55 | I10: 1.33
A11: Delaware | B11: 2.12 | C11: 1.42 | D11: 1.33 | E11: 2.12 | F11: 2.12 | G11: N/A | H11: 0.87 | I11: 1.33
A12: District of Columbia | B12: 3.19 | C12: 3.19 | D12: 3.19 | E12: N/A | F12: 3.19 | G12: N/A | H12: 2.16 | I12: 2.1
A13: Florida | B13: 2.06 | C13: 1.4 | D13: 1.33 | E13: 2.1 | F13: 1.91 | G13: N/A | H13: 0.24 | I13: 0.24
A14: Georgia | B14: 2.05 | C14: 1.49 | D14: 1.33 | E14: 2.47 | F14: 2.2 | G14: N/A | H14: 0.28 | I14: No
A15: Hawaii | B15: 3.08 | C15: 3.08 | D15: 3.08 | E15: N/A | F15: 1.91 | G15: N/A | H15: 1.05 | I15: 1.33
A16: Idaho | B16: 1.42 | C16: 1.42 | D16: 1.33 | E16: 1.85 | F16: 1.33 | G16: N/A | H16: 0.19 | I16: 1.33
A17: Illinois | B17: 3.13 | C17: 3.13 | D17: 3.13 | E17: N/A | F17: 2.08 | G17: N/A | H17: 1.33 | I17: 1.33
A18: Indiana | B18: 2.08 | C18: 1.58 | D18: 1.58 | E18: 2.5 | F18: 2.08 | G18: N/A | H18: 0.15 | I18: 1.33
A19: Iowa | B19: 3.75 | C19: 1.67 | D19: 1.67 | E19: 3.02 | F19: 3.75 | G19: N/A | H19: 0.44 | I19: 1.33
A20: Kansas | B20: 1.66 | C20: 1.49 | D20: 1.33 | E20: 2.5 | F20: 1.66 | G20: N/A | H20: 0.33 | I20: No
A21: Kentucky | B21: 2.13 | C21: 2.13 | D21: 2.13 | E21: N/A | F21: 1.95 | G21: 2.13 | H21: 0.19 | I21: 1.33
A22: Louisiana | B22: 2.12 | C22: 2.12 | D22: 2.12 | E22: 2.5 | F22: 1.33 | G22: N/A | H22: 0.19 | I22: 1.33
A23: Maine | B23: 3 | C23: 3 | D23: 3 | E23: N/A | F23: 2.09 | G23: N/A | H23: 1 | I23: 1.33
A24: Maryland | B24: 3.17 | C24: 3.17 | D24: 3.17 | E24: N/A | F24: 2.59 | G24: N/A | H24: 1.23 | I24: 1.33
A25: Massachusetts | B25: 2 | C25: 1.5 | D25: 1.5 | E25: 3 | F25: 2 | G25: N/A | H25: 1.33 | I25: 1.33
A26: Michigan | B26: 2.12 | C26: 2.12 | D26: 2.12 | E26: N/A | F26: 1.95 | G26: N/A | H26: 0.54 | I26: 1.33
A27: Minnesota | B27: 2.83 | C27: 2.75 | D27: 2.75 | E27: N/A | F27: 2.78 | G27: N/A | H27: 1.33 | I27: 2
A28: Mississippi | B28: 1.94 | C28: 1.43 | D28: 1.33 | E28: 2.09 | F28: 1.94 | G28: N/A | H28: 0.19 | I28: No
A29: Missouri | B29: 1.96 | C29: 1.5 | D29: 1.5 | E29: 3 | F29: 1.96 | G29: 3 | H29: 0.15 | I29: 1.33
A30: Montana | B30: 1.43 | C30: 1.43 | D30: 1.43 | E30: 2.61 | F30: 1.57 | G30: N/A | H30: 0.24 | I30: 1.33
A31: Nebraska | B31: 2.13 | C31: 2.13 | D31: 2.13 | E31: N/A | F31: 1.94 | G31: N/A | H31: 0.58 | I31: 1.33
A32: Nevada | B32: 1.6 | C32: 1.6 | D32: 1.33 | E32: 2 | F32: 1.6 | G32: N/A | H32: 0.26 | I32: 1.33
A33: New Hampshire | B33: 3.18 | C33: 3.18 | D33: 3.18 | E33: N/A | F33: 1.96 | G33: N/A | H33: 0.55 | I33: 1.33
A34: New Jersey | B34: 1.94 | C34: 1.42 | D34: 1.42 | E34: 3.5 | F34: 1.94 | G34: 2 | H34: 0.26 | I34: 1.33
A35: New Mexico | B35: 3 | C35: 3 | D35: 2.4 | E35: N/A | F35: 2.5 | G35: N/A | H35: 0.37 | I35: 1.33
A36: New York | B36: 2.18 | C36: 1.49 | D36: 1.49 | E36: 4 | F36: 2.18 | G36: N/A | H36: 1.33 | I36: 2
A37: North Carolina | B37: 2.11 | C37: 2.11 | D37: 2.11 | E37: N/A | F37: 1.96 | G37: N/A | H37: 0.36 | I37: 1.33
A38: North Dakota | B38: 1.7 | C38: 1.7 | D38: 1.7 | E38: N/A | F38: 1.7 | G38: N/A | H38: 0.43 | I38: 1.33
A39: Ohio | B39: 2.06 | C39: 2.06 | D39: 2.06 | E39: N/A | F39: 2 | G39: N/A | H39: 0.9 | I39: 1.33
A40: Oklahoma | B40: 2.05 | C40: 2.05 | D40: 2.05 | E40: N/A | F40: 2.05 | G40: N/A | H40: 0.33 | I40: 1.33
...

Sheet Medicaid Chip Stand Sort 2023
B1: ='Medicaid CHIP Income Stand 2022'!$A4 -> Alabama | C1: ='Medicaid CHIP Income Stand 2022'!$A5 -> Alaska | D1: ='Medicaid CHIP Income Stand 2022'!$A6 -> Arizona | E1: ='Medicaid CHIP Income Stand 2022'!$A7 -> Arkansas | F1: ='Medicaid CHIP Income Stand 2022'!$A8 -> California | G1: ='Medicaid CHIP Income Stand 2022'!$A9 -> Colorado | H1: ='Medicaid CHIP Income Stand 2022'!$A10 -> Connecticut | I1: ='Medicaid CHIP Income Stand 2022'!$A11 -> Delaware | J1: ='Medicaid CHIP Income Stand 2022'!$A12 -> District of Columbia | K1: ='Medicaid CHIP Income Stand 2022'!$A13 -> Florida | L1: ='Medicaid CHIP Income Stand 2022'!$A14 -> Georgia | M1: ='Medicaid CHIP Income Stand 2022'!$A15 -> Hawaii | N1: ='Medicaid CHIP Income Stand 2022'!$A16 -> Idaho | O1: ='Medicaid CHIP Income Stand 2022'!$A17 -> Illinois | P1: ='Medicaid CHIP Income Stand 2022'!$A18 -> Indiana | Q1: ='Medicaid CHIP Income Stand 2022'!$A19 -> Iowa | R1: ='Medicaid CHIP Income Stand 2022'!$A20 -> Kansas | S1: ='Medicaid CHIP Income Stand 2022'!$A21 -> Kentucky | T1: ='Medicaid CHIP Income Stand 2022'!$A22 -> Louisiana | U1: ='Medicaid CHIP Income Stand 2022'!$A23 -> Maine | V1: ='Medicaid CHIP Income Stand 2022'!$A24 -> Maryland | W1: ='Medicaid CHIP Income Stand 2022'!$A25 -> Massachusetts | X1: ='Medicaid CHIP Income Stand 2022'!$A26 -> Michigan | Y1: ='Medicaid CHIP Income Stand 2022'!$A27 -> Minnesota | Z1: ='Medicaid CHIP Income Stand 2022'!$A28 -> Mississippi | AA1: ='Medicaid CHIP Income Stand 2022'!$A29 -> Missouri | AB1: ='Medicaid CHIP Income Stand 2022'!$A30 -> Montana | AC1: ='Medicaid CHIP Income Stand 2022'!$A31 -> Nebraska | AD1: ='Medicaid CHIP Income Stand 2022'!$A32 -> Nevada | AE1: ='Medicaid CHIP Income Stand 2022'!$A33 -> New Hampshire | AF1: ='Medicaid CHIP Income Stand 2022'!$A34 -> New Jersey | AG1: ='Medicaid CHIP Income Stand 2022'!$A35 -> New Mexico | AH1: ='Medicaid CHIP Income Stand 2022'!$A36 -> New York | AI1: ='Medicaid CHIP Income Stand 2022'!$A37 -> North Carolina | AJ1: ='Medicaid CHIP Income Stand 2022'!$A38 -> North Dakota | AK1: ='Medicaid CHIP Income Stand 2022'!$A39 -> Ohio | AL1: ='Medicaid CHIP Income Stand 2022'!$A40 -> Oklahoma | AM1: ='Medicaid CHIP Income Stand 2022'!$A41 -> Oregon | AN1: ='Medicaid CHIP Income Stand 2022'!$A42 -> Pennsylvania | AO1: ='Medicaid CHIP Income Stand 2022'!$A43 -> Rhode Island | AP1: ='Medicaid CHIP Income Stand 2022'!$A44 -> South Carolina | AQ1: ='Medicaid CHIP Income Stand 2022'!$A45 -> South Dakota | AR1: ='Medicaid CHIP Income Stand 2022'!$A46 -> Tennessee | AS1: ='Medicaid CHIP Income Stand 2022'!$A47 -> Texas | AT1: ='Medicaid CHIP Income Stand 2022'!$A48 -> Utah | AU1: ='Medicaid CHIP Income Stand 2022'!$A49 -> Vermont | AV1: ='Medicaid CHIP Income Stand 2022'!$A50 -> Virginia | AW1: ='Medicaid CHIP Income Stand 2022'!$A51 -> Washington | AX1: ='Medicaid CHIP Income Stand 2022'!$A52 -> West Virginia | AY1: ='Medicaid CHIP Income Stand 2022'!$A53 -> Wisconsin | AZ1: ='Medicaid CHIP Income Stand 2022'!$A54 -> Wyoming
A2: ='Medicaid CHIP Income Stand 2022'!B3 -> Children Medicaid Ages 0-1 | B2: =INDEX('Medicaid CHIP Income Stand 2022'!$B$4:$B$54,MATCH(B$1,'Medicaid CHIP Income Stand 2022'!$A$4:$A$54,0)) -> 1.41 | C2: =INDEX('Medicaid CHIP Income Stand 2022'!$B$4:$B$54,MATCH(C$1,'Medicaid CHIP Income Stand 2022'!$A$4:$A$54,0)) -> 2.03 | D2: =INDEX('Medicaid CHIP Income Stand 2022'!$B$4:$B$54,MATCH(D$1,'Medicaid CHIP Income Stand 2022'!$A$4:$A$54,0)) -> 1.47 | E2: =INDEX('Medicaid CHIP Income Stand 2022'!$B$4:$B$54,MATCH(E$1,'Medicaid CHIP Income Stand 2022'!$A$4:$A$54,0)) -> 1.42 | F2: =INDEX('Medicaid CHIP Income Stand 2022'!$B$4:$B$54,MATCH(F$1,'Medicaid CHIP Income Stand 2022'!$A$4:$A$54,0)) -> 2.61 | G2: =INDEX('Medicaid CHIP Income Stand 2022'!$B$4:$B$54,MATCH(G$1,'Medicaid CHIP Income Stand 2022'!$A$4:$A$54,0)) -> 1.42 | H2: =INDEX('Medicaid CHIP Income Stand 2022'!$B$4:$B$54,MATCH(H$1,'Medicaid CHIP Income Stand 2022'!$A$4:$A$54,0)) -> 1.96 | I2: =INDEX('Medicaid CHIP Income Stand 2022'!$B$4:$B$54,MATCH(I$1,'Medicaid CHIP Income Stand 2022'!$A$4:$A$54,0)) -> 2.12 | ... AZ2: =INDEX('Medicaid CHIP Income Stand 2022'!$B$4:$B$54,MATCH(AZ$1,'Medicaid CHIP Income Stand 2022'!$A$4:$A$54,0)) -> 2
A3: ='Medicaid CHIP Income Stand 2022'!C3 -> Children Medicaid Ages 1-5 | B3: =INDEX('Medicaid CHIP Income Stand 2022'!$C$4:$C$54,MATCH(B$1,'Medicaid CHIP Income Stand 2022'!$A$4:$A$54,0)) -> 1.41 | C3: =INDEX('Medicaid CHIP Income Stand 2022'!$C$4:$C$54,MATCH(C$1,'Medicaid CHIP Income Stand 2022'!$A$4:$A$54,0)) -> 2.03 | D3: =INDEX('Medicaid CHIP Income Stand 2022'!$C$4:$C$54,MATCH(D$1,'Medicaid CHIP Income Stand 2022'!$A$4:$A$54,0)) -> 1.41 | E3: =INDEX('Medicaid CHIP Income Stand 2022'!$C$4:$C$54,MATCH(E$1,'Medicaid CHIP Income Stand 2022'!$A$4:$A$54,0)) -> 1.42 | F3: =INDEX('Medicaid CHIP Income Stand 2022'!$C$4:$C$54,MATCH(F$1,'Medicaid CHIP Income Stand 2022'!$A$4:$A$54,0)) -> 2.61 | G3: =INDEX('Medicaid CHIP Income Stand 2022'!$C$4:$C$54,MATCH(G$1,'Medicaid CHIP Income Stand 2022'!$A$4:$A$54,0)) -> 1.42 | H3: =INDEX('Medicaid CHIP Income Stand 2022'!$C$4:$C$54,MATCH(H$1,'Medicaid CHIP Income Stand 2022'!$A$4:$A$54,0)) -> 1.96 | I3: =INDEX('Medicaid CHIP Income Stand 2022'!$C$4:$C$54,MATCH(I$1,'Medicaid CHIP Income Stand 2022'!$A$4:$A$54,0)) -> 1.42 | ... AZ3: =INDEX('Medicaid CHIP Income Stand 2022'!$C$4:$C$54,MATCH(AZ$1,'Medicaid CHIP Income Stand 2022'!$A$4:$A$54,0)) -> 2
A4: Children Medicaid Ages 2-5 | B4: =INDEX('Medicaid CHIP Income Stand 2022'!$C$4:$C$54,MATCH(B$1,'Medicaid CHIP Income Stand 2022'!$A$4:$A$54,0)) -> 1.41 | C4: =INDEX('Medicaid CHIP Income Stand 2022'!$C$4:$C$54,MATCH(C$1,'Medicaid CHIP Income Stand 2022'!$A$4:$A$54,0)) -> 2.03 | D4: =INDEX('Medicaid CHIP Income Stand 2022'!$C$4:$C$54,MATCH(D$1,'Medicaid CHIP Income Stand 2022'!$A$4:$A$54,0)) -> 1.41 | E4: =INDEX('Medicaid CHIP Income Stand 2022'!$C$4:$C$54,MATCH(E$1,'Medicaid CHIP Income Stand 2022'!$A$4:$A$54,0)) -> 1.42 | F4: =INDEX('Medicaid CHIP Income Stand 2022'!$C$4:$C$54,MATCH(F$1,'Medicaid CHIP Income Stand 2022'!$A$4:$A$54,0)) -> 2.61 | G4: =INDEX('Medicaid CHIP Income Stand 2022'!$C$4:$C$54,MATCH(G$1,'Medicaid CHIP Income Stand 2022'!$A$4:$A$54,0)) -> 1.42 | H4: =INDEX('Medicaid CHIP Income Stand 2022'!$C$4:$C$54,MATCH(H$1,'Medicaid CHIP Income Stand 2022'!$A$4:$A$54,0)) -> 1.96 | I4: =INDEX('Medicaid CHIP Income Stand 2022'!$C$4:$C$54,MATCH(I$1,'Medicaid CHIP Income Stand 2022'!$A$4:$A$54,0)) -> 1.42 | ... AZ4: =INDEX('Medicaid CHIP Income Stand 2022'!$C$4:$C$54,MATCH(AZ$1,'Medicaid CHIP Income Stand 2022'!$A$4:$A$54,0)) -> 2
A5: ='Medicaid CHIP Income Stand 2022'!D3 -> Children Medicaid Ages 6-18 | B5: =INDEX('Medicaid CHIP Income Stand 2022'!$D$4:$D$54,MATCH(B$1,'Medicaid CHIP Income Stand 2022'!$A$4:$A$54,0)) -> 1.41 | C5: =INDEX('Medicaid CHIP Income Stand 2022'!$D$4:$D$54,MATCH(C$1,'Medicaid CHIP Income Stand 2022'!$A$4:$A$54,0)) -> 2.03 | D5: =INDEX('Medicaid CHIP Income Stand 2022'!$D$4:$D$54,MATCH(D$1,'Medicaid CHIP Income Stand 2022'!$A$4:$A$54,0)) -> 1.33 | E5: =INDEX('Medicaid CHIP Income Stand 2022'!$D$4:$D$54,MATCH(E$1,'Medicaid CHIP Income Stand 2022'!$A$4:$A$54,0)) -> 1.42 | F5: =INDEX('Medicaid CHIP Income Stand 2022'!$D$4:$D$54,MATCH(F$1,'Medicaid CHIP Income Stand 2022'!$A$4:$A$54,0)) -> 2.61 | G5: =INDEX('Medicaid CHIP Income Stand 2022'!$D$4:$D$54,MATCH(G$1,'Medicaid CHIP Income Stand 2022'!$A$4:$A$54,0)) -> 1.42 | H5: =INDEX('Medicaid CHIP Income Stand 2022'!$D$4:$D$54,MATCH(H$1,'Medicaid CHIP Income Stand 2022'!$A$4:$A$54,0)) -> 1.96 | I5: =INDEX('Medicaid CHIP Income Stand 2022'!$D$4:$D$54,MATCH(I$1,'Medicaid CHIP Income Stand 2022'!$A$4:$A$54,0)) -> 1.33 | ... AZ5: =INDEX('Medicaid CHIP Income Stand 2022'!$D$4:$D$54,MATCH(AZ$1,'Medicaid CHIP Income Stand 2022'!$A$4:$A$54,0)) -> 2
A6: ='Medicaid CHIP Income Stand 2022'!E3 -> Children Separate CHIP | B6: =INDEX('Medicaid CHIP Income Stand 2022'!$E$4:$E$54,MATCH(B$1,'Medicaid CHIP Income Stand 2022'!$A$4:$A$54,0)) -> 3.12 | C6: =INDEX('Medicaid CHIP Income Stand 2022'!$E$4:$E$54,MATCH(C$1,'Medicaid CHIP Income Stand 2022'!$A$4:$A$54,0)) -> N/A | D6: =INDEX('Medicaid CHIP Income Stand 2022'!$E$4:$E$54,MATCH(D$1,'Medicaid CHIP Income Stand 2022'!$A$4:$A$54,0)) -> 2 | E6: =INDEX('Medicaid CHIP Income Stand 2022'!$E$4:$E$54,MATCH(E$1,'Medicaid CHIP Income Stand 2022'!$A$4:$A$54,0)) -> 2.11 | F6: =INDEX('Medicaid CHIP Income Stand 2022'!$E$4:$E$54,MATCH(F$1,'Medicaid CHIP Income Stand 2022'!$A$4:$A$54,0)) -> 3.17 | G6: =INDEX('Medicaid CHIP Income Stand 2022'!$E$4:$E$54,MATCH(G$1,'Medicaid CHIP Income Stand 2022'!$A$4:$A$54,0)) -> 2.6 | H6: =INDEX('Medicaid CHIP Income Stand 2022'!$E$4:$E$54,MATCH(H$1,'Medicaid CHIP Income Stand 2022'!$A$4:$A$54,0)) -> 3.18 | I6: =INDEX('Medicaid CHIP Income Stand 2022'!$E$4:$E$54,MATCH(I$1,'Medicaid CHIP Income Stand 2022'!$A$4:$A$54,0)) -> 2.12 | ... AZ6: =INDEX('Medicaid CHIP Income Stand 2022'!$E$4:$E$54,MATCH(AZ$1,'Medicaid CHIP Income Stand 2022'!$A$4:$A$54,0)) -> N/A
A7: ='Medicaid CHIP Income Stand 2022'!F3 -> Pregnant Women Medicaid | B7: =INDEX('Medicaid CHIP Income Stand 2022'!$F$4:$F$54,MATCH(B$1,'Medicaid CHIP Income Stand 2022'!$A$4:$A$54,0)) -> 1.41 | C7: =INDEX('Medicaid CHIP Income Stand 2022'!$F$4:$F$54,MATCH(C$1,'Medicaid CHIP Income Stand 2022'!$A$4:$A$54,0)) -> 2 | D7: =INDEX('Medicaid CHIP Income Stand 2022'!$F$4:$F$54,MATCH(D$1,'Medicaid CHIP Income Stand 2022'!$A$4:$A$54,0)) -> 1.56 | E7: =INDEX('Medicaid CHIP Income Stand 2022'!$F$4:$F$54,MATCH(E$1,'Medicaid CHIP Income Stand 2022'!$A$4:$A$54,0)) -> 2.09 | F7: =INDEX('Medicaid CHIP Income Stand 2022'!$F$4:$F$54,MATCH(F$1,'Medicaid CHIP Income Stand 2022'!$A$4:$A$54,0)) -> 2.08 | G7: =INDEX('Medicaid CHIP Income Stand 2022'!$F$4:$F$54,MATCH(G$1,'Medicaid CHIP Income Stand 2022'!$A$4:$A$54,0)) -> 1.95 | H7: =INDEX('Medicaid CHIP Income Stand 2022'!$F$4:$F$54,MATCH(H$1,'Medicaid CHIP Income Stand 2022'!$A$4:$A$54,0)) -> 2.58 | I7: =INDEX('Medicaid CHIP Income Stand 2022'!$F$4:$F$54,MATCH(I$1,'Medicaid CHIP Income Stand 2022'!$A$4:$A$54,0)) -> 2.12 | ... AZ7: =INDEX('Medicaid CHIP Income Stand 2022'!$F$4:$F$54,MATCH(AZ$1,'Medicaid CHIP Income Stand 2022'!$A$4:$A$54,0)) -> 1.54
A8: ='Medicaid CHIP Income Stand 2022'!H3 -> Adults (Medicaid) Parent/ Caretaker Source | B8: =INDEX('Medicaid CHIP Income Stand 2022'!$I$4:$I$54,MATCH(B$1,'Medicaid CHIP Income Stand 2022'!$A$4:$A$54,0)) -> 0.13 | C8: =INDEX('Medicaid CHIP Income Stand 2022'!$I$4:$I$54,MATCH(C$1,'Medicaid CHIP Income Stand 2022'!$A$4:$A$54,0)) -> 1.31 | D8: =INDEX('Medicaid CHIP Income Stand 2022'!$I$4:$I$54,MATCH(D$1,'Medicaid CHIP Income Stand 2022'!$A$4:$A$54,0)) -> 1.06 | E8: =INDEX('Medicaid CHIP Income Stand 2022'!$I$4:$I$54,MATCH(E$1,'Medicaid CHIP Income Stand 2022'!$A$4:$A$54,0)) -> 0.15 | F8: =INDEX('Medicaid CHIP Income Stand 2022'!$I$4:$I$54,MATCH(F$1,'Medicaid CHIP Income Stand 2022'!$A$4:$A$54,0)) -> 1.09 | G8: =INDEX('Medicaid CHIP Income Stand 2022'!$I$4:$I$54,MATCH(G$1,'Medicaid CHIP Income Stand 2022'!$A$4:$A$54,0)) -> 0.68 | H8: =INDEX('Medicaid CHIP Income Stand 2022'!$I$4:$I$54,MATCH(H$1,'Medicaid CHIP Income Stand 2022'!$A$4:$A$54,0)) -> 1.55 | I8: =INDEX('Medicaid CHIP Income Stand 2022'!$I$4:$I$54,MATCH(I$1,'Medicaid CHIP Income Stand 2022'!$A$4:$A$54,0)) -> 0.87 | ... AZ8: =INDEX('Medicaid CHIP Income Stand 2022'!$I$4:$I$54,MATCH(AZ$1,'Medicaid CHIP Income Stand 2022'!$A$4:$A$54,0)) -> 0.51
A9: ='Medicaid CHIP Income Stand 2022'!J3 -> Adults (Medicaid) Expansion to Adults | B9: =INDEX('Medicaid CHIP Income Stand 2022'!$J$4:$J$54,MATCH(B$1,'Medicaid CHIP Income Stand 2022'!$A$4:$A$54,0)) -> No | C9: =INDEX('Medicaid CHIP Income Stand 2022'!$J$4:$J$54,MATCH(C$1,'Medicaid CHIP Income Stand 2022'!$A$4:$A$54,0)) -> 1.33 | D9: =INDEX('Medicaid CHIP Income Stand 2022'!$J$4:$J$54,MATCH(D$1,'Medicaid CHIP Income Stand 2022'!$A$4:$A$54,0)) -> 1.33 | E9: =INDEX('Medicaid CHIP Income Stand 2022'!$J$4:$J$54,MATCH(E$1,'Medicaid CHIP Income Stand 2022'!$A$4:$A$54,0)) -> 1.33 | F9: =INDEX('Medicaid CHIP Income Stand 2022'!$J$4:$J$54,MATCH(F$1,'Medicaid CHIP Income Stand 2022'!$A$4:$A$54,0)) -> 1.33 | G9: =INDEX('Medicaid CHIP Income Stand 2022'!$J$4:$J$54,MATCH(G$1,'Medicaid CHIP Income Stand 2022'!$A$4:$A$54,0)) -> 1.33 | H9: =INDEX('Medicaid CHIP Income Stand 2022'!$J$4:$J$54,MATCH(H$1,'Medicaid CHIP Income Stand 2022'!$A$4:$A$54,0)) -> 1.33 | I9: =INDEX('Medicaid CHIP Income Stand 2022'!$J$4:$J$54,MATCH(I$1,'Medicaid CHIP Income Stand 2022'!$A$4:$A$54,0)) -> 1.33 | ... AZ9: =INDEX('Medicaid CHIP Income Stand 2022'!$J$4:$J$54,MATCH(AZ$1,'Medicaid CHIP Income Stand 2022'!$A$4:$A$54,0)) -> No
A10: ='Medicaid CHIP Income Stand 2022'!K3 -> Adults (Medicaid) Parent/ Caretaker converted from Dollar? | B10: =INDEX('Medicaid CHIP Income Stand 2022'!$K$4:$K$54,MATCH(B$1,'Medicaid CHIP Income Stand 2022'!$A$4:$A$54,0)) -> No | C10: =INDEX('Medicaid CHIP Income Stand 2022'!$K$4:$K$54,MATCH(C$1,'Medicaid CHIP Income Stand 2022'!$A$4:$A$54,0)) -> Yes | D10: =INDEX('Medicaid CHIP Income Stand 2022'!$K$4:$K$54,MATCH(D$1,'Medicaid CHIP Income Stand 2022'!$A$4:$A$54,0)) -> No | E10: =INDEX('Medicaid CHIP Income Stand 2022'!$K$4:$K$54,MATCH(E$1,'Medicaid CHIP Income Stand 2022'!$A$4:$A$54,0)) -> Yes | F10: =INDEX('Medicaid CHIP Income Stand 2022'!$K$4:$K$54,MATCH(F$1,'Medicaid CHIP Income Stand 2022'!$A$4:$A$54,0)) -> No | G10: =INDEX('Medicaid CHIP Income Stand 2022'!$K$4:$K$54,MATCH(G$1,'Medicaid CHIP Income Stand 2022'!$A$4:$A$54,0)) -> No | H10: =INDEX('Medicaid CHIP Income Stand 2022'!$K$4:$K$54,MATCH(H$1,'Medicaid CHIP Income Stand 2022'!$A$4:$A$54,0)) -> No | I10: =INDEX('Medicaid CHIP Income Stand 2022'!$K$4:$K$54,MATCH(I$1,'Medicaid CHIP Income Stand 2022'!$A$4:$A$54,0)) -> No | ... AZ10: =INDEX('Medicaid CHIP Income Stand 2022'!$K$4:$K$54,MATCH(AZ$1,'Medicaid CHIP Income Stand 2022'!$A$4:$A$54,0)) -> Yes

Sheet Medicaid Chip Stand Sort 2024
B1: ='Medicaid CHIP Income Stand 2022'!$A4 -> Alabama | C1: ='Medicaid CHIP Income Stand 2022'!$A5 -> Alaska | D1: ='Medicaid CHIP Income Stand 2022'!$A6 -> Arizona | E1: ='Medicaid CHIP Income Stand 2022'!$A7 -> Arkansas | F1: ='Medicaid CHIP Income Stand 2022'!$A8 -> California | G1: ='Medicaid CHIP Income Stand 2022'!$A9 -> Colorado | H1: ='Medicaid CHIP Income Stand 2022'!$A10 -> Connecticut | I1: ='Medicaid CHIP Income Stand 2022'!$A11 -> Delaware | J1: ='Medicaid CHIP Income Stand 2022'!$A12 -> District of Columbia | K1: ='Medicaid CHIP Income Stand 2022'!$A13 -> Florida | L1: ='Medicaid CHIP Income Stand 2022'!$A14 -> Georgia | M1: ='Medicaid CHIP Income Stand 2022'!$A15 -> Hawaii | N1: ='Medicaid CHIP Income Stand 2022'!$A16 -> Idaho | O1: ='Medicaid CHIP Income Stand 2022'!$A17 -> Illinois | P1: ='Medicaid CHIP Income Stand 2022'!$A18 -> Indiana | Q1: ='Medicaid CHIP Income Stand 2022'!$A19 -> Iowa | R1: ='Medicaid CHIP Income Stand 2022'!$A20 -> Kansas | S1: ='Medicaid CHIP Income Stand 2022'!$A21 -> Kentucky | T1: ='Medicaid CHIP Income Stand 2022'!$A22 -> Louisiana | U1: ='Medicaid CHIP Income Stand 2022'!$A23 -> Maine | V1: ='Medicaid CHIP Income Stand 2022'!$A24 -> Maryland | W1: ='Medicaid CHIP Income Stand 2022'!$A25 -> Massachusetts | X1: ='Medicaid CHIP Income Stand 2022'!$A26 -> Michigan | Y1: ='Medicaid CHIP Income Stand 2022'!$A27 -> Minnesota | Z1: ='Medicaid CHIP Income Stand 2022'!$A28 -> Mississippi | AA1: ='Medicaid CHIP Income Stand 2022'!$A29 -> Missouri | AB1: ='Medicaid CHIP Income Stand 2022'!$A30 -> Montana | AC1: ='Medicaid CHIP Income Stand 2022'!$A31 -> Nebraska | AD1: ='Medicaid CHIP Income Stand 2022'!$A32 -> Nevada | AE1: ='Medicaid CHIP Income Stand 2022'!$A33 -> New Hampshire | AF1: ='Medicaid CHIP Income Stand 2022'!$A34 -> New Jersey | AG1: ='Medicaid CHIP Income Stand 2022'!$A35 -> New Mexico | AH1: ='Medicaid CHIP Income Stand 2022'!$A36 -> New York | AI1: ='Medicaid CHIP Income Stand 2022'!$A37 -> North Carolina | AJ1: ='Medicaid CHIP Income Stand 2022'!$A38 -> North Dakota | AK1: ='Medicaid CHIP Income Stand 2022'!$A39 -> Ohio | AL1: ='Medicaid CHIP Income Stand 2022'!$A40 -> Oklahoma | AM1: ='Medicaid CHIP Income Stand 2022'!$A41 -> Oregon | AN1: ='Medicaid CHIP Income Stand 2022'!$A42 -> Pennsylvania | AO1: ='Medicaid CHIP Income Stand 2022'!$A43 -> Rhode Island | AP1: ='Medicaid CHIP Income Stand 2022'!$A44 -> South Carolina | AQ1: ='Medicaid CHIP Income Stand 2022'!$A45 -> South Dakota | AR1: ='Medicaid CHIP Income Stand 2022'!$A46 -> Tennessee | AS1: ='Medicaid CHIP Income Stand 2022'!$A47 -> Texas | AT1: ='Medicaid CHIP Income Stand 2022'!$A48 -> Utah | AU1: ='Medicaid CHIP Income Stand 2022'!$A49 -> Vermont | AV1: ='Medicaid CHIP Income Stand 2022'!$A50 -> Virginia | AW1: ='Medicaid CHIP Income Stand 2022'!$A51 -> Washington | AX1: ='Medicaid CHIP Income Stand 2022'!$A52 -> West Virginia | AY1: ='Medicaid CHIP Income Stand 2022'!$A53 -> Wisconsin | AZ1: ='Medicaid CHIP Income Stand 2022'!$A54 -> Wyoming
A2: ='Medicaid CHIP Income Stand 2022'!B3 -> Children Medicaid Ages 0-1 | B2: =INDEX('Medicaid CHIP Income Stand 2022'!$B$4:$B$54,MATCH(B$1,'Medicaid CHIP Income Stand 2022'!$A$4:$A$54,0)) -> 1.41 | C2: =INDEX('Medicaid CHIP Income Stand 2022'!$B$4:$B$54,MATCH(C$1,'Medicaid CHIP Income Stand 2022'!$A$4:$A$54,0)) -> 2.03 | D2: =INDEX('Medicaid CHIP Income Stand 2022'!$B$4:$B$54,MATCH(D$1,'Medicaid CHIP Income Stand 2022'!$A$4:$A$54,0)) -> 1.47 | E2: =INDEX('Medicaid CHIP Income Stand 2022'!$B$4:$B$54,MATCH(E$1,'Medicaid CHIP Income Stand 2022'!$A$4:$A$54,0)) -> 1.42 | F2: =INDEX('Medicaid CHIP Income Stand 2022'!$B$4:$B$54,MATCH(F$1,'Medicaid CHIP Income Stand 2022'!$A$4:$A$54,0)) -> 2.61 | G2: =INDEX('Medicaid CHIP Income Stand 2022'!$B$4:$B$54,MATCH(G$1,'Medicaid CHIP Income Stand 2022'!$A$4:$A$54,0)) -> 1.42 | H2: =INDEX('Medicaid CHIP Income Stand 2022'!$B$4:$B$54,MATCH(H$1,'Medicaid CHIP Income Stand 2022'!$A$4:$A$54,0)) -> 1.96 | I2: =INDEX('Medicaid CHIP Income Stand 2022'!$B$4:$B$54,MATCH(I$1,'Medicaid CHIP Income Stand 2022'!$A$4:$A$54,0)) -> 2.12 | ... AZ2: =INDEX('Medicaid CHIP Income Stand 2022'!$B$4:$B$54,MATCH(AZ$1,'Medicaid CHIP Income Stand 2022'!$A$4:$A$54,0)) -> 2
A3: ='Medicaid CHIP Income Stand 2022'!C3 -> Children Medicaid Ages 1-5 | B3: =INDEX('Medicaid CHIP Income Stand 2022'!$C$4:$C$54,MATCH(B$1,'Medicaid CHIP Income Stand 2022'!$A$4:$A$54,0)) -> 1.41 | C3: =INDEX('Medicaid CHIP Income Stand 2022'!$C$4:$C$54,MATCH(C$1,'Medicaid CHIP Income Stand 2022'!$A$4:$A$54,0)) -> 2.03 | D3: =INDEX('Medicaid CHIP Income Stand 2022'!$C$4:$C$54,MATCH(D$1,'Medicaid CHIP Income Stand 2022'!$A$4:$A$54,0)) -> 1.41 | E3: =INDEX('Medicaid CHIP Income Stand 2022'!$C$4:$C$54,MATCH(E$1,'Medicaid CHIP Income Stand 2022'!$A$4:$A$54,0)) -> 1.42 | F3: =INDEX('Medicaid CHIP Income Stand 2022'!$C$4:$C$54,MATCH(F$1,'Medicaid CHIP Income Stand 2022'!$A$4:$A$54,0)) -> 2.61 | G3: =INDEX('Medicaid CHIP Income Stand 2022'!$C$4:$C$54,MATCH(G$1,'Medicaid CHIP Income Stand 2022'!$A$4:$A$54,0)) -> 1.42 | H3: =INDEX('Medicaid CHIP Income Stand 2022'!$C$4:$C$54,MATCH(H$1,'Medicaid CHIP Income Stand 2022'!$A$4:$A$54,0)) -> 1.96 | I3: =INDEX('Medicaid CHIP Income Stand 2022'!$C$4:$C$54,MATCH(I$1,'Medicaid CHIP Income Stand 2022'!$A$4:$A$54,0)) -> 1.42 | ... AZ3: =INDEX('Medicaid CHIP Income Stand 2022'!$C$4:$C$54,MATCH(AZ$1,'Medicaid CHIP Income Stand 2022'!$A$4:$A$54,0)) -> 2
A4: Children Medicaid Ages 2-5 | B4: =INDEX('Medicaid CHIP Income Stand 2022'!$C$4:$C$54,MATCH(B$1,'Medicaid CHIP Income Stand 2022'!$A$4:$A$54,0)) -> 1.41 | C4: =INDEX('Medicaid CHIP Income Stand 2022'!$C$4:$C$54,MATCH(C$1,'Medicaid CHIP Income Stand 2022'!$A$4:$A$54,0)) -> 2.03 | D4: =INDEX('Medicaid CHIP Income Stand 2022'!$C$4:$C$54,MATCH(D$1,'Medicaid CHIP Income Stand 2022'!$A$4:$A$54,0)) -> 1.41 | E4: =INDEX('Medicaid CHIP Income Stand 2022'!$C$4:$C$54,MATCH(E$1,'Medicaid CHIP Income Stand 2022'!$A$4:$A$54,0)) -> 1.42 | F4: =INDEX('Medicaid CHIP Income Stand 2022'!$C$4:$C$54,MATCH(F$1,'Medicaid CHIP Income Stand 2022'!$A$4:$A$54,0)) -> 2.61 | G4: =INDEX('Medicaid CHIP Income Stand 2022'!$C$4:$C$54,MATCH(G$1,'Medicaid CHIP Income Stand 2022'!$A$4:$A$54,0)) -> 1.42 | H4: =INDEX('Medicaid CHIP Income Stand 2022'!$C$4:$C$54,MATCH(H$1,'Medicaid CHIP Income Stand 2022'!$A$4:$A$54,0)) -> 1.96 | I4: =INDEX('Medicaid CHIP Income Stand 2022'!$C$4:$C$54,MATCH(I$1,'Medicaid CHIP Income Stand 2022'!$A$4:$A$54,0)) -> 1.42 | ... AZ4: =INDEX('Medicaid CHIP Income Stand 2022'!$C$4:$C$54,MATCH(AZ$1,'Medicaid CHIP Income Stand 2022'!$A$4:$A$54,0)) -> 2
A5: ='Medicaid CHIP Income Stand 2022'!D3 -> Children Medicaid Ages 6-18 | B5: =INDEX('Medicaid CHIP Income Stand 2022'!$D$4:$D$54,MATCH(B$1,'Medicaid CHIP Income Stand 2022'!$A$4:$A$54,0)) -> 1.41 | C5: =INDEX('Medicaid CHIP Income Stand 2022'!$D$4:$D$54,MATCH(C$1,'Medicaid CHIP Income Stand 2022'!$A$4:$A$54,0)) -> 2.03 | D5: =INDEX('Medicaid CHIP Income Stand 2022'!$D$4:$D$54,MATCH(D$1,'Medicaid CHIP Income Stand 2022'!$A$4:$A$54,0)) -> 1.33 | E5: =INDEX('Medicaid CHIP Income Stand 2022'!$D$4:$D$54,MATCH(E$1,'Medicaid CHIP Income Stand 2022'!$A$4:$A$54,0)) -> 1.42 | F5: =INDEX('Medicaid CHIP Income Stand 2022'!$D$4:$D$54,MATCH(F$1,'Medicaid CHIP Income Stand 2022'!$A$4:$A$54,0)) -> 2.61 | G5: =INDEX('Medicaid CHIP Income Stand 2022'!$D$4:$D$54,MATCH(G$1,'Medicaid CHIP Income Stand 2022'!$A$4:$A$54,0)) -> 1.42 | H5: =INDEX('Medicaid CHIP Income Stand 2022'!$D$4:$D$54,MATCH(H$1,'Medicaid CHIP Income Stand 2022'!$A$4:$A$54,0)) -> 1.96 | I5: =INDEX('Medicaid CHIP Income Stand 2022'!$D$4:$D$54,MATCH(I$1,'Medicaid CHIP Income Stand 2022'!$A$4:$A$54,0)) -> 1.33 | ... AZ5: =INDEX('Medicaid CHIP Income Stand 2022'!$D$4:$D$54,MATCH(AZ$1,'Medicaid CHIP Income Stand 2022'!$A$4:$A$54,0)) -> 2
A6: ='Medicaid CHIP Income Stand 2022'!E3 -> Children Separate CHIP | B6: =INDEX('Medicaid CHIP Income Stand 2022'!$E$4:$E$54,MATCH(B$1,'Medicaid CHIP Income Stand 2022'!$A$4:$A$54,0)) -> 3.12 | C6: =INDEX('Medicaid CHIP Income Stand 2022'!$E$4:$E$54,MATCH(C$1,'Medicaid CHIP Income Stand 2022'!$A$4:$A$54,0)) -> N/A | D6: =INDEX('Medicaid CHIP Income Stand 2022'!$E$4:$E$54,MATCH(D$1,'Medicaid CHIP Income Stand 2022'!$A$4:$A$54,0)) -> 2 | E6: =INDEX('Medicaid CHIP Income Stand 2022'!$E$4:$E$54,MATCH(E$1,'Medicaid CHIP Income Stand 2022'!$A$4:$A$54,0)) -> 2.11 | F6: =INDEX('Medicaid CHIP Income Stand 2022'!$E$4:$E$54,MATCH(F$1,'Medicaid CHIP Income Stand 2022'!$A$4:$A$54,0)) -> 3.17 | G6: =INDEX('Medicaid CHIP Income Stand 2022'!$E$4:$E$54,MATCH(G$1,'Medicaid CHIP Income Stand 2022'!$A$4:$A$54,0)) -> 2.6 | H6: =INDEX('Medicaid CHIP Income Stand 2022'!$E$4:$E$54,MATCH(H$1,'Medicaid CHIP Income Stand 2022'!$A$4:$A$54,0)) -> 3.18 | I6: =INDEX('Medicaid CHIP Income Stand 2022'!$E$4:$E$54,MATCH(I$1,'Medicaid CHIP Income Stand 2022'!$A$4:$A$54,0)) -> 2.12 | ... AZ6: =INDEX('Medicaid CHIP Income Stand 2022'!$E$4:$E$54,MATCH(AZ$1,'Medicaid CHIP Income Stand 2022'!$A$4:$A$54,0)) -> N/A
A7: ='Medicaid CHIP Income Stand 2022'!F3 -> Pregnant Women Medicaid | B7: =INDEX('Medicaid CHIP Income Stand 2022'!$F$4:$F$54,MATCH(B$1,'Medicaid CHIP Income Stand 2022'!$A$4:$A$54,0)) -> 1.41 | C7: =INDEX('Medicaid CHIP Income Stand 2022'!$F$4:$F$54,MATCH(C$1,'Medicaid CHIP Income Stand 2022'!$A$4:$A$54,0)) -> 2 | D7: =INDEX('Medicaid CHIP Income Stand 2022'!$F$4:$F$54,MATCH(D$1,'Medicaid CHIP Income Stand 2022'!$A$4:$A$54,0)) -> 1.56 | E7: =INDEX('Medicaid CHIP Income Stand 2022'!$F$4:$F$54,MATCH(E$1,'Medicaid CHIP Income Stand 2022'!$A$4:$A$54,0)) -> 2.09 | F7: =INDEX('Medicaid CHIP Income Stand 2022'!$F$4:$F$54,MATCH(F$1,'Medicaid CHIP Income Stand 2022'!$A$4:$A$54,0)) -> 2.08 | G7: =INDEX('Medicaid CHIP Income Stand 2022'!$F$4:$F$54,MATCH(G$1,'Medicaid CHIP Income Stand 2022'!$A$4:$A$54,0)) -> 1.95 | H7: =INDEX('Medicaid CHIP Income Stand 2022'!$F$4:$F$54,MATCH(H$1,'Medicaid CHIP Income Stand 2022'!$A$4:$A$54,0)) -> 2.58 | I7: =INDEX('Medicaid CHIP Income Stand 2022'!$F$4:$F$54,MATCH(I$1,'Medicaid CHIP Income Stand 2022'!$A$4:$A$54,0)) -> 2.12 | ... AZ7: =INDEX('Medicaid CHIP Income Stand 2022'!$F$4:$F$54,MATCH(AZ$1,'Medicaid CHIP Income Stand 2022'!$A$4:$A$54,0)) -> 1.54
A8: ='Medicaid CHIP Income Stand 2022'!H3 -> Adults (Medicaid) Parent/ Caretaker Source | B8: =INDEX('Medicaid CHIP Income Stand 2022'!$I$4:$I$54,MATCH(B$1,'Medicaid CHIP Income Stand 2022'!$A$4:$A$54,0)) -> 0.13 | C8: =INDEX('Medicaid CHIP Income Stand 2022'!$I$4:$I$54,MATCH(C$1,'Medicaid CHIP Income Stand 2022'!$A$4:$A$54,0)) -> 1.31 | D8: =INDEX('Medicaid CHIP Income Stand 2022'!$I$4:$I$54,MATCH(D$1,'Medicaid CHIP Income Stand 2022'!$A$4:$A$54,0)) -> 1.06 | E8: =INDEX('Medicaid CHIP Income Stand 2022'!$I$4:$I$54,MATCH(E$1,'Medicaid CHIP Income Stand 2022'!$A$4:$A$54,0)) -> 0.15 | F8: =INDEX('Medicaid CHIP Income Stand 2022'!$I$4:$I$54,MATCH(F$1,'Medicaid CHIP Income Stand 2022'!$A$4:$A$54,0)) -> 1.09 | G8: =INDEX('Medicaid CHIP Income Stand 2022'!$I$4:$I$54,MATCH(G$1,'Medicaid CHIP Income Stand 2022'!$A$4:$A$54,0)) -> 0.68 | H8: =INDEX('Medicaid CHIP Income Stand 2022'!$I$4:$I$54,MATCH(H$1,'Medicaid CHIP Income Stand 2022'!$A$4:$A$54,0)) -> 1.55 | I8: =INDEX('Medicaid CHIP Income Stand 2022'!$I$4:$I$54,MATCH(I$1,'Medicaid CHIP Income Stand 2022'!$A$4:$A$54,0)) -> 0.87 | ... AZ8: =INDEX('Medicaid CHIP Income Stand 2022'!$I$4:$I$54,MATCH(AZ$1,'Medicaid CHIP Income Stand 2022'!$A$4:$A$54,0)) -> 0.51
A9: ='Medicaid CHIP Income Stand 2022'!J3 -> Adults (Medicaid) Expansion to Adults | B9: =INDEX('Medicaid CHIP Income Stand 2022'!$J$4:$J$54,MATCH(B$1,'Medicaid CHIP Income Stand 2022'!$A$4:$A$54,0)) -> No | C9: =INDEX('Medicaid CHIP Income Stand 2022'!$J$4:$J$54,MATCH(C$1,'Medicaid CHIP Income Stand 2022'!$A$4:$A$54,0)) -> 1.33 | D9: =INDEX('Medicaid CHIP Income Stand 2022'!$J$4:$J$54,MATCH(D$1,'Medicaid CHIP Income Stand 2022'!$A$4:$A$54,0)) -> 1.33 | E9: =INDEX('Medicaid CHIP Income Stand 2022'!$J$4:$J$54,MATCH(E$1,'Medicaid CHIP Income Stand 2022'!$A$4:$A$54,0)) -> 1.33 | F9: =INDEX('Medicaid CHIP Income Stand 2022'!$J$4:$J$54,MATCH(F$1,'Medicaid CHIP Income Stand 2022'!$A$4:$A$54,0)) -> 1.33 | G9: =INDEX('Medicaid CHIP Income Stand 2022'!$J$4:$J$54,MATCH(G$1,'Medicaid CHIP Income Stand 2022'!$A$4:$A$54,0)) -> 1.33 | H9: =INDEX('Medicaid CHIP Income Stand 2022'!$J$4:$J$54,MATCH(H$1,'Medicaid CHIP Income Stand 2022'!$A$4:$A$54,0)) -> 1.33 | I9: =INDEX('Medicaid CHIP Income Stand 2022'!$J$4:$J$54,MATCH(I$1,'Medicaid CHIP Income Stand 2022'!$A$4:$A$54,0)) -> 1.33 | ... AZ9: =INDEX('Medicaid CHIP Income Stand 2022'!$J$4:$J$54,MATCH(AZ$1,'Medicaid CHIP Income Stand 2022'!$A$4:$A$54,0)) -> No
A10: ='Medicaid CHIP Income Stand 2022'!K3 -> Adults (Medicaid) Parent/ Caretaker converted from Dollar? | B10: =INDEX('Medicaid CHIP Income Stand 2022'!$K$4:$K$54,MATCH(B$1,'Medicaid CHIP Income Stand 2022'!$A$4:$A$54,0)) -> No | C10: =INDEX('Medicaid CHIP Income Stand 2022'!$K$4:$K$54,MATCH(C$1,'Medicaid CHIP Income Stand 2022'!$A$4:$A$54,0)) -> Yes | D10: =INDEX('Medicaid CHIP Income Stand 2022'!$K$4:$K$54,MATCH(D$1,'Medicaid CHIP Income Stand 2022'!$A$4:$A$54,0)) -> No | E10: =INDEX('Medicaid CHIP Income Stand 2022'!$K$4:$K$54,MATCH(E$1,'Medicaid CHIP Income Stand 2022'!$A$4:$A$54,0)) -> Yes | F10: =INDEX('Medicaid CHIP Income Stand 2022'!$K$4:$K$54,MATCH(F$1,'Medicaid CHIP Income Stand 2022'!$A$4:$A$54,0)) -> No | G10: =INDEX('Medicaid CHIP Income Stand 2022'!$K$4:$K$54,MATCH(G$1,'Medicaid CHIP Income Stand 2022'!$A$4:$A$54,0)) -> No | H10: =INDEX('Medicaid CHIP Income Stand 2022'!$K$4:$K$54,MATCH(H$1,'Medicaid CHIP Income Stand 2022'!$A$4:$A$54,0)) -> No | I10: =INDEX('Medicaid CHIP Income Stand 2022'!$K$4:$K$54,MATCH(I$1,'Medicaid CHIP Income Stand 2022'!$A$4:$A$54,0)) -> No | ... AZ10: =INDEX('Medicaid CHIP Income Stand 2022'!$K$4:$K$54,MATCH(AZ$1,'Medicaid CHIP Income Stand 2022'!$A$4:$A$54,0)) -> Yes
