Workbook
Name Adjusted_Gross_Income: [1]Calc1!$N$65:INDEX([1]Calc1!$N$65:$HH$65,COUNTIF([1]Calc1!$N$65:$HH$65,”<>”&””))
Name Adjusted_Gross_Income: [2]Calc1!$N$66:INDEX([2]Calc1!$N$66:$HH$66,COUNTIF([2]Calc1!$N$66:$HH$66,”<>”&””))
Name AgeAdult: [1]Lists!$F$10:$F$60
Name AgeAdult: [2]Lists!$F$10:$F$60
Name AgeChild: [1]Lists!$H$10:$H$29
Name AgeChild: [2]Lists!$H$10:$H$29
Name CCA_RateCategoryEntireCol: INDEX([1]!CCA_RateCategory[#Data],,FPIG!CCA_RateCategoryStateColNum)
Name CCA_RateCategoryEntireCol: INDEX([2]!CCA_RateCategory[#Data],,CCA_RateCategoryStateColNum)
Name CCA_RateCategoryLookup: INDEX([2]!CCA_RateCategory[#Data],1,CCA_RateCategoryStateColNum):INDEX([2]!CCA_RateCategory[#Data],COUNTA(CCA_RateCategoryEntireCol),CCA_RateCategoryStateColNum)
Name CCA_RateCategoryStateColNum: MATCH(FPIG!InputStateName,[1]!CCA_RateCategory[#Headers],0)
Name CCA_RateCategoryStateColNum: MATCH(InputStateName,[2]!CCA_RateCategory[#Headers],0)
Name CCA_SettingsEntireCol: INDEX([1]!CCA_Settings[#Data],,FPIG!CCA_SettingsStateColNum)
Name CCA_SettingsEntireCol: INDEX([2]!CCA_Settings[#Data],,CCA_SettingsStateColNum)
Name CCA_SettingsLookup: INDEX([1]!CCA_Settings[#Data],1,FPIG!CCA_SettingsStateColNum):INDEX([1]!CCA_Settings[#Data],COUNTA(FPIG!CCA_SettingsEntireCol),FPIG!CCA_SettingsStateColNum)
Name CCA_SettingsLookup: INDEX([2]!CCA_Settings[#Data],1,CCA_SettingsStateColNum):INDEX([2]!CCA_Settings[#Data],COUNTA(CCA_SettingsEntireCol),CCA_SettingsStateColNum)
Name CCA_SettingsStateColNum: MATCH(FPIG!InputStateName,[1]!CCA_Settings[#Headers],0)
Name CCA_SettingsStateColNum: MATCH(InputStateName,[2]!CCA_Settings[#Headers],0)
Name CHIP_GroupLookup1: [2]Calc1!$C$384:$G$391
Name CompareAlabamaAdjusted_Gross_Income: [1]Calc1!$N$65:INDEX([1]Calc1!$N$65:$HH$65,COUNTIF([1]Calc1!$N$65:$HH$65,”<>”&””))
Name CompareAlabamaAdjusted_Gross_Income: [2]Calc1!$N$66:INDEX([2]Calc1!$N$66:$HH$66,COUNTIF([2]Calc1!$N$66:$HH$66,”<>”&””))
Name CompareAlabamaHousehold_Annual_Earned_Income: [1]Calc1!$N$45:INDEX([1]Calc1!$N$45:$HH$45,COUNTIF([1]Calc1!$N$45:$HH$45,”<>”&””))
Name CompareAlabamaHousehold_Annual_Earned_Income: [2]Calc1!$N$46:INDEX([2]Calc1!$N$46:$HH$46,COUNTIF([2]Calc1!$N$46:$HH$46,”<>”&””))
Name CompareAlabamaHousehold_Annual_Income: [1]Calc1!$N$49:INDEX([1]Calc1!$N$49:$HH$49,COUNTIF([1]Calc1!$N$49:$HH$49,”<>”&””))
Name CompareAlabamaHousehold_Annual_Income: [2]Calc1!$N$50:INDEX([2]Calc1!$N$50:$HH$50,COUNTIF([2]Calc1!$N$50:$HH$50,”<>”&””))
Name CompareAlabamaHousehold_Annual_Unearned_Income: [1]Calc1!$N$47:INDEX([1]Calc1!$N$47:$HH$47,COUNTIF([1]Calc1!$N$47:$HH$47,”<>”&””))
Name CompareAlabamaHousehold_Annual_Unearned_Income: [2]Calc1!$N$48:INDEX([2]Calc1!$N$48:$HH$48,COUNTIF([2]Calc1!$N$48:$HH$48,”<>”&””))
Name CompareAlabamaHousehold_Monthly_Earned_Income: [1]Calc1!$N$44:INDEX([1]Calc1!$N$44:$HH$44,COUNTIF([1]Calc1!$N$44:$HH$44,”<>”&””))
Name CompareAlabamaHousehold_Monthly_Earned_Income: [2]Calc1!$N$45:INDEX([2]Calc1!$N$45:$HH$45,COUNTIF([2]Calc1!$N$45:$HH$45,”<>”&””))
Name CompareAlabamaHousehold_Monthly_Income: [1]Calc1!$N$48:INDEX([1]Calc1!$N$48:$HH$48,COUNTIF([1]Calc1!$N$48:$HH$48,”<>”&””))
Name CompareAlabamaHousehold_Monthly_Income: [2]Calc1!$N$49:INDEX([2]Calc1!$N$49:$HH$49,COUNTIF([2]Calc1!$N$49:$HH$49,”<>”&””))
Name CompareAlabamaHousehold_Monthly_Unearned_Income: [1]Calc1!$N$46:INDEX([1]Calc1!$N$46:$HH$46,COUNTIF([1]Calc1!$N$46:$HH$46,”<>”&””))
Name CompareAlabamaHousehold_Monthly_Unearned_Income: [2]Calc1!$N$47:INDEX([2]Calc1!$N$47:$HH$47,COUNTIF([2]Calc1!$N$47:$HH$47,”<>”&””))
Name CompareAlabamaOutputACTC: [1]Calc1!$N$139:$HF$139
Name CompareAlabamaOutputACTC: [2]Calc1!$N$140:$HF$140
Name CompareAlabamaOutputChildCareSubsidyFinal: [1]Calc1!$N$594:$HF$594
Name CompareAlabamaOutputChildCareSubsidyFinal: [2]Calc1!$N$588:$HF$588
Name CompareAlabamaOutputCHIP: [1]Calc1!$N$421:$HF$421
Name CompareAlabamaOutputCHIP: [2]Calc1!$N$419:$HF$419
Name CompareAlabamaOutputComboCashAssistance: FPIG!CompareAlabamaOutputTANF + FPIG!CompareAlabamaOutputSSI +FPIG!CompareAlabamaOutputLIHEAP
Name CompareAlabamaOutputComboCashAssistance: CompareAlabamaOutputTANF + CompareAlabamaOutputSSI +CompareAlabamaOutputLIHEAP
Name CompareAlabamaOutputComboFoodAssistance: FPIG!CompareAlabamaOutputSNAP + FPIG!CompareAlabamaOutputWIC + FPIG!CompareAlabamaOutputSubsidizedSchoolMeals
Name CompareAlabamaOutputComboFoodAssistance: CompareAlabamaOutputSNAP + CompareAlabamaOutputWIC + CompareAlabamaOutputSubsidizedSchoolMeals
Name CompareAlabamaOutputComboMedicalAssistance: FPIG!CompareAlabamaOutputMedicaid + FPIG!CompareAlabamaOutputCHIP + FPIG!CompareAlabamaOutputHIXPTC
Name CompareAlabamaOutputComboMedicalAssistance: CompareAlabamaOutputMedicaid + CompareAlabamaOutputCHIP + CompareAlabamaOutputHIXPTC
Name CompareAlabamaOutputComboNetEarnings: FPIG!CompareAlabamaAdjusted_Gross_Income - FPIG!CompareAlabamaOutputFICA - FPIG!CompareAlabamaOutputFedTax - FPIG!CompareAlabamaOutputStateTax
Name CompareAlabamaOutputComboNetEarnings: CompareAlabamaAdjusted_Gross_Income - CompareAlabamaOutputFICA - CompareAlabamaOutputFedTax - CompareAlabamaOutputStateTax
Name CompareAlabamaOutputComboRefundableTaxCredits: FPIG!CompareAlabamaOutputEITC + FPIG!CompareAlabamaOutputACTC + FPIG!CompareAlabamaOutputStateEITC + FPIG!CompareAlabamaOutputCTC
Name CompareAlabamaOutputComboRefundableTaxCredits: CompareAlabamaOutputEITC + CompareAlabamaOutputACTC + CompareAlabamaOutputStateEITC + CompareAlabamaOutputCTC
Name CompareAlabamaOutputCTC: [1]Calc1!$N$107:$HF$107
Name CompareAlabamaOutputCTC: [2]Calc1!$N$108:$HF$108
Name CompareAlabamaOutputEITC: [1]Calc1!$N$121:$HF$121
Name CompareAlabamaOutputEITC: [2]Calc1!$N$122:$HF$122
Name CompareAlabamaOutputFedTax: [1]Calc1!$N$101:$HF$101
Name CompareAlabamaOutputFedTax: [2]Calc1!$N$102:$HF$102
Name CompareAlabamaOutputFICA: [1]Calc1!$N$53:$HF$53
Name CompareAlabamaOutputFICA: [2]Calc1!$N$54:$HF$54
Name CompareAlabamaOutputHIXPTC: [1]Calc1!$N$464:$HF$464
Name CompareAlabamaOutputHIXPTC: [2]Calc1!$N$462:$HF$462
Name CompareAlabamaOutputInterval: [1]Calc1!$N$2:$HF$2
Name CompareAlabamaOutputInterval: [2]Calc1!$N$2:$HF$2

Sheet TANF
A1: TANF | B1: Temporary Assistance for Needy Families
B3: Income Disregards
B5: Program Disregards
C7: Earnings from children | D7: SSI | E7: Other disability benefits | F7: EITC | G7: SNAP
B8: Georgia | C8: þ | D8: þ | E8: þ | F8: þ | G8: þ
B10: Table: TANFComponents
C11: State | D11: Component | E11: Comment | F11: 2018 | G11: 2019 | H11: 2020 | I11: 2021 | J11: 2022 | K11: 2023
C12: Alabama | D12: Include SSI Child in AU? | F12: FALSE | G12: FALSE | H12: FALSE | I12: FALSE | J12: FALSE | K12: FALSE
C13: Arkansas | D13: Include SSI Child in AU? | F13: FALSE | G13: FALSE | H13: FALSE | I13: FALSE | J13: FALSE | K13: FALSE
C14: Florida | D14: Include SSI Child in AU? | F14: FALSE | G14: FALSE | H14: FALSE | I14: FALSE | J14: FALSE | K14: FALSE
C15: Georgia | D15: Include SSI Child in AU? | F15: FALSE | G15: FALSE | H15: FALSE | I15: FALSE | J15: FALSE | K15: FALSE
C16: Louisiana | D16: Include SSI Child in AU? | F16: FALSE | G16: FALSE | H16: FALSE | I16: FALSE | J16: FALSE | K16: FALSE
C17: Missouri | D17: Include SSI Child in AU? | F17: FALSE | G17: FALSE | H17: FALSE | I17: FALSE | J17: FALSE | K17: FALSE
C18: Mississippi | D18: Include SSI Child in AU? | F18: FALSE | G18: FALSE | H18: FALSE | I18: FALSE | J18: FALSE | K18: FALSE
C19: North Carolina | D19: Include SSI Child in AU? | F19: FALSE | G19: FALSE | H19: FALSE | I19: FALSE | J19: FALSE | K19: FALSE
C20: Oklahoma | D20: Include SSI Child in AU? | F20: FALSE | G20: FALSE | H20: FALSE | I20: FALSE | J20: FALSE | K20: FALSE
C21: South Carolina | D21: Include SSI Child in AU? | F21: FALSE | G21: FALSE | H21: FALSE | I21: FALSE | J21: FALSE | K21: FALSE
C22: Tennessee | D22: Include SSI Child in AU? | F22: FALSE | G22: FALSE | H22: FALSE | I22: FALSE | J22: FALSE | K22: FALSE
C23: Texas | D23: Include SSI Child in AU? | F23: FALSE | G23: FALSE | H23: FALSE | I23: FALSE | J23: FALSE | K23: FALSE
... C27: Arkansas | D27: Pregnant without children | F27: FALSE | G27: FALSE | H27: FALSE | I27: FALSE | J27: FALSE | K27: FALSE
C28: Florida | D28: Pregnant without children | E28: 9th month | F28: TRUE | G28: TRUE | H28: TRUE | I28: TRUE | J28: TRUE | K28: TRUE
C29: Georgia | D29: Pregnant without children | F29: FALSE | G29: FALSE | H29: FALSE | I29: FALSE | J29: FALSE | K29: FALSE
C30: Louisiana | D30: Pregnant without children | E30: 6th month | F30: TRUE | G30: TRUE | H30: TRUE | I30: TRUE | J30: TRUE | K30: TRUE
C31: Mississippi | D31: Pregnant without children | F31: FALSE | G31: FALSE | H31: FALSE | I31: FALSE | J31: FALSE | K31: FALSE
C32: Missouri | D32: Pregnant without children | F32: FALSE | G32: FALSE | H32: FALSE | I32: FALSE | J32: FALSE | K32: FALSE
C33: North Carolina | D33: Pregnant without children | F33: FALSE | G33: FALSE | H33: FALSE | I33: FALSE | J33: FALSE | K33: FALSE
C34: Oklahoma | D34: Pregnant without children | F34: FALSE | G34: FALSE | H34: FALSE | I34: FALSE | J34: FALSE | K34: FALSE
C35: South Carolina | D35: Pregnant without children | F35: FALSE | G35: FALSE | H35: FALSE | I35: FALSE | J35: FALSE | K35: FALSE
C36: Tennessee | D36: Pregnant without children | E36: 6th month | F36: TRUE | G36: TRUE | H36: TRUE | I36: TRUE | J36: TRUE | K36: TRUE
C37: Texas | D37: Pregnant without children | F37: FALSE | G37: FALSE | H37: FALSE | I37: FALSE | J37: FALSE | K37: FALSE
C38: Utah | D38: Pregnant without children | F38: TRUE | G38: TRUE | H38: TRUE | I38: TRUE | J38: TRUE | K38: TRUE
C39: West Virginia | D39: Pregnant without children | F39: FALSE | G39: FALSE | H39: FALSE | I39: FALSE | J39: FALSE | K39: FALSE
C40: Alabama | D40: Two parents benefit? | F40: TRUE | G40: TRUE | H40: TRUE | I40: TRUE | J40: TRUE | K40: TRUE
C41: Arkansas | D41: Two parents benefit? | F41: TRUE | G41: TRUE | H41: TRUE | I41: TRUE | J41: TRUE | K41: TRUE
C42: Florida | D42: Two parents benefit? | F42: TRUE | G42: TRUE | H42: TRUE | I42: TRUE | J42: TRUE | K42: TRUE
C43: Georgia | D43: Two parents benefit? | F43: TRUE | G43: TRUE | H43: TRUE | I43: TRUE | J43: TRUE | K43: TRUE
C44: Louisiana | D44: Two parents benefit? | F44: FALSE | G44: FALSE | H44: FALSE | I44: FALSE | J44: FALSE | K44: FALSE
C45: Mississippi | D45: Two parents benefit? | F45: TRUE | G45: TRUE | H45: TRUE | I45: TRUE | J45: TRUE | K45: TRUE
C46: Missouri | D46: Two parents benefit? | F46: TRUE | G46: TRUE | H46: TRUE | I46: TRUE | J46: TRUE | K46: TRUE
C47: North Carolina | D47: Two parents benefit? | F47: TRUE | G47: TRUE | H47: TRUE | I47: TRUE | J47: TRUE | K47: TRUE
...

Sheet FPIG
A1: FPIG | B1: Federal Poverty Income Guidelines
B3: U.S. Federal Poverty Guidelines Used to Determine Financial Eligibility for Certain Federal Programs
B5: U.S Department of Health and Human Services
B6: Office of the Assistant Secretary for Planning Evaluation
B7: https://aspe.hhs.gov/poverty-guidelines
B9: From the website, accessed 02/21/2020
B10: "There are two slightly different versions of the federal poverty measure: poverty thresholds and poverty guidelines."
B11: "The poverty thresholds are the original version of the federal poverty measure. They are updated each year by the Census Bureau. The thresholds are used mainly for statistical purposes — for instance, preparing estimates of the number of Americans in poverty each year. (In other words, all official poverty population figures are calculated using the poverty thresholds, not the guidelines). Poverty thresholds since 1973 (and for selected earlier years) and weighted average poverty thresholds since 1959 are available on the Census Bureau’s Web site. For an example of how the Census Bureau applies the thresholds to a family’s income to determine its poverty status, see “How the Census Bureau Measures Poverty” on the Census Bureau’s web site."
B12: "The poverty guidelines are the other version of the federal poverty measure. They are issued each year in the Federal Register by the Department of Health and Human Services (HHS). The guidelines are a simplification of the poverty thresholds for use for administrative purposes — for instance, determining financial eligibility for certain federal programs."
B13: "The poverty guidelines are sometimes loosely referred to as the “federal poverty level” (FPL), but that phrase is ambiguous and should be avoided, especially in situations (e.g., legislative or administrative) where precision is important."
B14: "Key differences between poverty thresholds and poverty guidelines are outlined in a table under Frequently Asked Questions (FAQs). See also the discussion of this topic on the Institute for Research on Poverty’s web site"
B15: "The January 2020 poverty guidelines are calculated by taking the 2018 Census Bureau’s poverty thresholds and adjusting them for price changes between 2018 and 2019 using the Consumer Price Index (CPI-U). The poverty thresholds used by the Census Bureau for statistical purposes are complex and are not composed of standardized increments between family sizes. Since many program officials prefer to use guidelines with uniform increments across family sizes, the poverty guidelines include rounding and standardizing adjustments."
W16: 2017 | X16: 2018 | Y16: 2019 | Z16: 2020 | AA16: 2021 | AB16: 2019 | AC16: 2020 | AD16: 2021 | AE16: 2019 | AF16: 2020 | AG16: 2021 | AH16: 2018 | AI16: 2019 | AJ16: 2020 | AK16: 2021
B17: LookupTable: FPIG | W17: Monthly | X17: Monthly | Y17: Monthly | Z17: Monthly | AA17: Monthly | AB17: Monthly | AC17: Monthly | AD17: Monthly | AE17: Monthly | AF17: Monthly | AG17: Monthly | AH17: Monthly | AI17: Monthly | AJ17: Monthly | AK17: Monthly
C18: State | D18: Persons in Family/Household | E18: 2011 | F18: 2012 | G18: 2013 | H18: 2014 | I18: 2015 | J18: 2016 | K18: 2017 | L18: 2018 | M18: 2019 | N18: 2020 | O18: 2021 | P18: 2022 | Q18: 2023 | X18: 1 | Y18: 1 | Z18: 1 | AA18: 1 | AB18: 1 | AC18: 1.33 | AD18: 1.33 | AE18: 1.33 | AF18: 2 | AG18: 2 | AH18: 2 | AI18: 0.5 | AJ18: 0.5 | AK18: 0.5 | AL18: 0.5
C19: 48 States | D19: 1 | E19: 10890 | F19: 11170 | G19: 11490 | H19: 11670 | I19: 11770 | J19: 11880 | K19: 12060 | L19: 12140 | M19: 12490 | N19: 12760 | O19: 12880 | P19: 13590 | Q19: 14580 | R19: =FPIG[[#This Row],[2019]]*2 -> 24980 | X19: =FPIG[[#This Row],[2017]]/12 -> 1005 | Y19: =FPIG[[#This Row],[2018]]/12 -> 1011.6667 | Z19: =FPIG[[#This Row],[2019]]/12 -> 1040.8333 | AA19: =FPIG[[#This Row],[2020]]/12 -> 1063.3333 | AB19: =FPIG[[#This Row],[2021]]/12 -> 1073.3333 | AC19: =$Z19*AC$18 -> 1384.3083 | AD19: =$AA19*AD$18 -> 1414.2333 | AE19: =$AB19*AE$18 -> 1427.5333 | AF19: =$Z19*AF$18 -> 2081.6667 | AG19: =$AA19*AG$18 -> 2126.6667 | AH19: =$AB19*AH$18 -> 2146.6667 | AI19: =FPIG[[#This Row],[2018]]*AI$18/12 -> 505.83333 | AJ19: =FPIG[[#This Row],[2019]]*AJ$18/12 -> 520.41667 | AK19: =FPIG[[#This Row],[2020]]*AK$18/12 -> 531.66667 | AL19: =FPIG[[#This Row],[2021]]*AL$18/12 -> 536.66667
C20: 48 States | D20: 2 | E20: 14710 | F20: 15130 | G20: 15510 | H20: 15730 | I20: 15930 | J20: 16020 | K20: 16240 | L20: 16460 | M20: 16910 | N20: 17240 | O20: 17420 | P20: 18310 | Q20: 19720 | S20: =FPIG[[#This Row],[2020]]/12 -> 1436.6667 | X20: =FPIG[[#This Row],[2017]]/12 -> 1353.3333 | Y20: =FPIG[[#This Row],[2018]]/12 -> 1371.6667 | Z20: =FPIG[[#This Row],[2019]]/12 -> 1409.1667 | AA20: =FPIG[[#This Row],[2020]]/12 -> 1436.6667 | AB20: =FPIG[[#This Row],[2021]]/12 -> 1451.6667 | AC20: =$Z20*AC$18 -> 1874.1917 | AD20: =$AA20*AD$18 -> 1910.7667 | AE20: =$AB20*AE$18 -> 1930.7167 | AF20: =$Z20*AF$18 -> 2818.3333 | AG20: =$AA20*AG$18 -> 2873.3333 | AH20: =$AB20*AH$18 -> 2903.3333 | AI20: =FPIG[[#This Row],[2018]]*AI$18/12 -> 685.83333 | AJ20: =FPIG[[#This Row],[2019]]*AJ$18/12 -> 704.58333 | AK20: =FPIG[[#This Row],[2020]]*AK$18/12 -> 718.33333 | AL20: =FPIG[[#This Row],[2021]]*AL$18/12 -> 725.83333
C21: 48 States | D21: 3 | E21: 18530 | F21: 19090 | G21: 19530 | H21: 19790 | I21: 20090 | J21: 20160 | K21: 20420 | L21: 20780 | M21: 21330 | N21: 21720 | O21: 21960 | P21: 23030 | Q21: 24860 | X21: =FPIG[[#This Row],[2017]]/12 -> 1701.6667 | Y21: =FPIG[[#This Row],[2018]]/12 -> 1731.6667 | Z21: =FPIG[[#This Row],[2019]]/12 -> 1777.5 | AA21: =FPIG[[#This Row],[2020]]/12 -> 1810 | AB21: =FPIG[[#This Row],[2021]]/12 -> 1830 | AC21: =$Z21*AC$18 -> 2364.075 | AD21: =$AA21*AD$18 -> 2407.3 | AE21: =$AB21*AE$18 -> 2433.9 | AF21: =$Z21*AF$18 -> 3555 | AG21: =$AA21*AG$18 -> 3620 | AH21: =$AB21*AH$18 -> 3660 | AI21: =FPIG[[#This Row],[2018]]*AI$18/12 -> 865.83333 | AJ21: =FPIG[[#This Row],[2019]]*AJ$18/12 -> 888.75 | AK21: =FPIG[[#This Row],[2020]]*AK$18/12 -> 905 | AL21: =FPIG[[#This Row],[2021]]*AL$18/12 -> 915
C22: 48 States | D22: 4 | E22: 22350 | F22: 23050 | G22: 23550 | H22: 23850 | I22: 24250 | J22: 24300 | K22: 24600 | L22: 25100 | M22: 25750 | N22: 26200 | O22: 26500 | P22: 27750 | Q22: 30000 | R22: =FPIG[[#This Row],[2020]]*4 -> 104800 | S22: 94000 | T22: =S22/FPIG[[#This Row],[2020]] -> 3.5877863 | U22: =S22/FPIG[[#This Row],[2019]] -> 3.6504854 | X22: =FPIG[[#This Row],[2017]]/12 -> 2050 | Y22: =FPIG[[#This Row],[2018]]/12 -> 2091.6667 | Z22: =FPIG[[#This Row],[2019]]/12 -> 2145.8333 | AA22: =FPIG[[#This Row],[2020]]/12 -> 2183.3333 | AB22: =FPIG[[#This Row],[2021]]/12 -> 2208.3333 | AC22: =$Z22*AC$18 -> 2853.9583 | AD22: =$AA22*AD$18 -> 2903.8333 | AE22: =$AB22*AE$18 -> 2937.0833 | AF22: =$Z22*AF$18 -> 4291.6667 | AG22: =$AA22*AG$18 -> 4366.6667 | AH22: =$AB22*AH$18 -> 4416.6667 | AI22: =FPIG[[#This Row],[2018]]*AI$18/12 -> 1045.8333 | AJ22: =FPIG[[#This Row],[2019]]*AJ$18/12 -> 1072.9167 | AK22: =FPIG[[#This Row],[2020]]*AK$18/12 -> 1091.6667 | AL22: =FPIG[[#This Row],[2021]]*AL$18/12 -> 1104.1667
C23: 48 States | D23: 5 | E23: 26170 | F23: 27010 | G23: 27570 | H23: 27910 | I23: 28410 | J23: 28440 | K23: 28780 | L23: 29420 | M23: 30170 | N23: 30680 | O23: 31040 | P23: 32470 | Q23: 35140 | R23: =ROUND((L19/12),0) -> 1012 | S23: =ROUND((L19/12)*1.85,0) -> 1872 | T23: 1 | X23: =FPIG[[#This Row],[2017]]/12 -> 2398.3333 | Y23: =FPIG[[#This Row],[2018]]/12 -> 2451.6667 | Z23: =FPIG[[#This Row],[2019]]/12 -> 2514.1667 | AA23: =FPIG[[#This Row],[2020]]/12 -> 2556.6667 | AB23: =FPIG[[#This Row],[2021]]/12 -> 2586.6667 | AC23: =$Z23*AC$18 -> 3343.8417 | AD23: =$AA23*AD$18 -> 3400.3667 | AE23: =$AB23*AE$18 -> 3440.2667 | AF23: =$Z23*AF$18 -> 5028.3333 | AG23: =$AA23*AG$18 -> 5113.3333 | AH23: =$AB23*AH$18 -> 5173.3333 | AI23: =FPIG[[#This Row],[2018]]*AI$18/12 -> 1225.8333 | AJ23: =FPIG[[#This Row],[2019]]*AJ$18/12 -> 1257.0833 | AK23: =FPIG[[#This Row],[2020]]*AK$18/12 -> 1278.3333 | AL23: =FPIG[[#This Row],[2021]]*AL$18/12 -> 1293.3333
C24: 48 States | D24: 6 | E24: 29990 | F24: 30970 | G24: 31590 | H24: 31970 | I24: 32570 | J24: 32580 | K24: 32960 | L24: 33740 | M24: 34590 | N24: 35160 | O24: 35580 | P24: 37190 | Q24: 40280 | R24: =ROUND((L20/12),0) -> 1372 | S24: =ROUND((L20/12)*1.85,0) -> 2538 | T24: 2 | X24: =FPIG[[#This Row],[2017]]/12 -> 2746.6667 | Y24: =FPIG[[#This Row],[2018]]/12 -> 2811.6667 | Z24: =FPIG[[#This Row],[2019]]/12 -> 2882.5 | AA24: =FPIG[[#This Row],[2020]]/12 -> 2930 | AB24: =FPIG[[#This Row],[2021]]/12 -> 2965 | AC24: =$Z24*AC$18 -> 3833.725 | AD24: =$AA24*AD$18 -> 3896.9 | AE24: =$AB24*AE$18 -> 3943.45 | AF24: =$Z24*AF$18 -> 5765 | AG24: =$AA24*AG$18 -> 5860 | AH24: =$AB24*AH$18 -> 5930 | AI24: =FPIG[[#This Row],[2018]]*AI$18/12 -> 1405.8333 | AJ24: =FPIG[[#This Row],[2019]]*AJ$18/12 -> 1441.25 | AK24: =FPIG[[#This Row],[2020]]*AK$18/12 -> 1465 | AL24: =FPIG[[#This Row],[2021]]*AL$18/12 -> 1482.5
C25: 48 States | D25: 7 | E25: 33810 | F25: 34930 | G25: 35610 | H25: 36030 | I25: 36730 | J25: 36730 | K25: 37140 | L25: 38060 | M25: 39010 | N25: 39640 | O25: 40120 | P25: 41910 | Q25: 45420 | R25: =ROUND((L21/12),0) -> 1732 | S25: =ROUND((L21/12)*1.85,0) -> 3204 | T25: 3
C26: 48 States | D26: 8 | E26: 37630 | F26: 38890 | G26: 39630 | H26: 40090 | I26: 40890 | J26: 40890 | K26: 41320 | L26: 42380 | M26: 43430 | N26: 44120 | O26: 44660 | P26: 46630 | Q26: 50560 | R26: =ROUND((L22/12),0) -> 2092 | S26: =ROUND((L22/12)*1.85,0) -> 3870 | T26: 4 | AA26: 888
C27: 48 States | D27: 9 | E27: =E26+E$29 -> 41450 | F27: =F26+F$29 -> 42850 | G27: =G26+G$29 -> 43650 | H27: =H26+H$29 -> 44150 | I27: =I26+I$29 -> 45050 | J27: =J26+J$29 -> 45050 | K27: =K26+K$29 -> 45500 | L27: =L26+L$29 -> 46700 | ... O27: =O26+O$29 -> 49200 | P27: 51350 | Q27: 55700
C28: 48 States | D28: 10 | E28: =E27+E$29 -> 45270 | F28: =F27+F$29 -> 46810 | G28: =G27+G$29 -> 47670 | H28: =H27+H$29 -> 48210 | I28: =I27+I$29 -> 49210 | J28: =J27+J$29 -> 49210 | K28: =K27+K$29 -> 49680 | L28: =L27+L$29 -> 51020 | ... O28: =O27+O$29 -> 53740 | P28: 56070 | Q28: 60840
C29: 48 States | D29: add* | E29: 3820 | F29: 3960 | G29: 4020 | H29: 4060 | I29: 4160 | J29: 4160 | K29: 4180 | L29: 4320 | M29: 4420 | N29: 4480 | O29: 4540 | P29: 4720 | Q29: 5140 | R29: =ROUND((L23/12),0) -> 2452 | S29: =ROUND((L23/12)*1.85,0) -> 4536 | T29: 5 | AA29: 1332
C30: Alaska | D30: 1 | E30: 13600 | F30: 13970 | G30: 14350 | H30: 14580 | I30: 14720 | J30: 14840 | K30: 15060 | L30: 15180 | M30: 15600 | N30: 15950 | O30: 16090 | P30: 16990 | Q30: 18210 | R30: =ROUND((L24/12),0) -> 2812 | S30: =ROUND((L24/12)*1.85,0) -> 5202 | T30: 6 | AA30: 1777
C31: Alaska | D31: 2 | E31: 18380 | F31: 18920 | G31: 19380 | H31: 19660 | I31: 19920 | J31: 20020 | K31: 20290 | L31: 20580 | M31: 21130 | N31: 21550 | O31: 21770 | P31: 22890 | Q31: 24640 | R31: =ROUND((L25/12),0) -> 3172 | S31: =ROUND((L25/12)*1.85,0) -> 5868 | T31: 7 | AA31: 2221
C32: Alaska | D32: 3 | E32: 23160 | F32: 23870 | G32: 24410 | H32: 24740 | I32: 25120 | J32: 25200 | K32: 25520 | L32: 25980 | M32: 26660 | N32: 27150 | O32: 27450 | P32: 28790 | Q32: 31070 | R32: =ROUND((L26/12),0) -> 3532 | S32: =ROUND((L26/12)*1.85,0) -> 6534 | T32: 8 | AA32: 2665
C33: Alaska | D33: 4 | E33: 27940 | F33: 28820 | G33: 29440 | H33: 29820 | I33: 30320 | J33: 30380 | K33: 30750 | L33: 31380 | M33: 32190 | N33: 32750 | O33: 33130 | P33: 34690 | Q33: 37500 | AA33: 3109
C34: Alaska | D34: 5 | E34: 32720 | F34: 33770 | G34: 34470 | H34: 34900 | I34: 35520 | J34: 35560 | K34: 35980 | L34: 36780 | M34: 37720 | N34: 38350 | O34: 38810 | P34: 40590 | Q34: 43930 | AA34: 3331
C35: Alaska | D35: 6 | E35: 37500 | F35: 38720 | G35: 39500 | H35: 39980 | I35: 40720 | J35: 40740 | K35: 41210 | L35: 42180 | M35: 43250 | N35: 43950 | O35: 44490 | P35: 46490 | Q35: 50360 | AA35: 3553
C36: Alaska | D36: 7 | E36: 42280 | F36: 43670 | G36: 44530 | H36: 45060 | I36: 45920 | J36: 45920 | K36: 46440 | L36: 47580 | M36: 48780 | N36: 49550 | O36: 50170 | P36: 52390 | Q36: 56790 | AA36: 3775
C37: Alaska | D37: 8 | E37: 47060 | F37: 48620 | G37: 49560 | H37: 50140 | I37: 51120 | J37: 51120 | K37: 51670 | L37: 52980 | M37: 54310 | N37: 55150 | O37: 55850 | P37: 58290 | Q37: 63220
C38: Alaska | D38: 9 | E38: =E37+E$40 -> 51840 | F38: =F37+F$40 -> 53570 | G38: =G37+G$40 -> 54590 | H38: =H37+H$40 -> 55220 | I38: =I37+I$40 -> 56320 | J38: =J37+J$40 -> 56320 | K38: =K37+K$40 -> 56900 | L38: =L37+L$40 -> 58380 | ... O38: =O37+O$40 -> 61530 | P38: 64190 | Q38: 69650
C39: Alaska | D39: 10 | E39: =E38+E$40 -> 56620 | F39: =F38+F$40 -> 58520 | G39: =G38+G$40 -> 59620 | H39: =H38+H$40 -> 60300 | I39: =I38+I$40 -> 61520 | J39: =J38+J$40 -> 61520 | K39: =K38+K$40 -> 62130 | L39: =L38+L$40 -> 63780 | ... O39: =O38+O$40 -> 67210 | P39: 70090 | Q39: 76080
C40: Alaska | D40: add* | E40: 4780 | F40: 4950 | G40: 5030 | H40: 5080 | I40: 5200 | J40: 5200 | K40: 5230 | L40: 5400 | M40: 5530 | N40: 5600 | O40: 5680 | P40: 5900 | Q40: 6430
C41: Hawaii | D41: 1 | E41: 12540 | F41: 12860 | G41: 13230 | H41: 13420 | I41: 13550 | J41: 13670 | K41: 13860 | L41: 13960 | M41: 14380 | N41: 14680 | O41: 14820 | P41: 15630 | Q41: 16770
C42: Hawaii | D42: 2 | E42: 16930 | F42: 17410 | G42: 17850 | H42: 18090 | I42: 18330 | J42: 18430 | K42: 18670 | L42: 18930 | M42: 19460 | N42: 19830 | O42: 20040 | P42: 21060 | Q42: 22680
C43: Hawaii | D43: 3 | E43: 21320 | F43: 21960 | G43: 22470 | H43: 22760 | I43: 23110 | J43: 23190 | K43: 23480 | L43: 23900 | M43: 24540 | N43: 24980 | O43: 25260 | P43: 26490 | Q43: 28590
...
